Workbook

Sheet LOGBOOK
A1: loogbook perawat
A2: RSU Sakina idaman
A4: NAMA | C4: =": " &'3'!B33 -> :
A5: PK | C5: :
A6: UNIT
A8: NO | B8: INDIKATOR YANG DINILAI | D8: TARGET (%) | E8: BULAN : DESEMBER | AJ8: CAPAIAN (%) | AL8: RUMUS WAJIB DIISI
E9: 1 | F9: 2 | G9: 3 | H9: 4 | I9: 5 | J9: 6 | K9: 7 | L9: 8 | M9: 9 | N9: 10 | O9: 11 | P9: 12 | Q9: 13 | R9: 14 | S9: 15 | T9: 16 | U9: 17 | V9: 18 | W9: 19 | X9: 20 | Y9: 21 | Z9: 22 | AA9: 23 | AB9: 24 | AC9: 25 | AD9: 26 | AE9: 27 | AF9: 28 | AG9: 29 | AH9: 30 | AI9: 31 | AL9: JUMLAH HARI : | AM9: 28
AM10: =AM9 -> 28
A11: 1 | B11: Melaporkan insiden keselamatan pasien | D11: 100 | AJ11: =SUM(E11:AI11)/AM9*40/100 -> 0 | AM11: =AM10 -> 28
A12: 2 | B12: Tidak ada keluhan dari teman sejawat/profesi lain/pasien dan keluarga | D12: 100 | S12: . | AJ12: =SUM(E12:AI12)/AM10*40/100 -> 0 | AM12: =AM11 -> 28
A13: 3 | B13: Kepatuhan terhadap kode etik keperawatan | D13: 100 | AJ13: =SUM(E13:AI13)/AM11*40/100 -> 0 | AM13: =AM12 -> 28
E14: =SUM(E11:E13)/3 -> 0 | F14: =SUM(F11:F13)/3 -> 0 | G14: =SUM(G11:G13)/3 -> 0 | H14: =SUM(H11:H13)/3 -> 0 | I14: =SUM(I11:I13)/3 -> 0 | J14: =SUM(J11:J13)/3 -> 0 | K14: =SUM(K11:K13)/3 -> 0 | L14: =SUM(L11:L13)/3 -> 0 | ... R14: =SUM(R11:R13)/3 -> 0 | S14: 0 | T14: =SUM(T11:T13)/3 -> 0 | U14: =SUM(U11:U13)/3 -> 0 | V14: =SUM(V11:V13)/3 -> 0 | W14: =SUM(W11:W13)/3 -> 0 | X14: =SUM(X11:X13)/3 -> 0 | Y14: =SUM(Y11:Y13)/3 -> 0 | Z14: =SUM(Z11:Z13)/3 -> 0 | AA14: =SUM(AA11:AA13)/3 -> 0 | ... AJ14: =SUM(AJ11:AJ13)/3 -> 0 | AM14: =AM13 -> 28
AM15: =AM14 -> 28
A16: 1 | B16: Menunjukan perilaku bertanggung gugat terhadap praktek profesional | D16: 100 | AJ16: =SUM(E16:AI16)/AM16*10/100 -> 0 | AM16: =AM15 -> 28
A17: 2 | B17: Kepatuhan dalam memberikan pendidikan pasien dan keluarga | D17: 100 | AJ17: =SUM(E17:AI17)/AM17*10/100 -> 0 | AM17: =AM16 -> 28
A18: JUMLAH RATA - RATA | E18: =SUM(E16:E17)/3 -> 0 | F18: =SUM(F16:F17)/3 -> 0 | G18: =SUM(G16:G17)/3 -> 0 | H18: =SUM(H16:H17)/3 -> 0 | I18: =SUM(I16:I17)/3 -> 0 | J18: =SUM(J16:J17)/3 -> 0 | K18: =SUM(K16:K17)/3 -> 0 | L18: =SUM(L16:L17)/3 -> 0 | ... AJ18: =SUM(AJ16:AJ17)/3 -> 0 | AM18: =#REF! -> #REF!
A19: C. KINERJA KLINIS (50%) | AM19: =AM18 -> #REF!
A20: 1 | B20: Kepatuhan identifikasi pasien | D20: 100 | AJ20: =SUM(E20:AI20)/AM20*50/100 -> #REF! | AM20: =AM19 -> #REF!
A21: =A20+1 -> 2 | B21: Kepatuhan pemakaian APD dengan benar | D21: 100 | AJ21: =SUM(E21:AI21)/AM21*50/100 -> #REF! | AM21: =AM20 -> #REF!
A22: =A21+1 -> 3 | B22: Kepatuhan kebersihan tangan | D22: 100 | AJ22: =SUM(E22:AI22)/AM22*50/100 -> #REF! | AM22: =AM21 -> #REF!
A23: =A22+1 -> 4 | B23: Kepatuhan upaya pencegahan resiko pasien jatuh | D23: 100 | AJ23: =SUM(E23:AI23)/AM23*50/100 -> #REF! | AM23: =AM22 -> #REF!
A24: =A23+1 -> 5 | B24: Kepatuhan melaksanakan hand over antar petugas dengan metode SBAR | D24: 100 | AJ24: =SUM(E24:AI24)/AM24*50/100 -> #REF! | AM24: =AM23 -> #REF!
A25: =A24+1 -> 6 | B25: Kepatuhan melaksanakan double chek obat high allert | D25: 100 | AJ25: =SUM(E25:AI25)/AM25*50/100 -> #REF! | AM25: =AM24 -> #REF!
A26: =A25+1 -> 7 | B26: Kemampuan menangani life saving anak dan dewasa | D26: 100 | AJ26: =SUM(E26:AI26)/AM26*50/100 -> #REF! | AM26: =AM25 -> #REF!
A27: 8 | B27: Kecepatan pelayanan pasien dengan risiko tinggi | D27: 100 | AJ27: =SUM(E27:AI27)/AM27*50/100 -> #REF! | AM27: =AM26 -> #REF!
A28: JUMLAH RATA - RATA | E28: =SUM(E20:E27)/8 -> 0 | F28: =SUM(F20:F27)/8 -> 0 | G28: =SUM(G20:G27)/8 -> 0 | H28: =SUM(H20:H27)/8 -> 0 | I28: =SUM(I20:I27)/8 -> 0 | J28: =SUM(J20:J27)/8 -> 0 | K28: =SUM(K20:K27)/8 -> 0 | L28: =SUM(L20:L27)/8 -> 0 | ... AJ28: =SUM(AJ20:AJ27)/8 -> #REF! | AM28: =AM27 -> #REF!
A29: TOTAL NILAI PERILAKU + PENGEMBANGAN PROFESI + KINERJA KLINIS | AJ29: =AJ14+AJ18+AJ28 -> #REF! | AM29: =AM28 -> #REF!

Sheet Data Perawat
B2: NAMA | D2: =": " &'3'!C31 -> : | E2: Tulis nama di sini
B3: PK | D3: : | E3: Tulis PK di sini
B4: UNIT | D4: : | E4: Tulis Unit di sini
B5: NIP | D5: : | E5: Tulis NIP di sini

Sheet JAN 
A1: LOGBOOK PERAWAT
A2: RSU SAKINA IDAMAN
A4: NAMA | C4: =": " &'Data Perawat'!E2 -> : Tulis nama di sini
A5: PK | C5: =": " &'Data Perawat'!E3 -> : Tulis PK di sini
A6: UNIT | C6: =": " &'Data Perawat'!E4 -> : Tulis Unit di sini
A8: NO | B8: INDIKATOR YANG DINILAI | D8: TARGET (%) | E8: BULAN : JANUARI | AJ8: CAPAIAN (%) | AL8: RUMUS WAJIB DIISI
E9: 1 | F9: 2 | G9: 3 | H9: 4 | I9: 5 | J9: 6 | K9: 7 | L9: 8 | M9: 9 | N9: 10 | O9: 11 | P9: 12 | Q9: 13 | R9: 14 | S9: 15 | T9: 16 | U9: 17 | V9: 18 | W9: 19 | X9: 20 | Y9: 21 | Z9: 22 | AA9: 23 | AB9: 24 | AC9: 25 | AD9: 26 | AE9: 27 | AF9: 28 | AG9: 29 | AH9: 30 | AI9: 31 | AL9: JUMLAH HARI : | AM9: 28
A10: A. PERILAKU ( 40 % ) | AM10: =AM9 -> 28
A11: 1 | B11: Melaporkan insiden keselamatan pasien | D11: 100 | E11: 1 | AJ11: =SUM(E11:AI11)/AM9*40/100 -> 0.014285714 | AM11: =AM9 -> 28
A12: 2 | B12: Ada keluhan dari teman sejawat/profesi lain/pasien dan keluarga | D12: 100 | E12: 1 | AJ12: =SUM(E12:AI12)/AM10*40/100 -> 0.014285714 | AM12: =AM9 -> 28
A13: 3 | B13: Kepatuhan terhadap kode etik keperawatan | D13: 100 | AJ13: =SUM(E13:AI13)/AM11*40/100 -> 0 | AM13: =AM9 -> 28
A14: JUMLAH RATA - RATA | E14: =AVERAGE(E11:E13) -> 1 | F14: =AVERAGE(F11:F13) -> #DIV/0! | G14: =AVERAGE(G11:G13) -> #DIV/0! | H14: =AVERAGE(H11:H13) -> #DIV/0! | I14: =AVERAGE(I11:I13) -> #DIV/0! | J14: =AVERAGE(J11:J13) -> #DIV/0! | K14: =AVERAGE(K11:K13) -> #DIV/0! | L14: =AVERAGE(L11:L13) -> #DIV/0! | ... AJ14: =AVERAGE(AJ11:AJ13) -> 0.0095238095 | AM14: =AM9 -> 28
A15: B. PENGEMBANGAN PROFESI (10%)
A16: 4 | B16: Jumlah pengembangan profesi yang diikuti (pelatihan,seminar,Bimtek target 5 SKP/tahun) | D16: 100 | AJ16: =SUM(E16:AI16)/AM16*10/100 -> 0 | AM16: =AM9 -> 28
A17: 5 | B17: Kepatuhan dalam memberikan pendidikan pasien dan keluarga | D17: 100 | AJ17: =SUM(E17:AI17)/AM17*10/100 -> 0 | AM17: =AM9 -> 28
A18: JUMLAH RATA - RATA | E18: =AVERAGE(E16:E17) -> #DIV/0! | F18: =AVERAGE(F16:F17) -> #DIV/0! | G18: =AVERAGE(G16:G17) -> #DIV/0! | H18: =AVERAGE(H16:H17) -> #DIV/0! | I18: =AVERAGE(I16:I17) -> #DIV/0! | J18: =AVERAGE(J16:J17) -> #DIV/0! | K18: =AVERAGE(K16:K17) -> #DIV/0! | L18: =AVERAGE(L16:L17) -> #DIV/0! | ... AJ18: =AVERAGE(AJ16:AJ17) -> 0 | AM18: =AM9 -> 28
A19: C. KINERJA KLINIS (50%)
A20: 6 | B20: Pengkajian Pasien | D20: 100 | AJ20: =SUM(E20:AI20)/AM20*50/100 -> 0 | AM20: =AM9 -> 28
A21: 7 | B21: Menetapkan diagnosa Keperawatan | D21: 100 | AJ21: =SUM(E21:AI21)/AM21*50/100 -> 0 | AM21: =AM9 -> 28
A22: 8 | B22: Menyusun rencana keperawatan | D22: 100 | AJ22: =SUM(E22:AI22)/AM22*50/100 -> 0 | AM22: =AM9 -> 28
A23: 9 | B23: Melakukan tindakan keperawatan | D23: 100 | AJ23: =SUM(E23:AI23)/AM23*50/100 -> 0 | AM23: =AM9 -> 28
A24: 10 | B24: Melakukan dokumentasi keperawatan | D24: 100 | AJ24: =SUM(E24:AI24)/AM24*50/100 -> 0 | AM24: =AM9 -> 28
A25: 11 | B25: Kepatuhan identifikasi pasien | D25: 100 | AJ25: =SUM(E25:AI25)/AM25*50/100 -> 0 | AM25: =AM9 -> 28
A26: 12 | B26: Kepatuhan pemakaian APD dengan benar | D26: 100 | AJ26: =SUM(E26:AI26)/AM26*50/100 -> 0 | AM26: =AM9 -> 28
A27: 13 | B27: Kepatuhan kebersihan tangan | D27: 100 | AJ27: =SUM(E27:AI27)/AM27*50/100 -> 0 | AM27: =AM9 -> 28
A28: 14 | B28: Kepatuhan upaya pencegahan resiko pasien jatuh | D28: 100 | AJ28: =SUM(E28:AI28)/AM28*50/100 -> 0 | AM28: =AM9 -> 28
A29: 15 | B29: Kepatuhan melaksanakan hand over antar petugas dengan metode SBAR | D29: 100 | AJ29: =SUM(E29:AI29)/AM29*50/100 -> 0 | AM29: =AM9 -> 28
A30: 16 | B30: Kepatuhan melaksanakan double chek obat high allert | D30: 100 | AJ30: =SUM(E30:AI30)/AM30*50/100 -> 0 | AM30: =AM9 -> 28
A31: 17 | B31: Kemampuan menangani life saving anak dan dewasa | D31: 100 | AJ31: =SUM(E31:AI31)/AM31*50/100 -> 0 | AM31: =AM9 -> 28
A32: 18 | B32: Ketepatan pelayanan pasien dengan risiko tinggi | D32: 100 | AJ32: =SUM(E32:AI32)/AM32*50/100 -> 0 | AM32: =AM9 -> 28
A33: JUMLAH RATA - RATA | E33: =AVERAGE(E20:E32) -> #DIV/0! | F33: =AVERAGE(F20:F32) -> #DIV/0! | G33: =AVERAGE(G20:G32) -> #DIV/0! | H33: =AVERAGE(H20:H32) -> #DIV/0! | I33: =AVERAGE(I20:I32) -> #DIV/0! | J33: =AVERAGE(J20:J32) -> #DIV/0! | K33: =AVERAGE(K20:K32) -> #DIV/0! | L33: =AVERAGE(L20:L32) -> #DIV/0! | ... AJ33: =AVERAGE(AJ20:AJ32) -> 0 | AM33: =AM9 -> 28
A34: TOTAL NILAI PERILAKU + PENGEMBANGAN PROFESI + KINERJA KLINIS | AJ34: =AJ14+AJ18+AJ33 -> 0.0095238095 | AM34: =AM9 -> 28

Sheet FEB
A1: LOGBOOK PERAWAT
A2: RSU SAKINA IDAMAN
A4: NAMA | C4: =": " &'Data Perawat'!E2 -> : Tulis nama di sini
A5: PK | C5: =": " &'Data Perawat'!E3 -> : Tulis PK di sini
A6: UNIT | C6: =": " &'Data Perawat'!E4 -> : Tulis Unit di sini
A8: NO | B8: INDIKATOR YANG DINILAI | D8: TARGET (%) | E8: BULAN : FEBRUARI | AJ8: CAPAIAN (%) | AL8: RUMUS WAJIB DIISI
E9: 1 | F9: 2 | G9: 3 | H9: 4 | I9: 5 | J9: 6 | K9: 7 | L9: 8 | M9: 9 | N9: 10 | O9: 11 | P9: 12 | Q9: 13 | R9: 14 | S9: 15 | T9: 16 | U9: 17 | V9: 18 | W9: 19 | X9: 20 | Y9: 21 | Z9: 22 | AA9: 23 | AB9: 24 | AC9: 25 | AD9: 26 | AE9: 27 | AF9: 28 | AG9: 29 | AH9: 30 | AI9: 31 | AL9: JUMLAH HARI : | AM9: 28
A10: A. PERILAKU ( 40 % ) | AM10: =AM9 -> 28
A11: 1 | B11: Melaporkan insiden keselamatan pasien | D11: 100 | AJ11: =SUM(E11:AI11)/AM9*40/100 -> 0 | AM11: =AM9 -> 28
A12: 2 | B12: Ada keluhan dari teman sejawat/profesi lain/pasien dan keluarga | D12: 100 | AJ12: =SUM(E12:AI12)/AM10*40/100 -> 0 | AM12: =AM9 -> 28
A13: 3 | B13: Kepatuhan terhadap kode etik keperawatan | D13: 100 | AJ13: =SUM(E13:AI13)/AM11*40/100 -> 0 | AM13: =AM9 -> 28
A14: JUMLAH RATA - RATA | E14: =AVERAGE(E11:E13) -> #DIV/0! | F14: =AVERAGE(F11:F13) -> #DIV/0! | G14: =AVERAGE(G11:G13) -> #DIV/0! | H14: =AVERAGE(H11:H13) -> #DIV/0! | I14: =AVERAGE(I11:I13) -> #DIV/0! | J14: =AVERAGE(J11:J13) -> #DIV/0! | K14: =AVERAGE(K11:K13) -> #DIV/0! | L14: =AVERAGE(L11:L13) -> #DIV/0! | ... AJ14: =AVERAGE(AJ11:AJ13) -> 0 | AM14: =AM9 -> 28
A15: B. PENGEMBANGAN PROFESI (10%)
A16: 4 | B16: Menunjukan perilaku bertanggung gugat terhadap praktek profesional | D16: 100 | AJ16: =SUM(E16:AI16)/AM16*10/100 -> 0 | AM16: =AM9 -> 28
A17: 5 | B17: Kepatuhan dalam memberikan pendidikan pasien dan keluarga | D17: 100 | AJ17: =SUM(E17:AI17)/AM17*10/100 -> 0 | AM17: =AM9 -> 28
A18: JUMLAH RATA - RATA | E18: =AVERAGE(E16:E17) -> #DIV/0! | F18: =AVERAGE(F16:F17) -> #DIV/0! | G18: =AVERAGE(G16:G17) -> #DIV/0! | H18: =AVERAGE(H16:H17) -> #DIV/0! | I18: =AVERAGE(I16:I17) -> #DIV/0! | J18: =AVERAGE(J16:J17) -> #DIV/0! | K18: =AVERAGE(K16:K17) -> #DIV/0! | L18: =AVERAGE(L16:L17) -> #DIV/0! | ... AJ18: =AVERAGE(AJ16:AJ17) -> 0 | AM18: =AM9 -> 28
A19: C. KINERJA KLINIS (50%)
A20: 6 | B20: Pengkajian Pasien | D20: 100 | AJ20: =SUM(E20:AI20)/AM20*50/100 -> 0 | AM20: =AM9 -> 28
A21: 7 | B21: Menetapkan diagnosa Keperawatan | D21: 100 | AJ21: =SUM(E21:AI21)/AM21*50/100 -> 0 | AM21: =AM9 -> 28
A22: 8 | B22: Menyusun rencana keperawatan | D22: 100 | AJ22: =SUM(E22:AI22)/AM22*50/100 -> 0 | AM22: =AM9 -> 28
A23: 9 | B23: Melakukan tindakan keperawatan | D23: 100 | AJ23: =SUM(E23:AI23)/AM23*50/100 -> 0 | AM23: =AM9 -> 28
A24: 10 | B24: Melakukan dokumentasi keperawatan | D24: 100 | AJ24: =SUM(E24:AI24)/AM24*50/100 -> 0 | AM24: =AM9 -> 28
A25: 11 | B25: Kepatuhan identifikasi pasien | D25: 100 | AJ25: =SUM(E25:AI25)/AM25*50/100 -> 0 | AM25: =AM9 -> 28
A26: 12 | B26: Kepatuhan pemakaian APD dengan benar | D26: 100 | AJ26: =SUM(E26:AI26)/AM26*50/100 -> 0 | AM26: =AM9 -> 28
A27: 13 | B27: Kepatuhan kebersihan tangan | D27: 100 | AJ27: =SUM(E27:AI27)/AM27*50/100 -> 0 | AM27: =AM9 -> 28
A28: 14 | B28: Kepatuhan upaya pencegahan resiko pasien jatuh | D28: 100 | AJ28: =SUM(E28:AI28)/AM28*50/100 -> 0 | AM28: =AM9 -> 28
A29: 15 | B29: Kepatuhan melaksanakan hand over antar petugas dengan metode SBAR | D29: 100 | AJ29: =SUM(E29:AI29)/AM29*50/100 -> 0 | AM29: =AM9 -> 28
A30: 16 | B30: Kepatuhan melaksanakan double chek obat high allert | D30: 100 | AJ30: =SUM(E30:AI30)/AM30*50/100 -> 0 | AM30: =AM9 -> 28
A31: 17 | B31: Kemampuan menangani life saving anak dan dewasa | D31: 100 | AJ31: =SUM(E31:AI31)/AM31*50/100 -> 0 | AM31: =AM9 -> 28
A32: 18 | B32: Kecepatan pelayanan pasien dengan risiko tinggi | D32: 100 | AJ32: =SUM(E32:AI32)/AM32*50/100 -> 0 | AM32: =AM9 -> 28
A33: JUMLAH RATA - RATA | E33: =AVERAGE(E20:E32) -> #DIV/0! | F33: =AVERAGE(F20:F32) -> #DIV/0! | G33: =AVERAGE(G20:G32) -> #DIV/0! | H33: =AVERAGE(H20:H32) -> #DIV/0! | I33: =AVERAGE(I20:I32) -> #DIV/0! | J33: =AVERAGE(J20:J32) -> #DIV/0! | K33: =AVERAGE(K20:K32) -> #DIV/0! | L33: =AVERAGE(L20:L32) -> #DIV/0! | ... AJ33: =AVERAGE(AJ20:AJ32) -> 0 | AM33: =AM9 -> 28
A34: TOTAL NILAI PERILAKU + PENGEMBANGAN PROFESI + KINERJA KLINIS | AJ34: =AJ14+AJ18+AJ33 -> 0 | AM34: =AM9 -> 28

Sheet MAR
A1: LOGBOOK PERAWAT
A2: RSU SAKINA IDAMAN
A4: NAMA | C4: =": " &'Data Perawat'!E2 -> : Tulis nama di sini
A5: PK | C5: =": " &'Data Perawat'!E3 -> : Tulis PK di sini
A6: UNIT | C6: =": " &'Data Perawat'!E4 -> : Tulis Unit di sini
A8: NO | B8: INDIKATOR YANG DINILAI | D8: TARGET (%) | E8: BULAN : MARET | AJ8: CAPAIAN (%) | AL8: RUMUS WAJIB DIISI
E9: 1 | F9: 2 | G9: 3 | H9: 4 | I9: 5 | J9: 6 | K9: 7 | L9: 8 | M9: 9 | N9: 10 | O9: 11 | P9: 12 | Q9: 13 | R9: 14 | S9: 15 | T9: 16 | U9: 17 | V9: 18 | W9: 19 | X9: 20 | Y9: 21 | Z9: 22 | AA9: 23 | AB9: 24 | AC9: 25 | AD9: 26 | AE9: 27 | AF9: 28 | AG9: 29 | AH9: 30 | AI9: 31 | AL9: JUMLAH HARI : | AM9: 28
A10: A. PERILAKU ( 40 % ) | AM10: =AM9 -> 28
A11: 1 | B11: Melaporkan insiden keselamatan pasien | D11: 100 | AJ11: =SUM(E11:AI11)/AM9*40/100 -> 0 | AM11: =AM9 -> 28
A12: 2 | B12: Ada keluhan dari teman sejawat/profesi lain/pasien dan keluarga | D12: 100 | AJ12: =SUM(E12:AI12)/AM10*40/100 -> 0 | AM12: =AM9 -> 28
A13: 3 | B13: Kepatuhan terhadap kode etik keperawatan | D13: 100 | AJ13: =SUM(E13:AI13)/AM11*40/100 -> 0 | AM13: =AM9 -> 28
A14: JUMLAH RATA - RATA | E14: =AVERAGE(E11:E13) -> #DIV/0! | F14: =AVERAGE(F11:F13) -> #DIV/0! | G14: =AVERAGE(G11:G13) -> #DIV/0! | H14: =AVERAGE(H11:H13) -> #DIV/0! | I14: =AVERAGE(I11:I13) -> #DIV/0! | J14: =AVERAGE(J11:J13) -> #DIV/0! | K14: =AVERAGE(K11:K13) -> #DIV/0! | L14: =AVERAGE(L11:L13) -> #DIV/0! | ... AJ14: =AVERAGE(AJ11:AJ13) -> 0 | AM14: =AM9 -> 28
A15: B. PENGEMBANGAN PROFESI (10%)
A16: 4 | B16: Menunjukan perilaku bertanggung gugat terhadap praktek profesional | D16: 100 | AJ16: =SUM(E16:AI16)/AM16*10/100 -> 0 | AM16: =AM9 -> 28
A17: 5 | B17: Kepatuhan dalam memberikan pendidikan pasien dan keluarga | D17: 100 | AJ17: =SUM(E17:AI17)/AM17*10/100 -> 0 | AM17: =AM9 -> 28
A18: JUMLAH RATA - RATA | E18: =AVERAGE(E16:E17) -> #DIV/0! | F18: =AVERAGE(F16:F17) -> #DIV/0! | G18: =AVERAGE(G16:G17) -> #DIV/0! | H18: =AVERAGE(H16:H17) -> #DIV/0! | I18: =AVERAGE(I16:I17) -> #DIV/0! | J18: =AVERAGE(J16:J17) -> #DIV/0! | K18: =AVERAGE(K16:K17) -> #DIV/0! | L18: =AVERAGE(L16:L17) -> #DIV/0! | ... AJ18: =AVERAGE(AJ16:AJ17) -> 0 | AM18: =AM9 -> 28
A19: C. KINERJA KLINIS (50%)
A20: 6 | B20: Pengkajian Pasien | D20: 100 | AJ20: =SUM(E20:AI20)/AM20*50/100 -> 0 | AM20: =AM9 -> 28
A21: 7 | B21: Menetapkan diagnosa Keperawatan | D21: 100 | AJ21: =SUM(E21:AI21)/AM21*50/100 -> 0 | AM21: =AM9 -> 28
A22: 8 | B22: Menyusun rencana keperawatan | D22: 100 | AJ22: =SUM(E22:AI22)/AM22*50/100 -> 0 | AM22: =AM9 -> 28
A23: 9 | B23: Melakukan tindakan keperawatan | D23: 100 | AJ23: =SUM(E23:AI23)/AM23*50/100 -> 0 | AM23: =AM9 -> 28
A24: 10 | B24: Melakukan dokumentasi keperawatan | D24: 100 | AJ24: =SUM(E24:AI24)/AM24*50/100 -> 0 | AM24: =AM9 -> 28
A25: 11 | B25: Kepatuhan identifikasi pasien | D25: 100 | AJ25: =SUM(E25:AI25)/AM25*50/100 -> 0 | AM25: =AM9 -> 28
A26: 12 | B26: Kepatuhan pemakaian APD dengan benar | D26: 100 | AJ26: =SUM(E26:AI26)/AM26*50/100 -> 0 | AM26: =AM9 -> 28
A27: 13 | B27: Kepatuhan kebersihan tangan | D27: 100 | AJ27: =SUM(E27:AI27)/AM27*50/100 -> 0 | AM27: =AM9 -> 28
A28: 14 | B28: Kepatuhan upaya pencegahan resiko pasien jatuh | D28: 100 | AJ28: =SUM(E28:AI28)/AM28*50/100 -> 0 | AM28: =AM9 -> 28
A29: 15 | B29: Kepatuhan melaksanakan hand over antar petugas dengan metode SBAR | D29: 100 | AJ29: =SUM(E29:AI29)/AM29*50/100 -> 0 | AM29: =AM9 -> 28
A30: 16 | B30: Kepatuhan melaksanakan double chek obat high allert | D30: 100 | AJ30: =SUM(E30:AI30)/AM30*50/100 -> 0 | AM30: =AM9 -> 28
A31: 17 | B31: Kemampuan menangani life saving anak dan dewasa | D31: 100 | AJ31: =SUM(E31:AI31)/AM31*50/100 -> 0 | AM31: =AM9 -> 28
A32: 18 | B32: Kecepatan pelayanan pasien dengan risiko tinggi | D32: 100 | AJ32: =SUM(E32:AI32)/AM32*50/100 -> 0 | AM32: =AM9 -> 28
A33: JUMLAH RATA - RATA | E33: =AVERAGE(E20:E32) -> #DIV/0! | F33: =AVERAGE(F20:F32) -> #DIV/0! | G33: =AVERAGE(G20:G32) -> #DIV/0! | H33: =AVERAGE(H20:H32) -> #DIV/0! | I33: =AVERAGE(I20:I32) -> #DIV/0! | J33: =AVERAGE(J20:J32) -> #DIV/0! | K33: =AVERAGE(K20:K32) -> #DIV/0! | L33: =AVERAGE(L20:L32) -> #DIV/0! | ... AJ33: =AVERAGE(AJ20:AJ32) -> 0 | AM33: =AM9 -> 28
A34: TOTAL NILAI PERILAKU + PENGEMBANGAN PROFESI + KINERJA KLINIS | AJ34: =AJ14+AJ18+AJ33 -> 0 | AM34: =AM9 -> 28

Sheet APR
A1: LOGBOOK PERAWAT
A2: RSU SAKINA IDAMAN
A4: NAMA | C4: =": " &'Data Perawat'!E2 -> : Tulis nama di sini
A5: PK | C5: =": " &'Data Perawat'!E3 -> : Tulis PK di sini
A6: UNIT | C6: =": " &'Data Perawat'!E4 -> : Tulis Unit di sini
A8: NO | B8: INDIKATOR YANG DINILAI | D8: TARGET (%) | E8: BULAN : APRIL | AJ8: CAPAIAN (%) | AL8: RUMUS WAJIB DIISI
E9: 1 | F9: 2 | G9: 3 | H9: 4 | I9: 5 | J9: 6 | K9: 7 | L9: 8 | M9: 9 | N9: 10 | O9: 11 | P9: 12 | Q9: 13 | R9: 14 | S9: 15 | T9: 16 | U9: 17 | V9: 18 | W9: 19 | X9: 20 | Y9: 21 | Z9: 22 | AA9: 23 | AB9: 24 | AC9: 25 | AD9: 26 | AE9: 27 | AF9: 28 | AG9: 29 | AH9: 30 | AI9: 31 | AL9: JUMLAH HARI : | AM9: 28
A10: A. PERILAKU ( 40 % ) | AM10: =AM9 -> 28
A11: 1 | B11: Melaporkan insiden keselamatan pasien | D11: 100 | AJ11: =SUM(E11:AI11)/AM9*40/100 -> 0 | AM11: =AM9 -> 28
A12: 2 | B12: Ada keluhan dari teman sejawat/profesi lain/pasien dan keluarga | D12: 100 | AJ12: =SUM(E12:AI12)/AM10*40/100 -> 0 | AM12: =AM9 -> 28
A13: 3 | B13: Kepatuhan terhadap kode etik keperawatan | D13: 100 | AJ13: =SUM(E13:AI13)/AM11*40/100 -> 0 | AM13: =AM9 -> 28
A14: JUMLAH RATA - RATA | E14: =AVERAGE(E11:E13) -> #DIV/0! | F14: =AVERAGE(F11:F13) -> #DIV/0! | G14: =AVERAGE(G11:G13) -> #DIV/0! | H14: =AVERAGE(H11:H13) -> #DIV/0! | I14: =AVERAGE(I11:I13) -> #DIV/0! | J14: =AVERAGE(J11:J13) -> #DIV/0! | K14: =AVERAGE(K11:K13) -> #DIV/0! | L14: =AVERAGE(L11:L13) -> #DIV/0! | ... AJ14: =AVERAGE(AJ11:AJ13) -> 0 | AM14: =AM9 -> 28
A15: B. PENGEMBANGAN PROFESI (10%)
A16: 4 | B16: Menunjukan perilaku bertanggung gugat terhadap praktek profesional | D16: 100 | AJ16: =SUM(E16:AI16)/AM16*10/100 -> 0 | AM16: =AM9 -> 28
A17: 5 | B17: Kepatuhan dalam memberikan pendidikan pasien dan keluarga | D17: 100 | AJ17: =SUM(E17:AI17)/AM17*10/100 -> 0 | AM17: =AM9 -> 28
A18: JUMLAH RATA - RATA | E18: =AVERAGE(E16:E17) -> #DIV/0! | F18: =AVERAGE(F16:F17) -> #DIV/0! | G18: =AVERAGE(G16:G17) -> #DIV/0! | H18: =AVERAGE(H16:H17) -> #DIV/0! | I18: =AVERAGE(I16:I17) -> #DIV/0! | J18: =AVERAGE(J16:J17) -> #DIV/0! | K18: =AVERAGE(K16:K17) -> #DIV/0! | L18: =AVERAGE(L16:L17) -> #DIV/0! | ... AJ18: =AVERAGE(AJ16:AJ17) -> 0 | AM18: =AM9 -> 28
A19: C. KINERJA KLINIS (50%)
A20: 6 | B20: Pengkajian Pasien | D20: 100 | AJ20: =SUM(E20:AI20)/AM20*50/100 -> 0 | AM20: =AM9 -> 28
A21: 7 | B21: Menetapkan diagnosa Keperawatan | D21: 100 | AJ21: =SUM(E21:AI21)/AM21*50/100 -> 0 | AM21: =AM9 -> 28
A22: 8 | B22: Menyusun rencana keperawatan | D22: 100 | AJ22: =SUM(E22:AI22)/AM22*50/100 -> 0 | AM22: =AM9 -> 28
A23: 9 | B23: Melakukan tindakan keperawatan | D23: 100 | AJ23: =SUM(E23:AI23)/AM23*50/100 -> 0 | AM23: =AM9 -> 28
A24: 10 | B24: Melakukan dokumentasi keperawatan | D24: 100 | AJ24: =SUM(E24:AI24)/AM24*50/100 -> 0 | AM24: =AM9 -> 28
A25: 11 | B25: Kepatuhan identifikasi pasien | D25: 100 | AJ25: =SUM(E25:AI25)/AM25*50/100 -> 0 | AM25: =AM9 -> 28
A26: 12 | B26: Kepatuhan pemakaian APD dengan benar | D26: 100 | AJ26: =SUM(E26:AI26)/AM26*50/100 -> 0 | AM26: =AM9 -> 28
A27: 13 | B27: Kepatuhan kebersihan tangan | D27: 100 | AJ27: =SUM(E27:AI27)/AM27*50/100 -> 0 | AM27: =AM9 -> 28
A28: 14 | B28: Kepatuhan upaya pencegahan resiko pasien jatuh | D28: 100 | AJ28: =SUM(E28:AI28)/AM28*50/100 -> 0 | AM28: =AM9 -> 28
A29: 15 | B29: Kepatuhan melaksanakan hand over antar petugas dengan metode SBAR | D29: 100 | AJ29: =SUM(E29:AI29)/AM29*50/100 -> 0 | AM29: =AM9 -> 28
A30: 16 | B30: Kepatuhan melaksanakan double chek obat high allert | D30: 100 | AJ30: =SUM(E30:AI30)/AM30*50/100 -> 0 | AM30: =AM9 -> 28
A31: 17 | B31: Kemampuan menangani life saving anak dan dewasa | D31: 100 | AJ31: =SUM(E31:AI31)/AM31*50/100 -> 0 | AM31: =AM9 -> 28
A32: 18 | B32: Kecepatan pelayanan pasien dengan risiko tinggi | D32: 100 | AJ32: =SUM(E32:AI32)/AM32*50/100 -> 0 | AM32: =AM9 -> 28
A33: JUMLAH RATA - RATA | E33: =AVERAGE(E20:E32) -> #DIV/0! | F33: =AVERAGE(F20:F32) -> #DIV/0! | G33: =AVERAGE(G20:G32) -> #DIV/0! | H33: =AVERAGE(H20:H32) -> #DIV/0! | I33: =AVERAGE(I20:I32) -> #DIV/0! | J33: =AVERAGE(J20:J32) -> #DIV/0! | K33: =AVERAGE(K20:K32) -> #DIV/0! | L33: =AVERAGE(L20:L32) -> #DIV/0! | ... AJ33: =AVERAGE(AJ20:AJ32) -> 0 | AM33: =AM9 -> 28
A34: TOTAL NILAI PERILAKU + PENGEMBANGAN PROFESI + KINERJA KLINIS | AJ34: =AJ14+AJ18+AJ33 -> 0 | AM34: =AM9 -> 28

Sheet MEI
A1: LOGBOOK PERAWAT
A2: RSU SAKINA IDAMAN
A4: NAMA | C4: =": " &'Data Perawat'!E2 -> : Tulis nama di sini
A5: PK | C5: =": " &'Data Perawat'!E3 -> : Tulis PK di sini
A6: UNIT | C6: =": " &'Data Perawat'!E4 -> : Tulis Unit di sini
A8: NO | B8: INDIKATOR YANG DINILAI | D8: TARGET (%) | E8: BULAN : MEI | AJ8: CAPAIAN (%) | AL8: RUMUS WAJIB DIISI
E9: 1 | F9: 2 | G9: 3 | H9: 4 | I9: 5 | J9: 6 | K9: 7 | L9: 8 | M9: 9 | N9: 10 | O9: 11 | P9: 12 | Q9: 13 | R9: 14 | S9: 15 | T9: 16 | U9: 17 | V9: 18 | W9: 19 | X9: 20 | Y9: 21 | Z9: 22 | AA9: 23 | AB9: 24 | AC9: 25 | AD9: 26 | AE9: 27 | AF9: 28 | AG9: 29 | AH9: 30 | AI9: 31 | AL9: JUMLAH HARI : | AM9: 28
A10: A. PERILAKU ( 40 % ) | AM10: =AM9 -> 28
A11: 1 | B11: Melaporkan insiden keselamatan pasien | D11: 100 | AJ11: =SUM(E11:AI11)/AM9*40/100 -> 0 | AM11: =AM9 -> 28
A12: 2 | B12: Ada keluhan dari teman sejawat/profesi lain/pasien dan keluarga | D12: 100 | AJ12: =SUM(E12:AI12)/AM10*40/100 -> 0 | AM12: =AM9 -> 28
A13: 3 | B13: Kepatuhan terhadap kode etik keperawatan | D13: 100 | AJ13: =SUM(E13:AI13)/AM11*40/100 -> 0 | AM13: =AM9 -> 28
A14: JUMLAH RATA - RATA | E14: =AVERAGE(E11:E13) -> #DIV/0! | F14: =AVERAGE(F11:F13) -> #DIV/0! | G14: =AVERAGE(G11:G13) -> #DIV/0! | H14: =AVERAGE(H11:H13) -> #DIV/0! | I14: =AVERAGE(I11:I13) -> #DIV/0! | J14: =AVERAGE(J11:J13) -> #DIV/0! | K14: =AVERAGE(K11:K13) -> #DIV/0! | L14: =AVERAGE(L11:L13) -> #DIV/0! | ... AJ14: =AVERAGE(AJ11:AJ13) -> 0 | AM14: =AM9 -> 28
A15: B. PENGEMBANGAN PROFESI (10%)
A16: 4 | B16: Menunjukan perilaku bertanggung gugat terhadap praktek profesional | D16: 100 | AJ16: =SUM(E16:AI16)/AM16*10/100 -> 0 | AM16: =AM9 -> 28
A17: 5 | B17: Kepatuhan dalam memberikan pendidikan pasien dan keluarga | D17: 100 | AJ17: =SUM(E17:AI17)/AM17*10/100 -> 0 | AM17: =AM9 -> 28
A18: JUMLAH RATA - RATA | E18: =AVERAGE(E16:E17) -> #DIV/0! | F18: =AVERAGE(F16:F17) -> #DIV/0! | G18: =AVERAGE(G16:G17) -> #DIV/0! | H18: =AVERAGE(H16:H17) -> #DIV/0! | I18: =AVERAGE(I16:I17) -> #DIV/0! | J18: =AVERAGE(J16:J17) -> #DIV/0! | K18: =AVERAGE(K16:K17) -> #DIV/0! | L18: =AVERAGE(L16:L17) -> #DIV/0! | ... AJ18: =AVERAGE(AJ16:AJ17) -> 0 | AM18: =AM9 -> 28
A19: C. KINERJA KLINIS (50%)
A20: 6 | B20: Pengkajian Pasien | D20: 100 | AJ20: =SUM(E20:AI20)/AM20*50/100 -> 0 | AM20: =AM9 -> 28
A21: 7 | B21: Menetapkan diagnosa Keperawatan | D21: 100 | AJ21: =SUM(E21:AI21)/AM21*50/100 -> 0 | AM21: =AM9 -> 28
A22: 8 | B22: Menyusun rencana keperawatan | D22: 100 | AJ22: =SUM(E22:AI22)/AM22*50/100 -> 0 | AM22: =AM9 -> 28
A23: 9 | B23: Melakukan tindakan keperawatan | D23: 100 | AJ23: =SUM(E23:AI23)/AM23*50/100 -> 0 | AM23: =AM9 -> 28
A24: 10 | B24: Melakukan dokumentasi keperawatan | D24: 100 | AJ24: =SUM(E24:AI24)/AM24*50/100 -> 0 | AM24: =AM9 -> 28
A25: 11 | B25: Kepatuhan identifikasi pasien | D25: 100 | AJ25: =SUM(E25:AI25)/AM25*50/100 -> 0 | AM25: =AM9 -> 28
A26: 12 | B26: Kepatuhan pemakaian APD dengan benar | D26: 100 | AJ26: =SUM(E26:AI26)/AM26*50/100 -> 0 | AM26: =AM9 -> 28
A27: 13 | B27: Kepatuhan kebersihan tangan | D27: 100 | AJ27: =SUM(E27:AI27)/AM27*50/100 -> 0 | AM27: =AM9 -> 28
A28: 14 | B28: Kepatuhan upaya pencegahan resiko pasien jatuh | D28: 100 | AJ28: =SUM(E28:AI28)/AM28*50/100 -> 0 | AM28: =AM9 -> 28
A29: 15 | B29: Kepatuhan melaksanakan hand over antar petugas dengan metode SBAR | D29: 100 | AJ29: =SUM(E29:AI29)/AM29*50/100 -> 0 | AM29: =AM9 -> 28
A30: 16 | B30: Kepatuhan melaksanakan double chek obat high allert | D30: 100 | AJ30: =SUM(E30:AI30)/AM30*50/100 -> 0 | AM30: =AM9 -> 28
A31: 17 | B31: Kemampuan menangani life saving anak dan dewasa | D31: 100 | AJ31: =SUM(E31:AI31)/AM31*50/100 -> 0 | AM31: =AM9 -> 28
A32: 18 | B32: Kecepatan pelayanan pasien dengan risiko tinggi | D32: 100 | AJ32: =SUM(E32:AI32)/AM32*50/100 -> 0 | AM32: =AM9 -> 28
A33: JUMLAH RATA - RATA | E33: =AVERAGE(E20:E32) -> #DIV/0! | F33: =AVERAGE(F20:F32) -> #DIV/0! | G33: =AVERAGE(G20:G32) -> #DIV/0! | H33: =AVERAGE(H20:H32) -> #DIV/0! | I33: =AVERAGE(I20:I32) -> #DIV/0! | J33: =AVERAGE(J20:J32) -> #DIV/0! | K33: =AVERAGE(K20:K32) -> #DIV/0! | L33: =AVERAGE(L20:L32) -> #DIV/0! | ... AJ33: =AVERAGE(AJ20:AJ32) -> 0 | AM33: =AM9 -> 28
A34: TOTAL NILAI PERILAKU + PENGEMBANGAN PROFESI + KINERJA KLINIS | AJ34: =AJ14+AJ18+AJ33 -> 0 | AM34: =AM9 -> 28

Sheet JUN
A1: LOGBOOK PERAWAT
A2: RSU SAKINA IDAMAN
A4: NAMA | C4: =": " &'Data Perawat'!E2 -> : Tulis nama di sini
A5: PK | C5: =": " &'Data Perawat'!E3 -> : Tulis PK di sini
A6: UNIT | C6: =": " &'Data Perawat'!E4 -> : Tulis Unit di sini
A8: NO | B8: INDIKATOR YANG DINILAI | D8: TARGET (%) | E8: BULAN : JUNI | AJ8: CAPAIAN (%) | AL8: RUMUS WAJIB DIISI
E9: 1 | F9: 2 | G9: 3 | H9: 4 | I9: 5 | J9: 6 | K9: 7 | L9: 8 | M9: 9 | N9: 10 | O9: 11 | P9: 12 | Q9: 13 | R9: 14 | S9: 15 | T9: 16 | U9: 17 | V9: 18 | W9: 19 | X9: 20 | Y9: 21 | Z9: 22 | AA9: 23 | AB9: 24 | AC9: 25 | AD9: 26 | AE9: 27 | AF9: 28 | AG9: 29 | AH9: 30 | AI9: 31 | AL9: JUMLAH HARI : | AM9: 28
A10: A. PERILAKU ( 40 % ) | AM10: =AM9 -> 28
A11: 1 | B11: Melaporkan insiden keselamatan pasien | D11: 100 | AJ11: =SUM(E11:AI11)/AM9*40/100 -> 0 | AM11: =AM9 -> 28
A12: 2 | B12: Ada keluhan dari teman sejawat/profesi lain/pasien dan keluarga | D12: 100 | AJ12: =SUM(E12:AI12)/AM10*40/100 -> 0 | AM12: =AM9 -> 28
A13: 3 | B13: Kepatuhan terhadap kode etik keperawatan | D13: 100 | AJ13: =SUM(E13:AI13)/AM11*40/100 -> 0 | AM13: =AM9 -> 28
A14: JUMLAH RATA - RATA | E14: =AVERAGE(E11:E13) -> #DIV/0! | F14: =AVERAGE(F11:F13) -> #DIV/0! | G14: =AVERAGE(G11:G13) -> #DIV/0! | H14: =AVERAGE(H11:H13) -> #DIV/0! | I14: =AVERAGE(I11:I13) -> #DIV/0! | J14: =AVERAGE(J11:J13) -> #DIV/0! | K14: =AVERAGE(K11:K13) -> #DIV/0! | L14: =AVERAGE(L11:L13) -> #DIV/0! | ... AJ14: =AVERAGE(AJ11:AJ13) -> 0 | AM14: =AM9 -> 28
A15: B. PENGEMBANGAN PROFESI (10%)
A16: 4 | B16: Menunjukan perilaku bertanggung gugat terhadap praktek profesional | D16: 100 | AJ16: =SUM(E16:AI16)/AM16*10/100 -> 0 | AM16: =AM9 -> 28
A17: 5 | B17: Kepatuhan dalam memberikan pendidikan pasien dan keluarga | D17: 100 | AJ17: =SUM(E17:AI17)/AM17*10/100 -> 0 | AM17: =AM9 -> 28
A18: JUMLAH RATA - RATA | E18: =AVERAGE(E16:E17) -> #DIV/0! | F18: =AVERAGE(F16:F17) -> #DIV/0! | G18: =AVERAGE(G16:G17) -> #DIV/0! | H18: =AVERAGE(H16:H17) -> #DIV/0! | I18: =AVERAGE(I16:I17) -> #DIV/0! | J18: =AVERAGE(J16:J17) -> #DIV/0! | K18: =AVERAGE(K16:K17) -> #DIV/0! | L18: =AVERAGE(L16:L17) -> #DIV/0! | ... AJ18: =AVERAGE(AJ16:AJ17) -> 0 | AM18: =AM9 -> 28
A19: C. KINERJA KLINIS (50%)
A20: 6 | B20: Pengkajian Pasien | D20: 100 | AJ20: =SUM(E20:AI20)/AM20*50/100 -> 0 | AM20: =AM9 -> 28
A21: 7 | B21: Menetapkan diagnosa Keperawatan | D21: 100 | AJ21: =SUM(E21:AI21)/AM21*50/100 -> 0 | AM21: =AM9 -> 28
A22: 8 | B22: Menyusun rencana keperawatan | D22: 100 | AJ22: =SUM(E22:AI22)/AM22*50/100 -> 0 | AM22: =AM9 -> 28
A23: 9 | B23: Melakukan tindakan keperawatan | D23: 100 | AJ23: =SUM(E23:AI23)/AM23*50/100 -> 0 | AM23: =AM9 -> 28
A24: 10 | B24: Melakukan dokumentasi keperawatan | D24: 100 | AJ24: =SUM(E24:AI24)/AM24*50/100 -> 0 | AM24: =AM9 -> 28
A25: 11 | B25: Kepatuhan identifikasi pasien | D25: 100 | AJ25: =SUM(E25:AI25)/AM25*50/100 -> 0 | AM25: =AM9 -> 28
A26: 12 | B26: Kepatuhan pemakaian APD dengan benar | D26: 100 | AJ26: =SUM(E26:AI26)/AM26*50/100 -> 0 | AM26: =AM9 -> 28
A27: 13 | B27: Kepatuhan kebersihan tangan | D27: 100 | AJ27: =SUM(E27:AI27)/AM27*50/100 -> 0 | AM27: =AM9 -> 28
A28: 14 | B28: Kepatuhan upaya pencegahan resiko pasien jatuh | D28: 100 | AJ28: =SUM(E28:AI28)/AM28*50/100 -> 0 | AM28: =AM9 -> 28
A29: 15 | B29: Kepatuhan melaksanakan hand over antar petugas dengan metode SBAR | D29: 100 | AJ29: =SUM(E29:AI29)/AM29*50/100 -> 0 | AM29: =AM9 -> 28
A30: 16 | B30: Kepatuhan melaksanakan double chek obat high allert | D30: 100 | AJ30: =SUM(E30:AI30)/AM30*50/100 -> 0 | AM30: =AM9 -> 28
A31: 17 | B31: Kemampuan menangani life saving anak dan dewasa | D31: 100 | AJ31: =SUM(E31:AI31)/AM31*50/100 -> 0 | AM31: =AM9 -> 28
A32: 18 | B32: Kecepatan pelayanan pasien dengan risiko tinggi | D32: 100 | AJ32: =SUM(E32:AI32)/AM32*50/100 -> 0 | AM32: =AM9 -> 28
A33: JUMLAH RATA - RATA | E33: =AVERAGE(E20:E32) -> #DIV/0! | F33: =AVERAGE(F20:F32) -> #DIV/0! | G33: =AVERAGE(G20:G32) -> #DIV/0! | H33: =AVERAGE(H20:H32) -> #DIV/0! | I33: =AVERAGE(I20:I32) -> #DIV/0! | J33: =AVERAGE(J20:J32) -> #DIV/0! | K33: =AVERAGE(K20:K32) -> #DIV/0! | L33: =AVERAGE(L20:L32) -> #DIV/0! | ... AJ33: =AVERAGE(AJ20:AJ32) -> 0 | AM33: =AM9 -> 28
A34: TOTAL NILAI PERILAKU + PENGEMBANGAN PROFESI + KINERJA KLINIS | AJ34: =AJ14+AJ18+AJ33 -> 0 | AM34: =AM9 -> 28

Sheet JUL
A1: LOGBOOK PERAWAT
A2: RSU SAKINA IDAMAN
A4: NAMA | C4: =": " &'Data Perawat'!E2 -> : Tulis nama di sini
A5: PK | C5: =": " &'Data Perawat'!E3 -> : Tulis PK di sini
A6: UNIT | C6: =": " &'Data Perawat'!E4 -> : Tulis Unit di sini
A8: NO | B8: INDIKATOR YANG DINILAI | D8: TARGET (%) | E8: BULAN : JULI | AJ8: CAPAIAN (%) | AL8: RUMUS WAJIB DIISI
E9: 1 | F9: 2 | G9: 3 | H9: 4 | I9: 5 | J9: 6 | K9: 7 | L9: 8 | M9: 9 | N9: 10 | O9: 11 | P9: 12 | Q9: 13 | R9: 14 | S9: 15 | T9: 16 | U9: 17 | V9: 18 | W9: 19 | X9: 20 | Y9: 21 | Z9: 22 | AA9: 23 | AB9: 24 | AC9: 25 | AD9: 26 | AE9: 27 | AF9: 28 | AG9: 29 | AH9: 30 | AI9: 31 | AL9: JUMLAH HARI : | AM9: 28
A10: A. PERILAKU ( 40 % ) | AM10: =AM9 -> 28
A11: 1 | B11: Melaporkan insiden keselamatan pasien | D11: 100 | AJ11: =SUM(E11:AI11)/AM9*40/100 -> 0 | AM11: =AM9 -> 28
A12: 2 | B12: Ada keluhan dari teman sejawat/profesi lain/pasien dan keluarga | D12: 100 | AJ12: =SUM(E12:AI12)/AM10*40/100 -> 0 | AM12: =AM9 -> 28
A13: 3 | B13: Kepatuhan terhadap kode etik keperawatan | D13: 100 | AJ13: =SUM(E13:AI13)/AM11*40/100 -> 0 | AM13: =AM9 -> 28
A14: JUMLAH RATA - RATA | E14: =AVERAGE(E11:E13) -> #DIV/0! | F14: =AVERAGE(F11:F13) -> #DIV/0! | G14: =AVERAGE(G11:G13) -> #DIV/0! | H14: =AVERAGE(H11:H13) -> #DIV/0! | I14: =AVERAGE(I11:I13) -> #DIV/0! | J14: =AVERAGE(J11:J13) -> #DIV/0! | K14: =AVERAGE(K11:K13) -> #DIV/0! | L14: =AVERAGE(L11:L13) -> #DIV/0! | ... AJ14: =AVERAGE(AJ11:AJ13) -> 0 | AM14: =AM9 -> 28
A15: B. PENGEMBANGAN PROFESI (10%)
A16: 4 | B16: Menunjukan perilaku bertanggung gugat terhadap praktek profesional | D16: 100 | AJ16: =SUM(E16:AI16)/AM16*10/100 -> 0 | AM16: =AM9 -> 28
A17: 5 | B17: Kepatuhan dalam memberikan pendidikan pasien dan keluarga | D17: 100 | AJ17: =SUM(E17:AI17)/AM17*10/100 -> 0 | AM17: =AM9 -> 28
A18: JUMLAH RATA - RATA | E18: =AVERAGE(E16:E17) -> #DIV/0! | F18: =AVERAGE(F16:F17) -> #DIV/0! | G18: =AVERAGE(G16:G17) -> #DIV/0! | H18: =AVERAGE(H16:H17) -> #DIV/0! | I18: =AVERAGE(I16:I17) -> #DIV/0! | J18: =AVERAGE(J16:J17) -> #DIV/0! | K18: =AVERAGE(K16:K17) -> #DIV/0! | L18: =AVERAGE(L16:L17) -> #DIV/0! | ... AJ18: =AVERAGE(AJ16:AJ17) -> 0 | AM18: =AM9 -> 28
A19: C. KINERJA KLINIS (50%)
A20: 6 | B20: Pengkajian Pasien | D20: 100 | AJ20: =SUM(E20:AI20)/AM20*50/100 -> 0 | AM20: =AM9 -> 28
A21: 7 | B21: Menetapkan diagnosa Keperawatan | D21: 100 | AJ21: =SUM(E21:AI21)/AM21*50/100 -> 0 | AM21: =AM9 -> 28
A22: 8 | B22: Menyusun rencana keperawatan | D22: 100 | AJ22: =SUM(E22:AI22)/AM22*50/100 -> 0 | AM22: =AM9 -> 28
A23: 9 | B23: Melakukan tindakan keperawatan | D23: 100 | AJ23: =SUM(E23:AI23)/AM23*50/100 -> 0 | AM23: =AM9 -> 28
A24: 10 | B24: Melakukan dokumentasi keperawatan | D24: 100 | AJ24: =SUM(E24:AI24)/AM24*50/100 -> 0 | AM24: =AM9 -> 28
A25: 11 | B25: Kepatuhan identifikasi pasien | D25: 100 | AJ25: =SUM(E25:AI25)/AM25*50/100 -> 0 | AM25: =AM9 -> 28
A26: 12 | B26: Kepatuhan pemakaian APD dengan benar | D26: 100 | AJ26: =SUM(E26:AI26)/AM26*50/100 -> 0 | AM26: =AM9 -> 28
A27: 13 | B27: Kepatuhan kebersihan tangan | D27: 100 | AJ27: =SUM(E27:AI27)/AM27*50/100 -> 0 | AM27: =AM9 -> 28
A28: 14 | B28: Kepatuhan upaya pencegahan resiko pasien jatuh | D28: 100 | AJ28: =SUM(E28:AI28)/AM28*50/100 -> 0 | AM28: =AM9 -> 28
A29: 15 | B29: Kepatuhan melaksanakan hand over antar petugas dengan metode SBAR | D29: 100 | AJ29: =SUM(E29:AI29)/AM29*50/100 -> 0 | AM29: =AM9 -> 28
A30: 16 | B30: Kepatuhan melaksanakan double chek obat high allert | D30: 100 | AJ30: =SUM(E30:AI30)/AM30*50/100 -> 0 | AM30: =AM9 -> 28
A31: 17 | B31: Kemampuan menangani life saving anak dan dewasa | D31: 100 | AJ31: =SUM(E31:AI31)/AM31*50/100 -> 0 | AM31: =AM9 -> 28
A32: 18 | B32: Kecepatan pelayanan pasien dengan risiko tinggi | D32: 100 | AJ32: =SUM(E32:AI32)/AM32*50/100 -> 0 | AM32: =AM9 -> 28
A33: JUMLAH RATA - RATA | E33: =AVERAGE(E20:E32) -> #DIV/0! | F33: =AVERAGE(F20:F32) -> #DIV/0! | G33: =AVERAGE(G20:G32) -> #DIV/0! | H33: =AVERAGE(H20:H32) -> #DIV/0! | I33: =AVERAGE(I20:I32) -> #DIV/0! | J33: =AVERAGE(J20:J32) -> #DIV/0! | K33: =AVERAGE(K20:K32) -> #DIV/0! | L33: =AVERAGE(L20:L32) -> #DIV/0! | ... AJ33: =AVERAGE(AJ20:AJ32) -> 0 | AM33: =AM9 -> 28
A34: TOTAL NILAI PERILAKU + PENGEMBANGAN PROFESI + KINERJA KLINIS | AJ34: =AJ14+AJ18+AJ33 -> 0 | AM34: =AM9 -> 28

Sheet AGST
A1: LOGBOOK PERAWAT
A2: RSU SAKINA IDAMAN
A4: NAMA | C4: =": " &'Data Perawat'!E2 -> : Tulis nama di sini
A5: PK | C5: =": " &'Data Perawat'!E3 -> : Tulis PK di sini
A6: UNIT | C6: =": " &'Data Perawat'!E4 -> : Tulis Unit di sini
A8: NO | B8: INDIKATOR YANG DINILAI | D8: TARGET (%) | E8: BULAN : AGUSTUS | AJ8: CAPAIAN (%) | AL8: RUMUS WAJIB DIISI
E9: 1 | F9: 2 | G9: 3 | H9: 4 | I9: 5 | J9: 6 | K9: 7 | L9: 8 | M9: 9 | N9: 10 | O9: 11 | P9: 12 | Q9: 13 | R9: 14 | S9: 15 | T9: 16 | U9: 17 | V9: 18 | W9: 19 | X9: 20 | Y9: 21 | Z9: 22 | AA9: 23 | AB9: 24 | AC9: 25 | AD9: 26 | AE9: 27 | AF9: 28 | AG9: 29 | AH9: 30 | AI9: 31 | AL9: JUMLAH HARI : | AM9: 28
A10: A. PERILAKU ( 40 % ) | AM10: =AM9 -> 28
A11: 1 | B11: Melaporkan insiden keselamatan pasien | D11: 100 | AJ11: =SUM(E11:AI11)/AM9*40/100 -> 0 | AM11: =AM9 -> 28
A12: 2 | B12: Ada keluhan dari teman sejawat/profesi lain/pasien dan keluarga | D12: 100 | AJ12: =SUM(E12:AI12)/AM10*40/100 -> 0 | AM12: =AM9 -> 28
A13: 3 | B13: Kepatuhan terhadap kode etik keperawatan | D13: 100 | AJ13: =SUM(E13:AI13)/AM11*40/100 -> 0 | AM13: =AM9 -> 28
A14: JUMLAH RATA - RATA | E14: =AVERAGE(E11:E13) -> #DIV/0! | F14: =AVERAGE(F11:F13) -> #DIV/0! | G14: =AVERAGE(G11:G13) -> #DIV/0! | H14: =AVERAGE(H11:H13) -> #DIV/0! | I14: =AVERAGE(I11:I13) -> #DIV/0! | J14: =AVERAGE(J11:J13) -> #DIV/0! | K14: =AVERAGE(K11:K13) -> #DIV/0! | L14: =AVERAGE(L11:L13) -> #DIV/0! | ... AJ14: =AVERAGE(AJ11:AJ13) -> 0 | AM14: =AM9 -> 28
A15: B. PENGEMBANGAN PROFESI (10%)
A16: 4 | B16: Menunjukan perilaku bertanggung gugat terhadap praktek profesional | D16: 100 | AJ16: =SUM(E16:AI16)/AM16*10/100 -> 0 | AM16: =AM9 -> 28
A17: 5 | B17: Kepatuhan dalam memberikan pendidikan pasien dan keluarga | D17: 100 | AJ17: =SUM(E17:AI17)/AM17*10/100 -> 0 | AM17: =AM9 -> 28
A18: JUMLAH RATA - RATA | E18: =AVERAGE(E16:E17) -> #DIV/0! | F18: =AVERAGE(F16:F17) -> #DIV/0! | G18: =AVERAGE(G16:G17) -> #DIV/0! | H18: =AVERAGE(H16:H17) -> #DIV/0! | I18: =AVERAGE(I16:I17) -> #DIV/0! | J18: =AVERAGE(J16:J17) -> #DIV/0! | K18: =AVERAGE(K16:K17) -> #DIV/0! | L18: =AVERAGE(L16:L17) -> #DIV/0! | ... AJ18: =AVERAGE(AJ16:AJ17) -> 0 | AM18: =AM9 -> 28
A19: C. KINERJA KLINIS (50%)
A20: 6 | B20: Pengkajian Pasien | D20: 100 | AJ20: =SUM(E20:AI20)/AM20*50/100 -> 0 | AM20: =AM9 -> 28
A21: 7 | B21: Menetapkan diagnosa Keperawatan | D21: 100 | AJ21: =SUM(E21:AI21)/AM21*50/100 -> 0 | AM21: =AM9 -> 28
A22: 8 | B22: Menyusun rencana keperawatan | D22: 100 | AJ22: =SUM(E22:AI22)/AM22*50/100 -> 0 | AM22: =AM9 -> 28
A23: 9 | B23: Melakukan tindakan keperawatan | D23: 100 | AJ23: =SUM(E23:AI23)/AM23*50/100 -> 0 | AM23: =AM9 -> 28
A24: 10 | B24: Melakukan dokumentasi keperawatan | D24: 100 | AJ24: =SUM(E24:AI24)/AM24*50/100 -> 0 | AM24: =AM9 -> 28
A25: 11 | B25: Kepatuhan identifikasi pasien | D25: 100 | AJ25: =SUM(E25:AI25)/AM25*50/100 -> 0 | AM25: =AM9 -> 28
A26: 12 | B26: Kepatuhan pemakaian APD dengan benar | D26: 100 | AJ26: =SUM(E26:AI26)/AM26*50/100 -> 0 | AM26: =AM9 -> 28
A27: 13 | B27: Kepatuhan kebersihan tangan | D27: 100 | AJ27: =SUM(E27:AI27)/AM27*50/100 -> 0 | AM27: =AM9 -> 28
A28: 14 | B28: Kepatuhan upaya pencegahan resiko pasien jatuh | D28: 100 | AJ28: =SUM(E28:AI28)/AM28*50/100 -> 0 | AM28: =AM9 -> 28
A29: 15 | B29: Kepatuhan melaksanakan hand over antar petugas dengan metode SBAR | D29: 100 | AJ29: =SUM(E29:AI29)/AM29*50/100 -> 0 | AM29: =AM9 -> 28
A30: 16 | B30: Kepatuhan melaksanakan double chek obat high allert | D30: 100 | AJ30: =SUM(E30:AI30)/AM30*50/100 -> 0 | AM30: =AM9 -> 28
A31: 17 | B31: Kemampuan menangani life saving anak dan dewasa | D31: 100 | AJ31: =SUM(E31:AI31)/AM31*50/100 -> 0 | AM31: =AM9 -> 28
A32: 18 | B32: Kecepatan pelayanan pasien dengan risiko tinggi | D32: 100 | AJ32: =SUM(E32:AI32)/AM32*50/100 -> 0 | AM32: =AM9 -> 28
A33: JUMLAH RATA - RATA | E33: =AVERAGE(E20:E32) -> #DIV/0! | F33: =AVERAGE(F20:F32) -> #DIV/0! | G33: =AVERAGE(G20:G32) -> #DIV/0! | H33: =AVERAGE(H20:H32) -> #DIV/0! | I33: =AVERAGE(I20:I32) -> #DIV/0! | J33: =AVERAGE(J20:J32) -> #DIV/0! | K33: =AVERAGE(K20:K32) -> #DIV/0! | L33: =AVERAGE(L20:L32) -> #DIV/0! | ... AJ33: =AVERAGE(AJ20:AJ32) -> 0 | AM33: =AM9 -> 28
A34: TOTAL NILAI PERILAKU + PENGEMBANGAN PROFESI + KINERJA KLINIS | AJ34: =AJ14+AJ18+AJ33 -> 0 | AM34: =AM9 -> 28

Sheet SEP
A1: LOGBOOK PERAWAT
A2: RSU SAKINA IDAMAN
A4: NAMA | C4: =": " &'Data Perawat'!E2 -> : Tulis nama di sini
A5: PK | C5: =": " &'Data Perawat'!E3 -> : Tulis PK di sini
A6: UNIT | C6: =": " &'Data Perawat'!E4 -> : Tulis Unit di sini
A8: NO | B8: INDIKATOR YANG DINILAI | D8: TARGET (%) | E8: BULAN : SEPTEMBER | AJ8: CAPAIAN (%) | AL8: RUMUS WAJIB DIISI
E9: 1 | F9: 2 | G9: 3 | H9: 4 | I9: 5 | J9: 6 | K9: 7 | L9: 8 | M9: 9 | N9: 10 | O9: 11 | P9: 12 | Q9: 13 | R9: 14 | S9: 15 | T9: 16 | U9: 17 | V9: 18 | W9: 19 | X9: 20 | Y9: 21 | Z9: 22 | AA9: 23 | AB9: 24 | AC9: 25 | AD9: 26 | AE9: 27 | AF9: 28 | AG9: 29 | AH9: 30 | AI9: 31 | AL9: JUMLAH HARI : | AM9: 28
A10: A. PERILAKU ( 40 % ) | AM10: =AM9 -> 28
A11: 1 | B11: Melaporkan insiden keselamatan pasien | D11: 100 | AJ11: =SUM(E11:AI11)/AM9*40/100 -> 0 | AM11: =AM9 -> 28
A12: 2 | B12: Ada keluhan dari teman sejawat/profesi lain/pasien dan keluarga | D12: 100 | AJ12: =SUM(E12:AI12)/AM10*40/100 -> 0 | AM12: =AM9 -> 28
A13: 3 | B13: Kepatuhan terhadap kode etik keperawatan | D13: 100 | AJ13: =SUM(E13:AI13)/AM11*40/100 -> 0 | AM13: =AM9 -> 28
A14: JUMLAH RATA - RATA | E14: =AVERAGE(E11:E13) -> #DIV/0! | F14: =AVERAGE(F11:F13) -> #DIV/0! | G14: =AVERAGE(G11:G13) -> #DIV/0! | H14: =AVERAGE(H11:H13) -> #DIV/0! | I14: =AVERAGE(I11:I13) -> #DIV/0! | J14: =AVERAGE(J11:J13) -> #DIV/0! | K14: =AVERAGE(K11:K13) -> #DIV/0! | L14: =AVERAGE(L11:L13) -> #DIV/0! | ... AJ14: =AVERAGE(AJ11:AJ13) -> 0 | AM14: =AM9 -> 28
A15: B. PENGEMBANGAN PROFESI (10%)
A16: 4 | B16: Menunjukan perilaku bertanggung gugat terhadap praktek profesional | D16: 100 | AJ16: =SUM(E16:AI16)/AM16*10/100 -> 0 | AM16: =AM9 -> 28
A17: 5 | B17: Kepatuhan dalam memberikan pendidikan pasien dan keluarga | D17: 100 | AJ17: =SUM(E17:AI17)/AM17*10/100 -> 0 | AM17: =AM9 -> 28
A18: JUMLAH RATA - RATA | E18: =AVERAGE(E16:E17) -> #DIV/0! | F18: =AVERAGE(F16:F17) -> #DIV/0! | G18: =AVERAGE(G16:G17) -> #DIV/0! | H18: =AVERAGE(H16:H17) -> #DIV/0! | I18: =AVERAGE(I16:I17) -> #DIV/0! | J18: =AVERAGE(J16:J17) -> #DIV/0! | K18: =AVERAGE(K16:K17) -> #DIV/0! | L18: =AVERAGE(L16:L17) -> #DIV/0! | ... AJ18: =AVERAGE(AJ16:AJ17) -> 0 | AM18: =AM9 -> 28
A19: C. KINERJA KLINIS (50%)
A20: 6 | B20: Pengkajian Pasien | D20: 100 | AJ20: =SUM(E20:AI20)/AM20*50/100 -> 0 | AM20: =AM9 -> 28
A21: 7 | B21: Menetapkan diagnosa Keperawatan | D21: 100 | AJ21: =SUM(E21:AI21)/AM21*50/100 -> 0 | AM21: =AM9 -> 28
A22: 8 | B22: Menyusun rencana keperawatan | D22: 100 | AJ22: =SUM(E22:AI22)/AM22*50/100 -> 0 | AM22: =AM9 -> 28
A23: 9 | B23: Melakukan tindakan keperawatan | D23: 100 | AJ23: =SUM(E23:AI23)/AM23*50/100 -> 0 | AM23: =AM9 -> 28
A24: 10 | B24: Melakukan dokumentasi keperawatan | D24: 100 | AJ24: =SUM(E24:AI24)/AM24*50/100 -> 0 | AM24: =AM9 -> 28
A25: 11 | B25: Kepatuhan identifikasi pasien | D25: 100 | AJ25: =SUM(E25:AI25)/AM25*50/100 -> 0 | AM25: =AM9 -> 28
A26: 12 | B26: Kepatuhan pemakaian APD dengan benar | D26: 100 | AJ26: =SUM(E26:AI26)/AM26*50/100 -> 0 | AM26: =AM9 -> 28
A27: 13 | B27: Kepatuhan kebersihan tangan | D27: 100 | AJ27: =SUM(E27:AI27)/AM27*50/100 -> 0 | AM27: =AM9 -> 28
A28: 14 | B28: Kepatuhan upaya pencegahan resiko pasien jatuh | D28: 100 | AJ28: =SUM(E28:AI28)/AM28*50/100 -> 0 | AM28: =AM9 -> 28
A29: 15 | B29: Kepatuhan melaksanakan hand over antar petugas dengan metode SBAR | D29: 100 | AJ29: =SUM(E29:AI29)/AM29*50/100 -> 0 | AM29: =AM9 -> 28
A30: 16 | B30: Kepatuhan melaksanakan double chek obat high allert | D30: 100 | AJ30: =SUM(E30:AI30)/AM30*50/100 -> 0 | AM30: =AM9 -> 28
A31: 17 | B31: Kemampuan menangani life saving anak dan dewasa | D31: 100 | AJ31: =SUM(E31:AI31)/AM31*50/100 -> 0 | AM31: =AM9 -> 28
A32: 18 | B32: Kecepatan pelayanan pasien dengan risiko tinggi | D32: 100 | AJ32: =SUM(E32:AI32)/AM32*50/100 -> 0 | AM32: =AM9 -> 28
A33: JUMLAH RATA - RATA | E33: =AVERAGE(E20:E32) -> #DIV/0! | F33: =AVERAGE(F20:F32) -> #DIV/0! | G33: =AVERAGE(G20:G32) -> #DIV/0! | H33: =AVERAGE(H20:H32) -> #DIV/0! | I33: =AVERAGE(I20:I32) -> #DIV/0! | J33: =AVERAGE(J20:J32) -> #DIV/0! | K33: =AVERAGE(K20:K32) -> #DIV/0! | L33: =AVERAGE(L20:L32) -> #DIV/0! | ... AJ33: =AVERAGE(AJ20:AJ32) -> 0 | AM33: =AM9 -> 28
A34: TOTAL NILAI PERILAKU + PENGEMBANGAN PROFESI + KINERJA KLINIS | AJ34: =AJ14+AJ18+AJ33 -> 0 | AM34: =AM9 -> 28

Sheet OKT
A1: LOGBOOK PERAWAT
A2: RSU SAKINA IDAMAN
A4: NAMA | C4: =": " &'Data Perawat'!E2 -> : Tulis nama di sini
A5: PK | C5: =": " &'Data Perawat'!E3 -> : Tulis PK di sini
A6: UNIT | C6: =": " &'Data Perawat'!E4 -> : Tulis Unit di sini
A8: NO | B8: INDIKATOR YANG DINILAI | D8: TARGET (%) | E8: BULAN : OKTOBER | AJ8: CAPAIAN (%) | AL8: RUMUS WAJIB DIISI
E9: 1 | F9: 2 | G9: 3 | H9: 4 | I9: 5 | J9: 6 | K9: 7 | L9: 8 | M9: 9 | N9: 10 | O9: 11 | P9: 12 | Q9: 13 | R9: 14 | S9: 15 | T9: 16 | U9: 17 | V9: 18 | W9: 19 | X9: 20 | Y9: 21 | Z9: 22 | AA9: 23 | AB9: 24 | AC9: 25 | AD9: 26 | AE9: 27 | AF9: 28 | AG9: 29 | AH9: 30 | AI9: 31 | AL9: JUMLAH HARI : | AM9: 28
A10: A. PERILAKU ( 40 % ) | AM10: =AM9 -> 28
A11: 1 | B11: Melaporkan insiden keselamatan pasien | D11: 100 | AJ11: =SUM(E11:AI11)/AM9*40/100 -> 0 | AM11: =AM9 -> 28
A12: 2 | B12: Ada keluhan dari teman sejawat/profesi lain/pasien dan keluarga | D12: 100 | AJ12: =SUM(E12:AI12)/AM10*40/100 -> 0 | AM12: =AM9 -> 28
A13: 3 | B13: Kepatuhan terhadap kode etik keperawatan | D13: 100 | AJ13: =SUM(E13:AI13)/AM11*40/100 -> 0 | AM13: =AM9 -> 28
A14: JUMLAH RATA - RATA | E14: =AVERAGE(E11:E13) -> #DIV/0! | F14: =AVERAGE(F11:F13) -> #DIV/0! | G14: =AVERAGE(G11:G13) -> #DIV/0! | H14: =AVERAGE(H11:H13) -> #DIV/0! | I14: =AVERAGE(I11:I13) -> #DIV/0! | J14: =AVERAGE(J11:J13) -> #DIV/0! | K14: =AVERAGE(K11:K13) -> #DIV/0! | L14: =AVERAGE(L11:L13) -> #DIV/0! | ... AJ14: =AVERAGE(AJ11:AJ13) -> 0 | AM14: =AM9 -> 28
A15: B. PENGEMBANGAN PROFESI (10%)
A16: 4 | B16: Menunjukan perilaku bertanggung gugat terhadap praktek profesional | D16: 100 | AJ16: =SUM(E16:AI16)/AM16*10/100 -> 0 | AM16: =AM9 -> 28
A17: 5 | B17: Kepatuhan dalam memberikan pendidikan pasien dan keluarga | D17: 100 | AJ17: =SUM(E17:AI17)/AM17*10/100 -> 0 | AM17: =AM9 -> 28
A18: JUMLAH RATA - RATA | E18: =AVERAGE(E16:E17) -> #DIV/0! | F18: =AVERAGE(F16:F17) -> #DIV/0! | G18: =AVERAGE(G16:G17) -> #DIV/0! | H18: =AVERAGE(H16:H17) -> #DIV/0! | I18: =AVERAGE(I16:I17) -> #DIV/0! | J18: =AVERAGE(J16:J17) -> #DIV/0! | K18: =AVERAGE(K16:K17) -> #DIV/0! | L18: =AVERAGE(L16:L17) -> #DIV/0! | ... AJ18: =AVERAGE(AJ16:AJ17) -> 0 | AM18: =AM9 -> 28
A19: C. KINERJA KLINIS (50%)
A20: 6 | B20: Pengkajian Pasien | D20: 100 | AJ20: =SUM(E20:AI20)/AM20*50/100 -> 0 | AM20: =AM9 -> 28
A21: 7 | B21: Menetapkan diagnosa Keperawatan | D21: 100 | AJ21: =SUM(E21:AI21)/AM21*50/100 -> 0 | AM21: =AM9 -> 28
A22: 8 | B22: Menyusun rencana keperawatan | D22: 100 | AJ22: =SUM(E22:AI22)/AM22*50/100 -> 0 | AM22: =AM9 -> 28
A23: 9 | B23: Melakukan tindakan keperawatan | D23: 100 | AJ23: =SUM(E23:AI23)/AM23*50/100 -> 0 | AM23: =AM9 -> 28
A24: 10 | B24: Melakukan dokumentasi keperawatan | D24: 100 | AJ24: =SUM(E24:AI24)/AM24*50/100 -> 0 | AM24: =AM9 -> 28
A25: 11 | B25: Kepatuhan identifikasi pasien | D25: 100 | AJ25: =SUM(E25:AI25)/AM25*50/100 -> 0 | AM25: =AM9 -> 28
A26: 12 | B26: Kepatuhan pemakaian APD dengan benar | D26: 100 | AJ26: =SUM(E26:AI26)/AM26*50/100 -> 0 | AM26: =AM9 -> 28
A27: 13 | B27: Kepatuhan kebersihan tangan | D27: 100 | AJ27: =SUM(E27:AI27)/AM27*50/100 -> 0 | AM27: =AM9 -> 28
A28: 14 | B28: Kepatuhan upaya pencegahan resiko pasien jatuh | D28: 100 | AJ28: =SUM(E28:AI28)/AM28*50/100 -> 0 | AM28: =AM9 -> 28
A29: 15 | B29: Kepatuhan melaksanakan hand over antar petugas dengan metode SBAR | D29: 100 | AJ29: =SUM(E29:AI29)/AM29*50/100 -> 0 | AM29: =AM9 -> 28
A30: 16 | B30: Kepatuhan melaksanakan double chek obat high allert | D30: 100 | AJ30: =SUM(E30:AI30)/AM30*50/100 -> 0 | AM30: =AM9 -> 28
A31: 17 | B31: Kemampuan menangani life saving anak dan dewasa | D31: 100 | AJ31: =SUM(E31:AI31)/AM31*50/100 -> 0 | AM31: =AM9 -> 28
A32: 18 | B32: Kecepatan pelayanan pasien dengan risiko tinggi | D32: 100 | AJ32: =SUM(E32:AI32)/AM32*50/100 -> 0 | AM32: =AM9 -> 28
A33: JUMLAH RATA - RATA | E33: =AVERAGE(E20:E32) -> #DIV/0! | F33: =AVERAGE(F20:F32) -> #DIV/0! | G33: =AVERAGE(G20:G32) -> #DIV/0! | H33: =AVERAGE(H20:H32) -> #DIV/0! | I33: =AVERAGE(I20:I32) -> #DIV/0! | J33: =AVERAGE(J20:J32) -> #DIV/0! | K33: =AVERAGE(K20:K32) -> #DIV/0! | L33: =AVERAGE(L20:L32) -> #DIV/0! | ... AJ33: =AVERAGE(AJ20:AJ32) -> 0 | AM33: =AM9 -> 28
A34: TOTAL NILAI PERILAKU + PENGEMBANGAN PROFESI + KINERJA KLINIS | AJ34: =AJ14+AJ18+AJ33 -> 0 | AM34: =AM9 -> 28

Sheet NOV
A1: LOGBOOK PERAWAT
A2: RSU SAKINA IDAMAN
A4: NAMA | C4: =": " &'Data Perawat'!E2 -> : Tulis nama di sini
A5: PK | C5: =": " &'Data Perawat'!E3 -> : Tulis PK di sini
A6: UNIT | C6: =": " &'Data Perawat'!E4 -> : Tulis Unit di sini
A8: NO | B8: INDIKATOR YANG DINILAI | D8: TARGET (%) | E8: BULAN : NOVEMBER | AJ8: CAPAIAN (%) | AL8: RUMUS WAJIB DIISI
E9: 1 | F9: 2 | G9: 3 | H9: 4 | I9: 5 | J9: 6 | K9: 7 | L9: 8 | M9: 9 | N9: 10 | O9: 11 | P9: 12 | Q9: 13 | R9: 14 | S9: 15 | T9: 16 | U9: 17 | V9: 18 | W9: 19 | X9: 20 | Y9: 21 | Z9: 22 | AA9: 23 | AB9: 24 | AC9: 25 | AD9: 26 | AE9: 27 | AF9: 28 | AG9: 29 | AH9: 30 | AI9: 31 | AL9: JUMLAH HARI : | AM9: 28
A10: A. PERILAKU ( 40 % ) | AM10: =AM9 -> 28
A11: 1 | B11: Melaporkan insiden keselamatan pasien | D11: 100 | AJ11: =SUM(E11:AI11)/AM9*40/100 -> 0 | AM11: =AM9 -> 28
A12: 2 | B12: Ada keluhan dari teman sejawat/profesi lain/pasien dan keluarga | D12: 100 | AJ12: =SUM(E12:AI12)/AM10*40/100 -> 0 | AM12: =AM9 -> 28
A13: 3 | B13: Kepatuhan terhadap kode etik keperawatan | D13: 100 | AJ13: =SUM(E13:AI13)/AM11*40/100 -> 0 | AM13: =AM9 -> 28
A14: JUMLAH RATA - RATA | E14: =AVERAGE(E11:E13) -> #DIV/0! | F14: =AVERAGE(F11:F13) -> #DIV/0! | G14: =AVERAGE(G11:G13) -> #DIV/0! | H14: =AVERAGE(H11:H13) -> #DIV/0! | I14: =AVERAGE(I11:I13) -> #DIV/0! | J14: =AVERAGE(J11:J13) -> #DIV/0! | K14: =AVERAGE(K11:K13) -> #DIV/0! | L14: =AVERAGE(L11:L13) -> #DIV/0! | ... AJ14: =AVERAGE(AJ11:AJ13) -> 0 | AM14: =AM9 -> 28
A15: B. PENGEMBANGAN PROFESI (10%)
A16: 4 | B16: Menunjukan perilaku bertanggung gugat terhadap praktek profesional | D16: 100 | AJ16: =SUM(E16:AI16)/AM16*10/100 -> 0 | AM16: =AM9 -> 28
A17: 5 | B17: Kepatuhan dalam memberikan pendidikan pasien dan keluarga | D17: 100 | AJ17: =SUM(E17:AI17)/AM17*10/100 -> 0 | AM17: =AM9 -> 28
A18: JUMLAH RATA - RATA | E18: =AVERAGE(E16:E17) -> #DIV/0! | F18: =AVERAGE(F16:F17) -> #DIV/0! | G18: =AVERAGE(G16:G17) -> #DIV/0! | H18: =AVERAGE(H16:H17) -> #DIV/0! | I18: =AVERAGE(I16:I17) -> #DIV/0! | J18: =AVERAGE(J16:J17) -> #DIV/0! | K18: =AVERAGE(K16:K17) -> #DIV/0! | L18: =AVERAGE(L16:L17) -> #DIV/0! | ... AJ18: =AVERAGE(AJ16:AJ17) -> 0 | AM18: =AM9 -> 28
A19: C. KINERJA KLINIS (50%)
A20: 6 | B20: Pengkajian Pasien | D20: 100 | AJ20: =SUM(E20:AI20)/AM20*50/100 -> 0 | AM20: =AM9 -> 28
A21: 7 | B21: Menetapkan diagnosa Keperawatan | D21: 100 | AJ21: =SUM(E21:AI21)/AM21*50/100 -> 0 | AM21: =AM9 -> 28
A22: 8 | B22: Menyusun rencana keperawatan | D22: 100 | AJ22: =SUM(E22:AI22)/AM22*50/100 -> 0 | AM22: =AM9 -> 28
A23: 9 | B23: Melakukan tindakan keperawatan | D23: 100 | AJ23: =SUM(E23:AI23)/AM23*50/100 -> 0 | AM23: =AM9 -> 28
A24: 10 | B24: Melakukan dokumentasi keperawatan | D24: 100 | AJ24: =SUM(E24:AI24)/AM24*50/100 -> 0 | AM24: =AM9 -> 28
A25: 11 | B25: Kepatuhan identifikasi pasien | D25: 100 | AJ25: =SUM(E25:AI25)/AM25*50/100 -> 0 | AM25: =AM9 -> 28
A26: 12 | B26: Kepatuhan pemakaian APD dengan benar | D26: 100 | AJ26: =SUM(E26:AI26)/AM26*50/100 -> 0 | AM26: =AM9 -> 28
A27: 13 | B27: Kepatuhan kebersihan tangan | D27: 100 | AJ27: =SUM(E27:AI27)/AM27*50/100 -> 0 | AM27: =AM9 -> 28
A28: 14 | B28: Kepatuhan upaya pencegahan resiko pasien jatuh | D28: 100 | AJ28: =SUM(E28:AI28)/AM28*50/100 -> 0 | AM28: =AM9 -> 28
A29: 15 | B29: Kepatuhan melaksanakan hand over antar petugas dengan metode SBAR | D29: 100 | AJ29: =SUM(E29:AI29)/AM29*50/100 -> 0 | AM29: =AM9 -> 28
A30: 16 | B30: Kepatuhan melaksanakan double chek obat high allert | D30: 100 | AJ30: =SUM(E30:AI30)/AM30*50/100 -> 0 | AM30: =AM9 -> 28
A31: 17 | B31: Kemampuan menangani life saving anak dan dewasa | D31: 100 | AJ31: =SUM(E31:AI31)/AM31*50/100 -> 0 | AM31: =AM9 -> 28
A32: 18 | B32: Kecepatan pelayanan pasien dengan risiko tinggi | D32: 100 | AJ32: =SUM(E32:AI32)/AM32*50/100 -> 0 | AM32: =AM9 -> 28
A33: JUMLAH RATA - RATA | E33: =AVERAGE(E20:E32) -> #DIV/0! | F33: =AVERAGE(F20:F32) -> #DIV/0! | G33: =AVERAGE(G20:G32) -> #DIV/0! | H33: =AVERAGE(H20:H32) -> #DIV/0! | I33: =AVERAGE(I20:I32) -> #DIV/0! | J33: =AVERAGE(J20:J32) -> #DIV/0! | K33: =AVERAGE(K20:K32) -> #DIV/0! | L33: =AVERAGE(L20:L32) -> #DIV/0! | ... AJ33: =AVERAGE(AJ20:AJ32) -> 0 | AM33: =AM9 -> 28
A34: TOTAL NILAI PERILAKU + PENGEMBANGAN PROFESI + KINERJA KLINIS | AJ34: =AJ14+AJ18+AJ33 -> 0 | AM34: =AM9 -> 28

Sheet DES
A1: LOGBOOK PERAWAT
A2: RSU SAKINA IDAMAN
A4: NAMA | C4: =": " &'Data Perawat'!E2 -> : Tulis nama di sini
A5: PK | C5: =": " &'Data Perawat'!E3 -> : Tulis PK di sini
A6: UNIT | C6: =": " &'Data Perawat'!E4 -> : Tulis Unit di sini
A8: NO | B8: INDIKATOR YANG DINILAI | D8: TARGET (%) | E8: BULAN : DESEMBER | AJ8: CAPAIAN (%) | AL8: RUMUS WAJIB DIISI
E9: 1 | F9: 2 | G9: 3 | H9: 4 | I9: 5 | J9: 6 | K9: 7 | L9: 8 | M9: 9 | N9: 10 | O9: 11 | P9: 12 | Q9: 13 | R9: 14 | S9: 15 | T9: 16 | U9: 17 | V9: 18 | W9: 19 | X9: 20 | Y9: 21 | Z9: 22 | AA9: 23 | AB9: 24 | AC9: 25 | AD9: 26 | AE9: 27 | AF9: 28 | AG9: 29 | AH9: 30 | AI9: 31 | AL9: JUMLAH HARI : | AM9: 28
A10: A. PERILAKU ( 40 % ) | AM10: =AM9 -> 28
A11: 1 | B11: Melaporkan insiden keselamatan pasien | D11: 100 | AJ11: =SUM(E11:AI11)/AM9*40/100 -> 0 | AM11: =AM9 -> 28
A12: 2 | B12: Ada keluhan dari teman sejawat/profesi lain/pasien dan keluarga | D12: 100 | AJ12: =SUM(E12:AI12)/AM10*40/100 -> 0 | AM12: =AM9 -> 28
A13: 3 | B13: Kepatuhan terhadap kode etik keperawatan | D13: 100 | AJ13: =SUM(E13:AI13)/AM11*40/100 -> 0 | AM13: =AM9 -> 28
A14: JUMLAH RATA - RATA | E14: =AVERAGE(E11:E13) -> #DIV/0! | F14: =AVERAGE(F11:F13) -> #DIV/0! | G14: =AVERAGE(G11:G13) -> #DIV/0! | H14: =AVERAGE(H11:H13) -> #DIV/0! | I14: =AVERAGE(I11:I13) -> #DIV/0! | J14: =AVERAGE(J11:J13) -> #DIV/0! | K14: =AVERAGE(K11:K13) -> #DIV/0! | L14: =AVERAGE(L11:L13) -> #DIV/0! | ... AJ14: =AVERAGE(AJ11:AJ13) -> 0 | AM14: =AM9 -> 28
A15: B. PENGEMBANGAN PROFESI (10%)
A16: 4 | B16: Menunjukan perilaku bertanggung gugat terhadap praktek profesional | D16: 100 | AJ16: =SUM(E16:AI16)/AM16*10/100 -> 0 | AM16: =AM9 -> 28
A17: 5 | B17: Kepatuhan dalam memberikan pendidikan pasien dan keluarga | D17: 100 | AJ17: =SUM(E17:AI17)/AM17*10/100 -> 0 | AM17: =AM9 -> 28
A18: JUMLAH RATA - RATA | E18: =AVERAGE(E16:E17) -> #DIV/0! | F18: =AVERAGE(F16:F17) -> #DIV/0! | G18: =AVERAGE(G16:G17) -> #DIV/0! | H18: =AVERAGE(H16:H17) -> #DIV/0! | I18: =AVERAGE(I16:I17) -> #DIV/0! | J18: =AVERAGE(J16:J17) -> #DIV/0! | K18: =AVERAGE(K16:K17) -> #DIV/0! | L18: =AVERAGE(L16:L17) -> #DIV/0! | ... AJ18: =AVERAGE(AJ16:AJ17) -> 0 | AM18: =AM9 -> 28
A19: C. KINERJA KLINIS (50%)
A20: 6 | B20: Pengkajian Pasien | D20: 100 | AJ20: =SUM(E20:AI20)/AM20*50/100 -> 0 | AM20: =AM9 -> 28
A21: 7 | B21: Menetapkan diagnosa Keperawatan | D21: 100 | AJ21: =SUM(E21:AI21)/AM21*50/100 -> 0 | AM21: =AM9 -> 28
A22: 8 | B22: Menyusun rencana keperawatan | D22: 100 | AJ22: =SUM(E22:AI22)/AM22*50/100 -> 0 | AM22: =AM9 -> 28
A23: 9 | B23: Melakukan tindakan keperawatan | D23: 100 | AJ23: =SUM(E23:AI23)/AM23*50/100 -> 0 | AM23: =AM9 -> 28
A24: 10 | B24: Melakukan dokumentasi keperawatan | D24: 100 | AJ24: =SUM(E24:AI24)/AM24*50/100 -> 0 | AM24: =AM9 -> 28
A25: 11 | B25: Kepatuhan identifikasi pasien | D25: 100 | AJ25: =SUM(E25:AI25)/AM25*50/100 -> 0 | AM25: =AM9 -> 28
A26: 12 | B26: Kepatuhan pemakaian APD dengan benar | D26: 100 | AJ26: =SUM(E26:AI26)/AM26*50/100 -> 0 | AM26: =AM9 -> 28
A27: 13 | B27: Kepatuhan kebersihan tangan | D27: 100 | AJ27: =SUM(E27:AI27)/AM27*50/100 -> 0 | AM27: =AM9 -> 28
A28: 14 | B28: Kepatuhan upaya pencegahan resiko pasien jatuh | D28: 100 | AJ28: =SUM(E28:AI28)/AM28*50/100 -> 0 | AM28: =AM9 -> 28
A29: 15 | B29: Kepatuhan melaksanakan hand over antar petugas dengan metode SBAR | D29: 100 | AJ29: =SUM(E29:AI29)/AM29*50/100 -> 0 | AM29: =AM9 -> 28
A30: 16 | B30: Kepatuhan melaksanakan double chek obat high allert | D30: 100 | AJ30: =SUM(E30:AI30)/AM30*50/100 -> 0 | AM30: =AM9 -> 28
A31: 17 | B31: Kemampuan menangani life saving anak dan dewasa | D31: 100 | AJ31: =SUM(E31:AI31)/AM31*50/100 -> 0 | AM31: =AM9 -> 28
A32: 18 | B32: Kecepatan pelayanan pasien dengan risiko tinggi | D32: 100 | AJ32: =SUM(E32:AI32)/AM32*50/100 -> 0 | AM32: =AM9 -> 28
A33: JUMLAH RATA - RATA | E33: =AVERAGE(E20:E32) -> #DIV/0! | F33: =AVERAGE(F20:F32) -> #DIV/0! | G33: =AVERAGE(G20:G32) -> #DIV/0! | H33: =AVERAGE(H20:H32) -> #DIV/0! | I33: =AVERAGE(I20:I32) -> #DIV/0! | J33: =AVERAGE(J20:J32) -> #DIV/0! | K33: =AVERAGE(K20:K32) -> #DIV/0! | L33: =AVERAGE(L20:L32) -> #DIV/0! | ... AJ33: =AVERAGE(AJ20:AJ32) -> 0 | AM33: =AM9 -> 28
A34: TOTAL NILAI PERILAKU + PENGEMBANGAN PROFESI + KINERJA KLINIS | AJ34: =AJ14+AJ18+AJ33 -> 0 | AM34: =AM9 -> 28

Sheet TAHUNAN
A1: PENILAIAN KINERJA PERAWAT
A2: SESUAI STANDAR AKRIDITASI RUMAH SAKIT
A4: NAMA | C4: =": " &'3'!B33 -> : | D4: ='Data Perawat'!E2 -> Tulis nama di sini
A5: PK | C5: : | D5: ='Data Perawat'!E3 -> Tulis PK di sini
A7: NO | B7: INDIKATOR YANG DINILAI | D7: TAHUN 2023 | P7: RATA - RATA CAPAIAN
D8: JANUARI | E8: FEBRUARI | F8: MARET | G8: APRIL | H8: MEI | I8: JUNI | J8: JULI | K8: AGUSTUS | L8: SEPTEMBER | M8: OKTOBER | N8: NOVEMBER | O8: DESEMBER
A9: A. PERILAKU ( 40 % )
A10: 1 | B10: Melaporkan insiden keselamatan pasien | D10: ='JAN '!AJ11 -> 0.014285714 | E10: =FEB!AJ11 -> 0 | F10: =MAR!AK11 -> 0 | G10: =APR!AL11 -> 0 | H10: =MEI!AJ11 -> 0 | I10: =JUN!AJ11 -> 0 | J10: =JUL!AJ11 -> 0 | K10: =AGST!AJ11 -> 0 | L10: =SEP!AJ11 -> 0 | M10: =OKT!AJ11 -> 0 | N10: =NOV!AJ11 -> 0 | O10: =DES!AJ11 -> 0 | P10: =SUM(D10:O10)/12 -> 0.0011904762
A11: 2 | B11: Tidak ada keluhan dari teman sejawat/profesi lain/pasien dan keluarga | D11: ='JAN '!AJ12 -> 0.014285714 | E11: =FEB!AJ12 -> 0 | F11: =MAR!AK12 -> 0 | G11: =APR!AL12 -> 0 | H11: =MEI!AJ12 -> 0 | I11: =JUN!AJ12 -> 0 | J11: =JUL!AJ12 -> 0 | K11: =AGST!AJ12 -> 0 | L11: =SEP!AJ12 -> 0 | M11: =OKT!AJ12 -> 0 | N11: =NOV!AJ12 -> 0 | O11: =DES!AJ12 -> 0 | P11: =SUM(D11:O11)/12 -> 0.0011904762
A12: 3 | B12: Kepatuhan terhadap kode etik keperawatan | D12: ='JAN '!AJ13 -> 0 | E12: =FEB!AJ13 -> 0 | F12: =MAR!AK13 -> 0 | G12: =APR!AL13 -> 0 | H12: =MEI!AJ13 -> 0 | I12: =JUN!AJ13 -> 0 | J12: =JUL!AJ13 -> 0 | K12: =AGST!AJ13 -> 0 | L12: =SEP!AJ13 -> 0 | M12: =OKT!AJ13 -> 0 | N12: =NOV!AJ13 -> 0 | O12: =DES!AJ13 -> 0 | P12: =SUM(D12:O12)/12 -> 0
A13: JUMLAH RATA - RATA | D13: =AVERAGE(D10:D12) -> 0.0095238095 | E13: =FEB!AJ14 -> 0 | F13: =MAR!AK14 -> 0 | G13: =APR!AL14 -> 0 | H13: =MEI!AJ14 -> 0 | I13: =JUN!AJ14 -> 0 | J13: =JUL!AJ14 -> 0 | K13: =AGST!AJ14 -> 0 | L13: =SEP!AJ14 -> 0 | M13: =OKT!AJ14 -> 0 | N13: =NOV!AJ14 -> 0 | O13: =DES!AJ14 -> 0 | P13: =SUM(D13:O13)/12 -> 0.00079365079
A14: B. PENGEMBANGAN PROFESI (10%)
A15: 1 | B15: Menunjukan perilaku bertanggung gugat terhadap praktek profesional | D15: ='JAN '!AJ16 -> 0 | E15: =FEB!AJ16 -> 0 | F15: =MAR!AK16 -> 0 | G15: =APR!AL16 -> 0 | H15: =MEI!AJ16 -> 0 | I15: =JUN!AJ16 -> 0 | J15: =JUL!AJ16 -> 0 | K15: =AGST!AJ16 -> 0 | L15: =SEP!AJ16 -> 0 | M15: =OKT!AJ16 -> 0 | N15: =NOV!AJ16 -> 0 | O15: =DES!AJ16 -> 0 | P15: =SUM(D15:O15)/12 -> 0
A16: 2 | B16: Kepatuhan dalam memberikan pendidikan pasien dan keluarga | D16: ='JAN '!AJ17 -> 0 | E16: =FEB!AJ17 -> 0 | F16: =MAR!AK17 -> 0 | G16: =APR!AL17 -> 0 | H16: =MEI!AJ17 -> 0 | I16: =JUN!AJ17 -> 0 | J16: =JUL!AJ17 -> 0 | K16: =AGST!AJ17 -> 0 | L16: =SEP!AJ17 -> 0 | M16: =OKT!AJ17 -> 0 | N16: =NOV!AJ17 -> 0 | O16: =DES!AJ17 -> 0 | P16: =SUM(D16:O16)/12 -> 0
A17: JUMLAH RATA - RATA | D17: =AVERAGE(D15:D16) -> 0 | E17: =FEB!AJ18 -> 0 | F17: =MAR!AK18 -> 0 | G17: =APR!AL18 -> 0 | H17: =MEI!AJ18 -> 0 | I17: =JUN!AJ18 -> 0 | J17: =JUL!AJ18 -> 0 | K17: =AGST!AJ18 -> 0 | L17: =SEP!AJ18 -> 0 | M17: =OKT!AJ18 -> 0 | N17: =NOV!AJ18 -> 0 | O17: =DES!AJ18 -> 0 | P17: =SUM(D17:O17)/12 -> 0
A18: C. KINERJA KLINIS (50%)
A19: 1 | B19: Pengkajian Pasien | D19: ='JAN '!AJ20 -> 0 | E19: =FEB!AJ20 -> 0 | F19: =MAR!AK20 -> 0 | G19: =APR!AL20 -> 0 | H19: =MEI!AJ20 -> 0 | I19: =JUN!AJ20 -> 0 | J19: =JUL!AJ20 -> 0 | K19: =AGST!AJ20 -> 0 | L19: =SEP!AJ20 -> 0 | M19: =OKT!AJ20 -> 0 | N19: =NOV!AJ20 -> 0 | O19: =DES!AJ20 -> 0 | P19: =SUM(D19:O19)/12 -> 0
A20: 2 | B20: Menetapkan diagnosa Keperawatan | D20: ='JAN '!AJ21 -> 0 | E20: =FEB!AJ21 -> 0 | F20: =MAR!AK21 -> 0 | G20: =APR!AL21 -> 0 | H20: =MEI!AJ21 -> 0 | I20: =JUN!AJ21 -> 0 | J20: =JUL!AJ21 -> 0 | K20: =AGST!AJ21 -> 0 | L20: =SEP!AJ21 -> 0 | M20: =OKT!AJ21 -> 0 | N20: =NOV!AJ21 -> 0 | O20: =DES!AJ21 -> 0 | P20: =SUM(D20:O20)/12 -> 0
A21: 3 | B21: Menyusun rencana keperawatan | D21: ='JAN '!AJ22 -> 0 | E21: =FEB!AJ22 -> 0 | F21: =MAR!AK22 -> 0 | G21: =APR!AL22 -> 0 | H21: =MEI!AJ22 -> 0 | I21: =JUN!AJ22 -> 0 | J21: =JUL!AJ22 -> 0 | K21: =AGST!AJ22 -> 0 | L21: =SEP!AJ22 -> 0 | M21: =OKT!AJ22 -> 0 | N21: =NOV!AJ22 -> 0 | O21: =DES!AJ22 -> 0 | P21: =SUM(D21:O21)/12 -> 0
A22: 4 | B22: Melakukan tindakan keperawatan | D22: ='JAN '!AJ23 -> 0 | E22: =FEB!AJ23 -> 0 | F22: =MAR!AK23 -> 0 | G22: =APR!AL23 -> 0 | H22: =MEI!AJ23 -> 0 | I22: =JUN!AJ23 -> 0 | J22: =JUL!AJ23 -> 0 | K22: =AGST!AJ23 -> 0 | L22: =SEP!AJ23 -> 0 | M22: =OKT!AJ23 -> 0 | N22: =NOV!AJ23 -> 0 | O22: =DES!AJ23 -> 0 | P22: =SUM(D22:O22)/12 -> 0
