Workbook

Sheet JAN 
A1: PENILAIAN KINERJA PERAWAT
A2: SESUAI STANDAR AKRIDITASI RUMAH SAKIT
A4: NAMA | C4: =": "&'3'!B33 -> :
A5: PK | C5: :
A7: NO | B7: INDIKATOR YANG DINILAI | D7: TARGET (%) | E7: BULAN : JANUARI | AJ7: CAPAIAN (%) | AL7: RUMUS WAJIB DIISI
E8: 1 | F8: 2 | G8: 3 | H8: 4 | I8: 5 | J8: 6 | K8: 7 | L8: 8 | M8: 9 | N8: 10 | O8: 11 | P8: 12 | Q8: 13 | R8: 14 | S8: 15 | T8: 16 | U8: 17 | V8: 18 | W8: 19 | X8: 20 | Y8: 21 | Z8: 22 | AA8: 23 | AB8: 24 | AC8: 25 | AD8: 26 | AE8: 27 | AF8: 28 | AG8: 29 | AH8: 30 | AI8: 31 | AL8: JUMLAH HARI : | AM8: 28
A9: A. PERILAKU ( 40 % ) | AM9: =AM8 -> 28
A10: 1 | B10: Melaporkan insiden keselamatan pasien | D10: 100 | E10: 0 | F10: 0 | I10: 0 | J10: 0 | K10: 0 | L10: 0 | M10: 0 | P10: 0 | Q10: 0 | R10: 0 | T10: 0 | U10: 0 | V10: 0 | W10: 0 | X10: 0 | Y10: 0 | AB10: 0 | AC10: 0 | AD10: 0 | AF10: 0 | AH10: 0 | AI10: 0 | AJ10: =SUM(E10:AI10)/AM8*40/100 -> 0 | AM10: =AM9 -> 28
A11: 2 | B11: Ada keluhan dari teman sejawat/profesi lain/pasien dan keluarga | D11: 100 | E11: 0 | F11: 0 | I11: 0 | J11: 0 | K11: 0 | L11: 0 | M11: 0 | P11: 0 | Q11: 0 | R11: 0 | T11: 0 | U11: 0 | V11: 0 | W11: 0 | X11: 0 | Y11: 0 | AB11: 0 | AC11: 0 | AD11: 0 | AF11: 0 | AH11: 0 | AI11: 0 | AJ11: =SUM(E11:AI11)/AM9*40/100 -> 0 | AM11: =AM10 -> 28
A12: 3 | B12: Kepatuhan terhadap kode etik keperawatan | D12: 100 | E12: 2 | F12: 3 | I12: 4 | J12: 3 | K12: 2 | L12: 4 | M12: 3 | P12: 5 | Q12: 5 | R12: 5 | T12: 2 | U12: 2 | V12: 3 | W12: 5 | X12: 3 | Y12: 4 | AB12: 3 | AC12: 3 | AD12: 3 | AF12: 3 | AH12: 4 | AI12: 5 | AJ12: =SUM(E12:AI12)/AM10*40/100 -> 1.0857143 | AM12: =AM11 -> 28
A13: JUMLAH RATA - RATA | E13: =SUM(E10:E12)/3 -> 0.66666667 | F13: =SUM(F10:F12)/3 -> 1 | G13: =SUM(G10:G12)/3 -> 0 | H13: =SUM(H10:H12)/3 -> 0 | I13: =SUM(I10:I12)/3 -> 1.3333333 | J13: =SUM(J10:J12)/3 -> 1 | K13: =SUM(K10:K12)/3 -> 0.66666667 | L13: =SUM(L10:L12)/3 -> 1.3333333 | ... R13: =SUM(R10:R12)/3 -> 1.6666667 | S13: 0 | T13: =SUM(T10:T12)/3 -> 0.66666667 | U13: =SUM(U10:U12)/3 -> 0.66666667 | V13: =SUM(V10:V12)/3 -> 1 | W13: =SUM(W10:W12)/3 -> 1.6666667 | X13: =SUM(X10:X12)/3 -> 1 | Y13: =SUM(Y10:Y12)/3 -> 1.3333333 | Z13: =SUM(Z10:Z12)/3 -> 0 | AA13: =SUM(AA10:AA12)/3 -> 0 | ... AJ13: =SUM(AJ10:AJ12)/3 -> 0.36190476 | AM13: =AM12 -> 28
A14: B. PENGEMBANGAN PROFESI (10%) | AM14: =AM13 -> 28
A15: 1 | B15: Menunjukan perilaku bertanggung gugat terhadap praktek profesional | D15: 100 | E15: 2 | F15: 3 | I15: 4 | J15: 3 | K15: 2 | L15: 4 | M15: 3 | P15: 5 | Q15: 5 | R15: 5 | T15: 2 | U15: 2 | V15: 3 | W15: 5 | X15: 3 | Y15: 4 | AB15: 3 | AC15: 3 | AD15: 3 | AF15: 3 | AH15: 4 | AI15: 5 | AJ15: =SUM(E15:AI15)/AM15*10/100 -> 0.27142857 | AM15: =AM14 -> 28
A16: 2 | B16: Kepatuhan dalam memberikan pendidikan pasien dan keluarga | D16: 100 | E16: 2 | F16: 3 | I16: 4 | J16: 3 | K16: 2 | L16: 4 | M16: 3 | P16: 5 | Q16: 5 | R16: 5 | T16: 2 | U16: 2 | V16: 3 | W16: 5 | X16: 3 | Y16: 4 | AB16: 3 | AC16: 3 | AD16: 3 | AF16: 3 | AH16: 4 | AI16: 5 | AJ16: =SUM(E16:AI16)/AM16*10/100 -> 0.27142857 | AM16: =AM15 -> 28
A17: JUMLAH RATA - RATA | E17: =SUM(E15:E16)/3 -> 1.3333333 | F17: =SUM(F15:F16)/3 -> 2 | G17: =SUM(G15:G16)/3 -> 0 | H17: =SUM(H15:H16)/3 -> 0 | I17: =SUM(I15:I16)/3 -> 2.6666667 | J17: =SUM(J15:J16)/3 -> 2 | K17: =SUM(K15:K16)/3 -> 1.3333333 | L17: =SUM(L15:L16)/3 -> 2.6666667 | ... AJ17: =SUM(AJ15:AJ16)/3 -> 0.18095238 | AM17: =#REF! -> #REF!
A18: C. KINERJA KLINIS (50%) | AM18: =AM17 -> #REF!
A19: 1 | B19: Pengkajian Pasien | D19: 100 | E19: 2 | F19: 3 | I19: 4 | J19: 3 | K19: 2 | L19: 4 | M19: 3 | P19: 5 | Q19: 5 | R19: 5 | T19: 2 | U19: 2 | V19: 3 | W19: 5 | X19: 3 | Y19: 4 | AB19: 3 | AC19: 3 | AD19: 3 | AF19: 3 | AH19: 4 | AI19: 5
A20: 2 | B20: Menetapkan diagnosa Keperawatan | D20: 100 | E20: 2 | F20: 3 | I20: 4 | J20: 3 | K20: 2 | L20: 4 | M20: 3 | P20: 5 | Q20: 5 | R20: 5 | T20: 2 | U20: 2 | V20: 3 | W20: 5 | X20: 3 | Y20: 4 | AB20: 3 | AC20: 3 | AD20: 3 | AF20: 3 | AH20: 4 | AI20: 5
A21: 3 | B21: Menyusun rencana keperawatan | D21: 100 | E21: 2 | F21: 3 | I21: 4 | J21: 3 | K21: 2 | L21: 4 | M21: 3 | P21: 5 | Q21: 5 | R21: 5 | T21: 2 | U21: 2 | V21: 3 | W21: 5 | X21: 3 | Y21: 4 | AB21: 3 | AC21: 3 | AD21: 3 | AF21: 3 | AH21: 4 | AI21: 5
A22: 4 | B22: Melakukan tindakan keperawatan | D22: 100 | E22: 2 | F22: 3 | I22: 4 | J22: 3 | K22: 2 | L22: 4 | M22: 3 | P22: 5 | Q22: 5 | R22: 5 | T22: 2 | U22: 2 | V22: 3 | W22: 5 | X22: 3 | Y22: 4 | AB22: 3 | AC22: 3 | AD22: 3 | AF22: 3 | AH22: 4 | AI22: 5
A23: 5 | B23: Melakukan dokumentasi keperawatan | D23: 100 | E23: 2 | F23: 3 | I23: 4 | J23: 3 | K23: 2 | L23: 4 | M23: 3 | P23: 5 | Q23: 5 | R23: 5 | T23: 2 | U23: 2 | V23: 3 | W23: 5 | X23: 3 | Y23: 4 | AB23: 3 | AC23: 3 | AD23: 3 | AF23: 3 | AH23: 4 | AI23: 5
A24: 1 | B24: Kepatuhan identifikasi pasien | D24: 100 | E24: 2 | F24: 3 | I24: 4 | J24: 3 | K24: 2 | L24: 4 | M24: 3 | P24: 5 | Q24: 5 | R24: 5 | T24: 2 | U24: 2 | V24: 3 | W24: 5 | X24: 3 | Y24: 4 | AB24: 3 | AC24: 3 | AD24: 3 | AF24: 3 | AH24: 4 | AI24: 5 | AJ24: =SUM(E24:AI24)/AM24*50/100 -> #REF! | AM24: =AM18 -> #REF!
A25: =A24+1 -> 2 | B25: Kepatuhan pemakaian APD dengan benar | D25: 100 | E25: 4 | F25: 6 | I25: 8 | J25: 6 | K25: 4 | L25: 8 | M25: 6 | P25: 10 | Q25: 10 | R25: 10 | T25: 4 | U25: 4 | V25: 6 | W25: 10 | X25: 6 | Y25: 8 | AB25: 6 | AC25: 6 | AD25: 6 | AF25: 6 | AH25: 8 | AI25: 10 | AJ25: =SUM(E25:AI25)/AM25*50/100 -> #REF! | AM25: =AM24 -> #REF!
A26: =A25+1 -> 3 | B26: Kepatuhan kebersihan tangan | D26: 100 | E26: 4 | F26: 6 | I26: 8 | J26: 6 | K26: 4 | L26: 8 | M26: 6 | P26: 10 | Q26: 10 | R26: 10 | T26: 4 | U26: 4 | V26: 6 | W26: 10 | X26: 6 | Y26: 8 | AB26: 6 | AC26: 6 | AD26: 6 | AF26: 6 | AH26: 8 | AI26: 10 | AJ26: =SUM(E26:AI26)/AM26*50/100 -> #REF! | AM26: =AM25 -> #REF!
A27: =A26+1 -> 4 | B27: Kepatuhan upaya pencegahan resiko pasien jatuh | D27: 100 | E27: 2 | F27: 3 | I27: 4 | J27: 3 | K27: 2 | L27: 4 | M27: 3 | P27: 5 | Q27: 5 | R27: 5 | T27: 2 | U27: 2 | V27: 3 | W27: 5 | X27: 3 | Y27: 4 | AB27: 3 | AC27: 3 | AD27: 3 | AF27: 3 | AH27: 4 | AI27: 5 | AJ27: =SUM(E27:AI27)/AM27*50/100 -> #REF! | AM27: =AM26 -> #REF!
A28: =A27+1 -> 5 | B28: Kepatuhan melaksanakan hand over antar petugas dengan metode SBAR | D28: 100 | E28: 2 | F28: 3 | I28: 4 | J28: 3 | K28: 2 | L28: 4 | M28: 3 | P28: 5 | Q28: 5 | R28: 5 | T28: 2 | U28: 2 | V28: 3 | W28: 5 | X28: 3 | Y28: 4 | AB28: 3 | AC28: 3 | AD28: 3 | AF28: 3 | AH28: 4 | AI28: 5 | AJ28: =SUM(E28:AI28)/AM28*50/100 -> #REF! | AM28: =AM27 -> #REF!
A29: =A28+1 -> 6 | B29: Kepatuhan melaksanakan double chek obat high allert | D29: 100 | E29: 0 | F29: 0 | I29: 0 | J29: 0 | K29: 0 | L29: 0 | M29: 0 | P29: 0 | Q29: 0 | R29: 0 | T29: 0 | U29: 0 | V29: 0 | W29: 0 | X29: 0 | Y29: 0 | AB29: 0 | AC29: 0 | AD29: 0 | AF29: 0 | AH29: 0 | AI29: 0 | AJ29: =SUM(E29:AI29)/AM29*50/100 -> #REF! | AM29: =AM28 -> #REF!
A30: =A29+1 -> 7 | B30: Kemampuan menangani life saving anak dan dewasa | D30: 100 | E30: 0 | F30: 0 | I30: 0 | J30: 0 | K30: 0 | L30: 0 | M30: 0 | P30: 0 | Q30: 0 | R30: 0 | T30: 0 | U30: 0 | V30: 0 | W30: 0 | X30: 0 | Y30: 0 | AB30: 0 | AC30: 0 | AD30: 0 | AF30: 0 | AH30: 0 | AI30: 0 | AJ30: =SUM(E30:AI30)/AM30*50/100 -> #REF! | AM30: =AM29 -> #REF!
A31: 8 | B31: RESPON Time / kecepatan pelayanan di Gawat Darurat | D31: 100 | E31: 0 | F31: 0 | I31: 0 | J31: 0 | K31: 0 | L31: 0 | M31: 0 | P31: 0 | Q31: 0 | R31: 0 | T31: 0 | U31: 0 | V31: 0 | W31: 0 | X31: 0 | Y31: 0 | AB31: 0 | AC31: 0 | AD31: 0 | AF31: 0 | AH31: 0 | AI31: 0 | AJ31: =SUM(E31:AI31)/AM31*50/100 -> #REF! | AM31: =AM30 -> #REF!
A32: JUMLAH RATA - RATA | E32: =SUM(E24:E31)/8 -> 1.75 | F32: =SUM(F24:F31)/8 -> 2.625 | G32: =SUM(G24:G31)/8 -> 0 | H32: =SUM(H24:H31)/8 -> 0 | I32: =SUM(I24:I31)/8 -> 3.5 | J32: =SUM(J24:J31)/8 -> 2.625 | K32: =SUM(K24:K31)/8 -> 1.75 | L32: =SUM(L24:L31)/8 -> 3.5 | ... AJ32: =SUM(AJ24:AJ31)/8 -> #REF! | AM32: =AM31 -> #REF!
A33: TOTAL NILAI PERILAKU + PENGEMBANGAN PROFESI + KINERJA KLINIS | AJ33: =AJ13+AJ17+AJ32 -> #REF! | AM33: =AM32 -> #REF!

Sheet FEB
A1: PENILAIAN KINERJA PERAWAT
A2: SESUAI STANDAR AKRIDITASI RUMAH SAKIT
A4: NAMA | C4: =": "&'3'!B33 -> :
A5: PK | C5: :
A7: NO | B7: INDIKATOR YANG DINILAI | D7: TARGET (%) | E7: BULAN : FEBRUARI | AJ7: CAPAIAN (%) | AL7: RUMUS WAJIB DIISI
E8: 1 | F8: 2 | G8: 3 | H8: 4 | I8: 5 | J8: 6 | K8: 7 | L8: 8 | M8: 9 | N8: 10 | O8: 11 | P8: 12 | Q8: 13 | R8: 14 | S8: 15 | T8: 16 | U8: 17 | V8: 18 | W8: 19 | X8: 20 | Y8: 21 | Z8: 22 | AA8: 23 | AB8: 24 | AC8: 25 | AD8: 26 | AE8: 27 | AF8: 28 | AG8: 29 | AH8: 30 | AI8: 31 | AL8: JUMLAH HARI : | AM8: 28
A9: A. PERILAKU ( 40 % ) | AM9: =AM8 -> 28
A10: 1 | B10: Melaporkan insiden keselamatan pasien | D10: 100 | E10: 0 | G10: 0 | H10: 0 | I10: 0 | J10: 0 | M10: 0 | N10: 0 | O10: 0 | Q10: 0 | R10: 0 | S10: 0 | U10: 0 | V10: 0 | W10: 0 | X10: 0 | Y10: 0 | AB10: 0 | AC10: 0 | AD10: 0 | AF10: 0 | AJ10: =SUM(E10:AI10)/AM10*40/100 -> 0 | AM10: =AM9 -> 28
A11: 2 | B11: Tidak ada keluhan dari teman sejawat/profesi lain/pasien dan keluarga | D11: 100 | E11: 0 | G11: 0 | H11: 0 | I11: 0 | J11: 0 | M11: 0 | N11: 0 | O11: 0 | Q11: 0 | R11: 0 | S11: 0 | U11: 0 | V11: 0 | W11: 0 | X11: 0 | Y11: 0 | AB11: 0 | AC11: 0 | AD11: 0 | AF11: 0 | AJ11: =SUM(E11:AI11)/AM11*40/100 -> 0 | AM11: =AM10 -> 28
A12: 3 | B12: Kepatuhan terhadap kode etik keperawatan | D12: 100 | E12: 5 | G12: 5 | H12: 3 | I12: 3 | J12: 2 | M12: 4 | N12: 3 | O12: 4 | Q12: 4 | R12: 8 | S12: 5 | U12: 7 | V12: 6 | W12: 6 | X12: 5 | Y12: 2 | AB12: 4 | AC12: 4 | AD12: 4 | AF12: 6 | AJ12: =SUM(E12:AI12)/AM12*40/100 -> 1.2857143 | AM12: =AM11 -> 28
A13: JUMLAH RATA - RATA | E13: =SUM(E10:E12)/3 -> 1.6666667 | F13: =SUM(F10:F12)/3 -> 0 | G13: =SUM(G10:G12)/3 -> 1.6666667 | H13: =SUM(H10:H12)/3 -> 1 | I13: =SUM(I10:I12)/3 -> 1 | J13: =SUM(J10:J12)/3 -> 0.66666667 | K13: =SUM(K10:K12)/3 -> 0 | L13: =SUM(L10:L12)/3 -> 0 | ... AJ13: =SUM(AJ10:AJ12)/3 -> 0.42857143 | AM13: =AM12 -> 28
A14: B. PENGEMBANGAN PROFESI (10%) | AM14: =AM13 -> 28
A15: 1 | B15: Menunjukan perilaku bertanggung gugat terhadap praktek profesional | D15: 100 | E15: 5 | G15: 5 | H15: 3 | I15: 3 | J15: 2 | M15: 4 | N15: 3 | O15: 4 | Q15: 4 | R15: 8 | S15: 5 | U15: 7 | V15: 6 | W15: 6 | X15: 5 | Y15: 2 | AB15: 4 | AC15: 4 | AD15: 4 | AF15: 6 | AJ15: =SUM(E15:AI15)/AM15*10/100 -> 0.32142857 | AM15: =AM14 -> 28
A16: 2 | B16: Kepatuhan dalam memberikan pendidikan pasien dan keluarga (Edukasi) | D16: 100 | E16: 5 | G16: 5 | H16: 3 | I16: 3 | J16: 2 | M16: 4 | N16: 3 | O16: 4 | Q16: 4 | R16: 8 | S16: 5 | U16: 7 | V16: 6 | W16: 6 | X16: 5 | Y16: 2 | AB16: 4 | AC16: 4 | AD16: 4 | AF16: 6 | AJ16: =SUM(E16:AI16)/AM16*10/100 -> 0.32142857 | AM16: =AM15 -> 28
A17: JUMLAH RATA - RATA | E17: =SUM(E15:E16)/3 -> 3.3333333 | F17: =SUM(F15:F16)/3 -> 0 | G17: =SUM(G15:G16)/3 -> 3.3333333 | H17: =SUM(H15:H16)/3 -> 2 | I17: =SUM(I15:I16)/3 -> 2 | J17: =SUM(J15:J16)/3 -> 1.3333333 | K17: =SUM(K15:K16)/3 -> 0 | L17: =SUM(L15:L16)/3 -> 0 | ... AJ17: =SUM(AJ15:AJ16)/3 -> 0.21428571 | AM17: =#REF! -> #REF!
A18: C. KINERJA KLINIS (50%) | AM18: =AM17 -> #REF!
A19: 1 | B19: Kepatuhan identifikasi pasien | D19: 100 | E19: 5 | G19: 5 | H19: 3 | I19: 3 | J19: 2 | M19: 4 | N19: 3 | O19: 4 | Q19: 4 | R19: 8 | S19: 5 | U19: 7 | V19: 6 | W19: 6 | X19: 5 | Y19: 2 | AB19: 4 | AC19: 4 | AD19: 4 | AF19: 6 | AJ19: =SUM(E19:AI19)/AM19*50/100 -> #REF! | AM19: =AM18 -> #REF!
A20: =A19+1 -> 2 | B20: Kepatuhan pemakaian APD dengan benar | D20: 100 | E20: 10 | G20: 10 | H20: 6 | I20: 6 | J20: 4 | M20: 8 | N20: 6 | O20: 8 | Q20: 8 | R20: 16 | S20: 10 | U20: 14 | V20: 12 | W20: 12 | X20: 10 | Y20: 4 | AB20: 8 | AC20: 8 | AD20: 8 | AF20: 12 | AJ20: =SUM(E20:AI20)/AM20*50/100 -> #REF! | AM20: =AM19 -> #REF!
A21: =A20+1 -> 3 | B21: Kepatuhan kebersihan tangan | D21: 100 | E21: 10 | G21: 10 | H21: 6 | I21: 6 | J21: 2 | M21: 8 | N21: 6 | O21: 8 | Q21: 8 | R21: 16 | S21: 10 | U21: 14 | V21: 12 | W21: 12 | X21: 10 | Y21: 4 | AB21: 8 | AC21: 8 | AD21: 8 | AF21: 12 | AJ21: =SUM(E21:AI21)/AM21*50/100 -> #REF! | AM21: =AM20 -> #REF!
A22: =A21+1 -> 4 | B22: Kepatuhan upaya pencegahan resiko pasien jatuh | D22: 100 | E22: 5 | G22: 5 | H22: 3 | I22: 3 | J22: 2 | M22: 4 | N22: 3 | O22: 4 | Q22: 4 | R22: 8 | S22: 5 | U22: 7 | V22: 6 | W22: 6 | X22: 5 | Y22: 2 | AB22: 4 | AC22: 4 | AD22: 4 | AF22: 6 | AJ22: =SUM(E22:AI22)/AM22*50/100 -> #REF! | AM22: =AM21 -> #REF!
A23: =A22+1 -> 5 | B23: Kepatuhan melaksanakan hand over antar petugas dengan metode SBAR | D23: 100 | E23: 5 | G23: 5 | H23: 3 | I23: 3 | J23: 2 | M23: 4 | N23: 3 | O23: 4 | Q23: 4 | R23: 8 | S23: 5 | U23: 7 | V23: 6 | W23: 6 | X23: 5 | Y23: 2 | AB23: 4 | AC23: 4 | AD23: 4 | AF23: 6 | AJ23: =SUM(E23:AI23)/AM23*50/100 -> #REF! | AM23: =AM22 -> #REF!
A24: =A23+1 -> 6 | B24: Kepatuhan melaksanakan double chek obat high allert | D24: 100 | E24: 0 | G24: 0 | H24: 0 | I24: 0 | J24: 0 | M24: 9 | N24: 0 | O24: 0 | Q24: 0 | R24: 0 | S24: 0 | U24: 0 | V24: 0 | W24: 0 | X24: 0 | Y24: 0 | AB24: 0 | AC24: 0 | AD24: 0 | AF24: 0 | AJ24: =SUM(E24:AI24)/AM24*50/100 -> #REF! | AM24: =AM23 -> #REF!
A25: =A24+1 -> 7 | B25: Kemampuan menangani life saving anak / dewasa | D25: 100 | E25: 0 | G25: 0 | H25: 0 | I25: 0 | J25: 0 | M25: 9 | N25: 0 | O25: 0 | Q25: 0 | R25: 0 | S25: 0 | U25: 0 | V25: 0 | W25: 0 | X25: 5 | Y25: 0 | AB25: 0 | AC25: 0 | AD25: 0 | AF25: 0 | AJ25: =SUM(E25:AI25)/AM25*50/100 -> #REF! | AM25: =AM24 -> #REF!
A26: 8 | B26: RESPON Time / kecepatan pelayanan di Gawat Darurat | D26: 100 | E26: 0 | G26: 0 | H26: 0 | I26: 0 | J26: 0 | M26: 9 | N26: 0 | O26: 0 | Q26: 0 | R26: 0 | S26: 0 | U26: 0 | V26: 0 | W26: 0 | X26: 5 | Y26: 0 | AB26: 0 | AC26: 0 | AD26: 0 | AF26: 0 | AJ26: =SUM(E26:AI26)/AM26*50/100 -> #REF! | AM26: =AM25 -> #REF!
A27: JUMLAH RATA - RATA | E27: =SUM(E19:E26)/8 -> 4.375 | F27: =SUM(F19:F26)/8 -> 0 | G27: =SUM(G19:G26)/8 -> 4.375 | H27: =SUM(H19:H26)/8 -> 2.625 | I27: =SUM(I19:I26)/8 -> 2.625 | J27: =SUM(J19:J26)/8 -> 1.5 | K27: =SUM(K19:K26)/8 -> 0 | L27: =SUM(L19:L26)/8 -> 0 | ... AJ27: =SUM(AJ19:AJ26)/8 -> #REF! | AM27: =AM26 -> #REF!
A28: TOTAL NILAI PERILAKU + PENGEMBANGAN PROFESI + KINERJA KLINIS | AJ28: =AJ13+AJ17+AJ27 -> #REF! | AM28: =AM27 -> #REF!

Sheet MART
A1: PENILAIAN KINERJA PERAWAT
A2: SESUAI STANDAR AKRIDITASI RUMAH SAKIT
A4: NAMA | C4: =": "&'3'!B33 -> :
A5: PK | C5: :
A7: NO | B7: INDIKATOR YANG DINILAI | D7: TARGET (%) | E7: BULAN : MARET | AJ7: CAPAIAN (%) | AL7: RUMUS WAJIB DIISI
E8: 1 | F8: 2 | G8: 3 | H8: 4 | I8: 5 | J8: 6 | K8: 7 | L8: 8 | M8: 9 | N8: 10 | O8: 11 | P8: 12 | Q8: 13 | R8: 14 | S8: 15 | T8: 16 | U8: 17 | V8: 18 | W8: 19 | X8: 20 | Y8: 21 | Z8: 22 | AA8: 23 | AB8: 24 | AC8: 25 | AD8: 26 | AE8: 27 | AF8: 28 | AG8: 29 | AH8: 30 | AI8: 31 | AL8: JUMLAH HARI : | AM8: 28
A9: A. PERILAKU ( 40 % ) | AM9: =AM8 -> 28
A10: 1 | B10: Melaporkan insiden keselamatan pasien | D10: 100 | E10: 0 | F10: 0 | I10: 0 | J10: 0 | K10: 0 | L10: 0 | N10: 0 | O10: 0 | P10: 0 | Q10: 0 | R10: 0 | S10: 0 | V10: 0 | W10: 0 | X10: 0 | Z10: 0 | AA10: 0 | AD10: 0 | AE10: 0 | AF10: 0 | AG10: 0 | AI10: 0 | AJ10: =SUM(E10:AI10)/AM8*40/100 -> 0 | AM10: =AM9 -> 28
A11: 2 | B11: Tidak ada keluhan dari teman sejawat/profesi lain/pasien dan keluarga | D11: 100 | E11: 0 | F11: 0 | I11: 0 | J11: 0 | K11: 0 | L11: 0 | N11: 0 | O11: 0 | P11: 0 | Q11: 0 | R11: 0 | S11: 0 | V11: 0 | W11: 0 | X11: 0 | Z11: 0 | AA11: 0 | AD11: 0 | AE11: 0 | AF11: 0 | AG11: 0 | AI11: 0 | AJ11: =SUM(E11:AI11)/AM9*40/100 -> 0 | AM11: =AM10 -> 28
A12: 3 | B12: Kepatuhan terhadap kode etik keperawatan | D12: 100 | E12: 3 | F12: 6 | I12: 3 | J12: 7 | K12: 6 | L12: 7 | N12: 4 | O12: 4 | P12: 4 | Q12: 3 | R12: 2 | S12: 3 | V12: 3 | W12: 3 | X12: 3 | Z12: 2 | AA12: 2 | AD12: 3 | AE12: 4 | AF12: 5 | AG12: 5 | AI12: 7 | AJ12: =SUM(E12:AI12)/AM10*40/100 -> 1.2714286 | AM12: =AM11 -> 28
A13: JUMLAH RATA - RATA | E13: =SUM(E10:E12)/3 -> 1 | F13: =SUM(F10:F12)/3 -> 2 | G13: =SUM(G10:G12)/3 -> 0 | H13: =SUM(H10:H12)/3 -> 0 | I13: =SUM(I10:I12)/3 -> 1 | J13: =SUM(J10:J12)/3 -> 2.3333333 | K13: =SUM(K10:K12)/3 -> 2 | L13: =SUM(L10:L12)/3 -> 2.3333333 | ... R13: =SUM(R10:R12)/3 -> 0.66666667 | S13: 0 | T13: =SUM(T10:T12)/3 -> 0 | U13: =SUM(U10:U12)/3 -> 0 | V13: =SUM(V10:V12)/3 -> 1 | W13: =SUM(W10:W12)/3 -> 1 | X13: =SUM(X10:X12)/3 -> 1 | Y13: =SUM(Y10:Y12)/3 -> 0 | Z13: =SUM(Z10:Z12)/3 -> 0.66666667 | AA13: =SUM(AA10:AA12)/3 -> 0.66666667 | ... AJ13: =SUM(AJ10:AJ12)/3 -> 0.42380952 | AM13: =AM12 -> 28
A14: B. PENGEMBANGAN PROFESI (10%) | AM14: =AM13 -> 28
A15: 1 | B15: Menunjukan perilaku bertanggung gugat terhadap praktek profesional | D15: 100 | E15: 3 | F15: 6 | I15: 3 | J15: 7 | K15: 6 | L15: 7 | N15: 4 | O15: 4 | P15: 4 | Q15: 3 | R15: 2 | S15: 3 | V15: 3 | W15: 3 | X15: 3 | Z15: 2 | AA15: 2 | AD15: 3 | AE15: 4 | AF15: 5 | AG15: 5 | AI15: 7 | AJ15: =SUM(E15:AI15)/AM15*10/100 -> 0.31785714 | AM15: =AM14 -> 28
A16: 2 | B16: Kepatuhan dalam memberikan pendidikan pasien dan keluarga | D16: 100 | E16: 3 | F16: 6 | I16: 3 | J16: 7 | K16: 6 | L16: 7 | N16: 4 | O16: 4 | P16: 4 | Q16: 3 | R16: 2 | S16: 3 | V16: 3 | W16: 3 | X16: 3 | Z16: 2 | AA16: 2 | AD16: 3 | AE16: 4 | AF16: 5 | AG16: 5 | AI16: 7 | AJ16: =SUM(E16:AI16)/AM16*10/100 -> 0.31785714 | AM16: =AM15 -> 28
A17: JUMLAH RATA - RATA | E17: =SUM(E15:E16)/3 -> 2 | F17: =SUM(F15:F16)/3 -> 4 | G17: =SUM(G15:G16)/3 -> 0 | H17: =SUM(H15:H16)/3 -> 0 | I17: =SUM(I15:I16)/3 -> 2 | J17: =SUM(J15:J16)/3 -> 4.6666667 | K17: =SUM(K15:K16)/3 -> 4 | L17: =SUM(L15:L16)/3 -> 4.6666667 | ... AJ17: =SUM(AJ15:AJ16)/3 -> 0.21190476 | AM17: =#REF! -> #REF!
A18: C. KINERJA KLINIS (50%) | AM18: =AM17 -> #REF!
A19: 1 | B19: Kepatuhan identifikasi pasien | D19: 100 | E19: 3 | F19: 6 | I19: 3 | J19: 7 | K19: 6 | L19: 7 | N19: 4 | O19: 4 | P19: 4 | Q19: 3 | R19: 2 | S19: 3 | V19: 3 | W19: 3 | X19: 3 | Z19: 2 | AA19: 2 | AD19: 3 | AE19: 4 | AF19: 5 | AG19: 5 | AI19: 7 | AJ19: =SUM(E19:AI19)/AM19*50/100 -> #REF! | AM19: =AM18 -> #REF!
A20: =A19+1 -> 2 | B20: Kepatuhan pemakaian APD dengan benar | D20: 100 | E20: 6 | F20: 12 | I20: 6 | J20: 14 | K20: 12 | L20: 14 | N20: 8 | O20: 8 | P20: 8 | Q20: 6 | R20: 4 | S20: 6 | V20: 6 | W20: 6 | X20: 6 | Z20: 4 | AA20: 4 | AD20: 6 | AE20: 8 | AF20: 10 | AG20: 10 | AI20: 14 | AJ20: =SUM(E20:AI20)/AM20*50/100 -> #REF! | AM20: =AM19 -> #REF!
A21: =A20+1 -> 3 | B21: Kepatuhan kebersihan tangan | D21: 100 | E21: 6 | F21: 12 | I21: 6 | J21: 14 | K21: 2 | L21: 14 | N21: 8 | O21: 8 | P21: 8 | Q21: 6 | R21: 4 | S21: 6 | V21: 6 | W21: 6 | X21: 6 | Z21: 4 | AA21: 4 | AD21: 6 | AE21: 8 | AF21: 10 | AG21: 10 | AI21: 14 | AJ21: =SUM(E21:AI21)/AM21*50/100 -> #REF! | AM21: =AM20 -> #REF!
A22: =A21+1 -> 4 | B22: Kepatuhan upaya pencegahan resiko pasien jatuh | D22: 100 | E22: 3 | F22: 6 | I22: 3 | J22: 7 | K22: 6 | L22: 7 | N22: 4 | O22: 4 | P22: 4 | Q22: 3 | R22: 2 | S22: 3 | V22: 3 | W22: 3 | X22: 3 | Z22: 2 | AA22: 2 | AD22: 3 | AE22: 4 | AF22: 5 | AG22: 5 | AI22: 7 | AJ22: =SUM(E22:AI22)/AM22*50/100 -> #REF! | AM22: =AM21 -> #REF!
A23: =A22+1 -> 5 | B23: Kepatuhan melaksanakan hand over antar petugas dengan metode SBAR | D23: 100 | E23: 3 | F23: 6 | I23: 3 | J23: 7 | K23: 6 | L23: 7 | N23: 4 | O23: 4 | P23: 4 | Q23: 3 | R23: 2 | S23: 3 | V23: 3 | W23: 3 | X23: 3 | Z23: 2 | AA23: 2 | AD23: 3 | AE23: 4 | AF23: 5 | AG23: 5 | AI23: 7 | AJ23: =SUM(E23:AI23)/AM23*50/100 -> #REF! | AM23: =AM22 -> #REF!
A24: =A23+1 -> 6 | B24: Kepatuhan melaksanakan double chek obat high allert | D24: 100 | E24: 0 | F24: 0 | I24: 0 | J24: 0 | K24: 0 | L24: 0 | N24: 0 | O24: 0 | P24: 0 | Q24: 0 | R24: 0 | S24: 0 | V24: 0 | W24: 0 | X24: 0 | Z24: 0 | AA24: 0 | AD24: 0 | AE24: 0 | AF24: 0 | AG24: 0 | AI24: 0 | AJ24: =SUM(E24:AI24)/AM24*50/100 -> #REF! | AM24: =AM23 -> #REF!
A25: =A24+1 -> 7 | B25: Kemampuan menangani life saving anak dan dewasa | D25: 100 | E25: 0 | F25: 0 | I25: 0 | J25: 0 | K25: 0 | L25: 0 | N25: 0 | O25: 0 | P25: 0 | Q25: 0 | R25: 0 | S25: 0 | V25: 0 | W25: 0 | X25: 0 | Z25: 0 | AA25: 0 | AD25: 0 | AE25: 0 | AF25: 0 | AG25: 0 | AI25: 0 | AJ25: =SUM(E25:AI25)/AM25*50/100 -> #REF! | AM25: =AM24 -> #REF!
A26: 8 | B26: RESPON Time / kecepatan pelayanan di Gawat Darurat | D26: 100 | E26: 0 | F26: 0 | I26: 0 | J26: 0 | K26: 0 | L26: 0 | N26: 0 | O26: 0 | P26: 0 | Q26: 0 | R26: 0 | S26: 0 | V26: 0 | W26: 0 | X26: 0 | Z26: 0 | AA26: 0 | AD26: 0 | AE26: 0 | AF26: 0 | AG26: 0 | AI26: 0 | AJ26: =SUM(E26:AI26)/AM26*50/100 -> #REF! | AM26: =AM25 -> #REF!
A27: JUMLAH RATA - RATA | E27: =SUM(E19:E26)/8 -> 2.625 | F27: =SUM(F19:F26)/8 -> 5.25 | G27: =SUM(G19:G26)/8 -> 0 | H27: =SUM(H19:H26)/8 -> 0 | I27: =SUM(I19:I26)/8 -> 2.625 | J27: =SUM(J19:J26)/8 -> 6.125 | K27: =SUM(K19:K26)/8 -> 4 | L27: =SUM(L19:L26)/8 -> 6.125 | ... AJ27: =SUM(AJ19:AJ26)/8 -> #REF! | AM27: =AM26 -> #REF!
A28: TOTAL NILAI PERILAKU + PENGEMBANGAN PROFESI + KINERJA KLINIS | AJ28: =AJ13+AJ17+AJ27 -> #REF! | AM28: =AM27 -> #REF!

Sheet APRIL
A1: PENILAIAN KINERJA PERAWAT
A2: SESUAI STANDAR AKRIDITASI RUMAH SAKIT
A4: NAMA | C4: AYSAH LUTFI NURAZIZAH
A5: PK | C5: PELAKSANA/PK 1
A7: NO | B7: INDIKATOR YANG DINILAI | D7: TARGET (%) | E7: BULAN : APRIL | AJ7: CAPAIAN (%) | AL7: RUMUS WAJIB DIISI
E8: 1 | F8: 2 | G8: 3 | H8: 4 | I8: 5 | J8: 6 | K8: 7 | L8: 8 | M8: 9 | N8: 10 | O8: 11 | P8: 12 | Q8: 13 | R8: 14 | S8: 15 | T8: 16 | U8: 17 | V8: 18 | W8: 19 | X8: 20 | Y8: 21 | Z8: 22 | AA8: 23 | AB8: 24 | AC8: 25 | AD8: 26 | AE8: 27 | AF8: 28 | AG8: 29 | AH8: 30 | AI8: 31 | AL8: JUMLAH HARI : | AM8: 28
A9: A. PERILAKU ( 40 % ) | AM9: =AM8 -> 28
A10: 1 | B10: Melaporkan insiden keselamatan pasien | D10: 100 | E10: 0 | J10: 0 | K10: 0 | L10: 0 | M10: 0 | N10: 0 | Q10: 0 | R10: 0 | S10: 0 | T10: 0 | U10: 0 | V10: 0 | X10: 0 | Y10: 0 | Z10: 0 | AB10: 0 | AC10: 0 | AD10: 0 | AE10: 0 | AG10: 0 | AJ10: =SUM(E10:AI10)/AM8*40/100 -> 0 | AM10: =AM9 -> 28
A11: 2 | B11: Tidak ada keluhan dari teman sejawat/profesi lain/pasien dan keluarga | D11: 100 | E11: 0 | J11: 0 | K11: 0 | L11: 0 | M11: 0 | N11: 0 | Q11: 0 | R11: 0 | S11: 0 | T11: 0 | U11: 0 | V11: 0 | X11: 0 | Y11: 0 | Z11: 0 | AB11: 0 | AC11: 0 | AD11: 0 | AE11: 0 | AG11: 0 | AJ11: =SUM(E11:AI11)/AM9*40/100 -> 0 | AM11: =AM10 -> 28
A12: 3 | B12: Kepatuhan terhadap kode etik keperawatan | D12: 100 | E12: 4 | J12: 5 | K12: 3 | L12: 4 | M12: 5 | N12: 5 | Q12: 4 | R12: 3 | S12: 5 | T12: 3 | U12: 5 | V12: 4 | X12: 4 | Y12: 4 | Z12: 2 | AB12: 3 | AC12: 4 | AD12: 6 | AE12: 6 | AG12: 3 | AJ12: =SUM(E12:AI12)/AM10*40/100 -> 1.1714286 | AM12: =AM11 -> 28
A13: JUMLAH RATA - RATA | E13: =SUM(E10:E12)/3 -> 1.3333333 | F13: =SUM(F10:F12)/3 -> 0 | G13: =SUM(G10:G12)/3 -> 0 | H13: =SUM(H10:H12)/3 -> 0 | I13: =SUM(I10:I12)/3 -> 0 | J13: =SUM(J10:J12)/3 -> 1.6666667 | K13: =SUM(K10:K12)/3 -> 1 | L13: =SUM(L10:L12)/3 -> 1.3333333 | ... R13: =SUM(R10:R12)/3 -> 1 | S13: 0 | T13: =SUM(T10:T12)/3 -> 1 | U13: =SUM(U10:U12)/3 -> 1.6666667 | V13: =SUM(V10:V12)/3 -> 1.3333333 | W13: =SUM(W10:W12)/3 -> 0 | X13: =SUM(X10:X12)/3 -> 1.3333333 | Y13: =SUM(Y10:Y12)/3 -> 1.3333333 | Z13: =SUM(Z10:Z12)/3 -> 0.66666667 | AA13: =SUM(AA10:AA12)/3 -> 0 | ... AJ13: =SUM(AJ10:AJ12)/3 -> 0.39047619 | AM13: =AM12 -> 28
A14: B. PENGEMBANGAN PROFESI (10%) | AM14: =AM13 -> 28
A15: 1 | B15: Menunjukan perilaku bertanggung gugat terhadap praktek profesional | D15: 100 | E15: 4 | J15: 5 | K15: 3 | L15: 4 | M15: 5 | N15: 5 | Q15: 4 | R15: 3 | S15: 5 | T15: 3 | U15: 5 | V15: 4 | X15: 4 | Y15: 4 | Z15: 2 | AB15: 3 | AC15: 4 | AD15: 6 | AE15: 6 | AG15: 3 | AJ15: =SUM(E15:AI15)/AM15*10/100 -> 0.29285714 | AM15: =AM14 -> 28
A16: 2 | B16: Kepatuhan dalam memberikan pendidikan pasien dan keluarga | D16: 100 | E16: 4 | J16: 5 | K16: 3 | L16: 4 | M16: 5 | N16: 5 | Q16: 4 | R16: 3 | S16: 5 | T16: 3 | U16: 5 | V16: 4 | X16: 4 | Y16: 4 | Z16: 2 | AB16: 3 | AC16: 4 | AD16: 6 | AE16: 6 | AG16: 3 | AJ16: =SUM(E16:AI16)/AM16*10/100 -> 0.29285714 | AM16: =AM15 -> 28
A17: JUMLAH RATA - RATA | E17: =SUM(E15:E16)/3 -> 2.6666667 | F17: =SUM(F15:F16)/3 -> 0 | G17: =SUM(G15:G16)/3 -> 0 | H17: =SUM(H15:H16)/3 -> 0 | I17: =SUM(I15:I16)/3 -> 0 | J17: =SUM(J15:J16)/3 -> 3.3333333 | K17: =SUM(K15:K16)/3 -> 2 | L17: =SUM(L15:L16)/3 -> 2.6666667 | ... AJ17: =SUM(AJ15:AJ16)/3 -> 0.1952381 | AM17: =#REF! -> #REF!
A18: C. KINERJA KLINIS (50%) | AM18: =AM17 -> #REF!
A19: 1 | B19: Kepatuhan identifikasi pasien | D19: 100 | E19: 4 | J19: 5 | K19: 3 | L19: 4 | M19: 5 | N19: 5 | Q19: 4 | R19: 3 | S19: 5 | T19: 3 | U19: 5 | V19: 4 | X19: 4 | Y19: 4 | Z19: 2 | AB19: 3 | AC19: 4 | AD19: 6 | AE19: 6 | AG19: 3 | AJ19: =SUM(E19:AI19)/AM19*50/100 -> #REF! | AM19: =AM18 -> #REF!
A20: =A19+1 -> 2 | B20: Kepatuhan pemakaian APD dengan benar | D20: 100 | E20: 8 | J20: 10 | K20: 6 | L20: 8 | M20: 10 | N20: 10 | Q20: 8 | R20: 6 | S20: 10 | T20: 6 | U20: 10 | V20: 8 | X20: 8 | Y20: 8 | Z20: 4 | AB20: 6 | AC20: 8 | AD20: 12 | AE20: 12 | AG20: 6 | AJ20: =SUM(E20:AI20)/AM20*50/100 -> #REF! | AM20: =AM19 -> #REF!
A21: =A20+1 -> 3 | B21: Kepatuhan kebersihan tangan | D21: 100 | E21: 8 | J21: 10 | K21: 6 | L21: 8 | M21: 10 | N21: 10 | Q21: 8 | R21: 6 | S21: 10 | T21: 6 | U21: 10 | V21: 8 | X21: 8 | Y21: 8 | Z21: 4 | AB21: 6 | AC21: 8 | AD21: 12 | AE21: 12 | AG21: 6 | AJ21: =SUM(E21:AI21)/AM21*50/100 -> #REF! | AM21: =AM20 -> #REF!
A22: =A21+1 -> 4 | B22: Kepatuhan upaya pencegahan resiko pasien jatuh | D22: 100 | E22: 4 | J22: 5 | K22: 3 | L22: 4 | M22: 5 | N22: 5 | Q22: 4 | R22: 3 | S22: 5 | T22: 3 | U22: 5 | V22: 4 | X22: 4 | Y22: 4 | Z22: 2 | AB22: 3 | AC22: 4 | AD22: 6 | AE22: 6 | AG22: 3 | AJ22: =SUM(E22:AI22)/AM22*50/100 -> #REF! | AM22: =AM21 -> #REF!
A23: =A22+1 -> 5 | B23: Kepatuhan melaksanakan hand over antar petugas dengan metode SBAR | D23: 100 | E23: 4 | J23: 5 | K23: 3 | L23: 4 | M23: 5 | N23: 5 | Q23: 4 | R23: 3 | S23: 5 | T23: 3 | U23: 5 | V23: 4 | X23: 4 | Y23: 4 | Z23: 2 | AB23: 3 | AC23: 4 | AD23: 6 | AE23: 6 | AG23: 3 | AJ23: =SUM(E23:AI23)/AM23*50/100 -> #REF! | AM23: =AM22 -> #REF!
A24: =A23+1 -> 6 | B24: Kepatuhan melaksanakan double chek obat high allert | D24: 100 | E24: 0 | J24: 0 | K24: 0 | L24: 0 | M24: 0 | N24: 0 | Q24: 0 | R24: 0 | S24: 0 | T24: 0 | U24: 0 | V24: 0 | X24: 0 | Y24: 0 | Z24: 0 | AB24: 0 | AC24: 0 | AD24: 0 | AE24: 0 | AG24: 0 | AJ24: =SUM(E24:AI24)/AM24*50/100 -> #REF! | AM24: =AM23 -> #REF!
A25: =A24+1 -> 7 | B25: Kemampuan menangani life saving anak dan dewasa | D25: 100 | E25: 0 | J25: 0 | K25: 0 | L25: 0 | M25: 0 | N25: 0 | Q25: 0 | R25: 0 | S25: 0 | T25: 0 | U25: 0 | V25: 0 | X25: 0 | Y25: 0 | Z25: 0 | AB25: 0 | AC25: 0 | AD25: 0 | AE25: 0 | AG25: 0 | AJ25: =SUM(E25:AI25)/AM25*50/100 -> #REF! | AM25: =AM24 -> #REF!
A26: 8 | B26: RESPON Time / kecepatan pelayanan di Gawat Darurat | D26: 100 | E26: 0 | J26: 0 | K26: 0 | L26: 0 | M26: 0 | N26: 0 | Q26: 0 | R26: 0 | S26: 0 | T26: 0 | U26: 0 | V26: 0 | X26: 0 | Y26: 0 | Z26: 0 | AB26: 0 | AC26: 0 | AD26: 0 | AE26: 0 | AG26: 0 | AJ26: =SUM(E26:AI26)/AM26*50/100 -> #REF! | AM26: =AM25 -> #REF!
A27: JUMLAH RATA - RATA | E27: =SUM(E19:E26)/8 -> 3.5 | F27: =SUM(F19:F26)/8 -> 0 | G27: =SUM(G19:G26)/8 -> 0 | H27: =SUM(H19:H26)/8 -> 0 | I27: =SUM(I19:I26)/8 -> 0 | J27: =SUM(J19:J26)/8 -> 4.375 | K27: =SUM(K19:K26)/8 -> 2.625 | L27: =SUM(L19:L26)/8 -> 3.5 | ... AJ27: =SUM(AJ19:AJ26)/8 -> #REF! | AM27: =AM26 -> #REF!
A28: TOTAL NILAI PERILAKU + PENGEMBANGAN PROFESI + KINERJA KLINIS | AJ28: =AJ13+AJ17+AJ27 -> #REF! | AM28: =AM27 -> #REF!

Sheet MEI
A1: PENILAIAN KINERJA PERAWAT
A2: SESUAI STANDAR AKRIDITASI RUMAH SAKIT
A4: NAMA | C4: =": "&'3'!B33 -> :
A5: PK | C5: :
A7: NO | B7: INDIKATOR YANG DINILAI | D7: TARGET (%) | E7: BULAN : MEI | AJ7: CAPAIAN (%) | AL7: RUMUS WAJIB DIISI
E8: 1 | F8: 2 | G8: 3 | H8: 4 | I8: 5 | J8: 6 | K8: 7 | L8: 8 | M8: 9 | N8: 10 | O8: 11 | P8: 12 | Q8: 13 | R8: 14 | S8: 15 | T8: 16 | U8: 17 | V8: 18 | W8: 19 | X8: 20 | Y8: 21 | Z8: 22 | AA8: 23 | AB8: 24 | AC8: 25 | AD8: 26 | AE8: 27 | AF8: 28 | AG8: 29 | AH8: 30 | AI8: 31 | AL8: JUMLAH HARI : | AM8: 28
A9: A. PERILAKU ( 40 % ) | AM9: =AM8 -> 28
A10: 1 | B10: Melaporkan insiden keselamatan pasien | D10: 100 | E10: 0 | F10: 0 | G10: 0 | H10: 0 | I10: 0 | J10: 0 | K10: L | L10: L | M10: 0 | N10: L | O10: 0 | P10: 0 | Q10: 0 | R10: L | S10: L | T10: 0 | U10: 0 | V10: 0 | W10: 0 | X10: 0 | Y10: 0 | Z10: L | AA10: L | AB10: 0 | AC10: 0 | AD10: 0 | AE10: 0 | AF10: 0 | AG10: 0 | AJ10: =SUM(E10:AI10)/AM8*40/100 -> 0 | AM10: =AM9 -> 28
A11: 2 | B11: Tidak ada keluhan dari teman sejawat/profesi lain/pasien dan keluarga | D11: 100 | E11: 0 | F11: 0 | G11: 0 | H11: 0 | I11: 0 | J11: 0 | K11: L | L11: L | M11: 0 | N11: L | O11: 0 | P11: 0 | Q11: 0 | R11: L | S11: L | T11: 0 | U11: 0 | V11: 0 | W11: 0 | X11: 0 | Y11: 0 | Z11: L | AA11: L | AB11: 0 | AC11: 0 | AD11: 0 | AE11: 0 | AF11: 0 | AG11: 0 | AJ11: =SUM(E11:AI11)/AM9*40/100 -> 0 | AM11: =AM10 -> 28
A12: 3 | B12: Kepatuhan terhadap kode etik keperawatan | D12: 100 | E12: 6 | F12: 5 | G12: 3 | H12: 3 | I12: 4 | J12: 4 | K12: L | L12: L | M12: 4 | N12: L | O12: 4 | P12: 4 | Q12: 1 | R12: L | S12: L | T12: 2 | U12: 2 | V12: 3 | W12: 4 | X12: 2 | Y12: 1 | Z12: L | AA12: L | AB12: 6 | AC12: 7 | AD12: 5 | AE12: 4 | AF12: 5 | AG12: 5 | AJ12: =SUM(E12:AI12)/AM10*40/100 -> 1.2 | AM12: =AM11 -> 28
A13: JUMLAH RATA - RATA | E13: =SUM(E10:E12)/3 -> 2 | F13: =SUM(F10:F12)/3 -> 1.6666667 | G13: =SUM(G10:G12)/3 -> 1 | H13: =SUM(H10:H12)/3 -> 1 | I13: =SUM(I10:I12)/3 -> 1.3333333 | J13: =SUM(J10:J12)/3 -> 1.3333333 | K13: =SUM(K10:K12)/3 -> 0 | L13: =SUM(L10:L12)/3 -> 0 | ... R13: =SUM(R10:R12)/3 -> 0 | S13: 0 | T13: =SUM(T10:T12)/3 -> 0.66666667 | U13: =SUM(U10:U12)/3 -> 0.66666667 | V13: =SUM(V10:V12)/3 -> 1 | W13: =SUM(W10:W12)/3 -> 1.3333333 | X13: =SUM(X10:X12)/3 -> 0.66666667 | Y13: =SUM(Y10:Y12)/3 -> 0.33333333 | Z13: =SUM(Z10:Z12)/3 -> 0 | AA13: =SUM(AA10:AA12)/3 -> 0 | ... AJ13: =SUM(AJ10:AJ12)/3 -> 0.4 | AM13: =AM12 -> 28
A14: B. PENGEMBANGAN PROFESI (10%) | AM14: =AM13 -> 28
A15: 1 | B15: Menunjukan perilaku bertanggung gugat terhadap praktek profesional | D15: 100 | E15: 6 | F15: 5 | G15: 3 | H15: 3 | I15: 4 | J15: 4 | K15: L | L15: L | M15: 4 | N15: L | O15: 4 | P15: 4 | Q15: 1 | R15: L | S15: L | T15: 2 | U15: 2 | V15: 3 | W15: 4 | X15: 2 | Y15: 1 | Z15: L | AA15: L | AB15: 6 | AC15: 7 | AD15: 5 | AE15: 4 | AF15: 5 | AG15: 5 | AJ15: =SUM(E15:AI15)/AM15*10/100 -> 0.3 | AM15: =AM14 -> 28
A16: 2 | B16: Kepatuhan dalam memberikan pendidikan pasien dan keluarga | D16: 100 | E16: 6 | F16: 5 | G16: 3 | H16: 3 | I16: 4 | J16: 4 | K16: L | L16: L | M16: 4 | N16: L | O16: 4 | P16: 4 | Q16: 1 | R16: L | S16: L | T16: 2 | U16: 2 | V16: 3 | W16: 4 | X16: 2 | Y16: 1 | Z16: L | AA16: L | AB16: 6 | AC16: 7 | AD16: 5 | AE16: 4 | AF16: 5 | AG16: 5 | AJ16: =SUM(E16:AI16)/AM16*10/100 -> 0.3 | AM16: =AM15 -> 28
A17: JUMLAH RATA - RATA | E17: =SUM(E15:E16)/3 -> 4 | F17: =SUM(F15:F16)/3 -> 3.3333333 | G17: =SUM(G15:G16)/3 -> 2 | H17: =SUM(H15:H16)/3 -> 2 | I17: =SUM(I15:I16)/3 -> 2.6666667 | J17: =SUM(J15:J16)/3 -> 2.6666667 | K17: =SUM(K15:K16)/3 -> 0 | L17: =SUM(L15:L16)/3 -> 0 | ... AJ17: =SUM(AJ15:AJ16)/3 -> 0.2 | AM17: =#REF! -> #REF!
A18: C. KINERJA KLINIS (50%) | AM18: =AM17 -> #REF!
A19: 1 | B19: Kepatuhan identifikasi pasien | D19: 100 | E19: 6 | F19: 5 | G19: 3 | H19: 3 | I19: 4 | J19: 4 | K19: L | L19: L | M19: 4 | N19: L | O19: 4 | P19: 4 | Q19: 1 | R19: L | S19: L | T19: 2 | U19: 2 | V19: 3 | W19: 4 | X19: 2 | Y19: 1 | Z19: L | AA19: L | AB19: 6 | AC19: 7 | AD19: 5 | AE19: 4 | AF19: 5 | AG19: 5 | AJ19: =SUM(E19:AI19)/AM19*50/100 -> #REF! | AM19: =AM18 -> #REF!
A20: =A19+1 -> 2 | B20: Kepatuhan pemakaian APD dengan benar | D20: 100 | E20: 12 | F20: 10 | G20: 6 | H20: 6 | I20: 8 | J20: 8 | K20: L | L20: L | M20: 8 | N20: L | O20: 8 | P20: 8 | Q20: 2 | R20: L | S20: L | T20: 4 | U20: 4 | V20: 6 | W20: 8 | X20: 4 | Y20: 2 | Z20: L | AA20: L | AB20: 12 | AC20: 14 | AD20: 10 | AE20: 8 | AF20: 10 | AG20: 10 | AJ20: =SUM(E20:AI20)/AM20*50/100 -> #REF! | AM20: =AM19 -> #REF!
A21: =A20+1 -> 3 | B21: Kepatuhan kebersihan tangan | D21: 100 | E21: 12 | F21: 10 | G21: 6 | H21: 6 | I21: 8 | J21: 8 | K21: L | L21: L | M21: 8 | N21: L | O21: 8 | P21: 8 | Q21: 2 | R21: L | S21: L | T21: 4 | U21: 4 | V21: 6 | W21: 8 | X21: 4 | Y21: 2 | Z21: L | AA21: L | AB21: 12 | AC21: 14 | AD21: 10 | AE21: 8 | AF21: 10 | AG21: 10 | AJ21: =SUM(E21:AI21)/AM21*50/100 -> #REF! | AM21: =AM20 -> #REF!
A22: =A21+1 -> 4 | B22: Kepatuhan upaya pencegahan resiko pasien jatuh | D22: 100 | E22: 6 | F22: 5 | G22: 3 | H22: 3 | I22: 4 | J22: 4 | K22: L | L22: L | M22: 4 | N22: L | O22: 4 | P22: 4 | Q22: 1 | R22: L | S22: L | T22: 2 | U22: 2 | V22: 3 | W22: 4 | X22: 2 | Y22: 1 | Z22: L | AA22: L | AB22: 6 | AC22: 7 | AD22: 5 | AE22: 4 | AF22: 5 | AG22: 5 | AJ22: =SUM(E22:AI22)/AM22*50/100 -> #REF! | AM22: =AM21 -> #REF!
A23: =A22+1 -> 5 | B23: Kepatuhan melaksanakan hand over antar petugas dengan metode SBAR | D23: 100 | E23: 6 | F23: 5 | G23: 3 | H23: 3 | I23: 4 | J23: 4 | K23: L | L23: L | M23: 4 | N23: L | O23: 4 | P23: 4 | Q23: 1 | R23: L | S23: L | T23: 2 | U23: 2 | V23: 3 | W23: 4 | X23: 2 | Y23: 1 | Z23: L | AA23: L | AB23: 6 | AC23: 7 | AD23: 5 | AE23: 4 | AF23: 5 | AG23: 5 | AJ23: =SUM(E23:AI23)/AM23*50/100 -> #REF! | AM23: =AM22 -> #REF!
A24: =A23+1 -> 6 | B24: Kepatuhan melaksanakan double chek obat high allert | D24: 100 | E24: 0 | F24: 0 | G24: 0 | H24: 0 | I24: 0 | J24: 0 | K24: L | L24: L | M24: 0 | N24: L | O24: 0 | P24: 0 | Q24: 0 | R24: L | S24: L | T24: 0 | U24: 0 | V24: 0 | W24: 0 | X24: 0 | Y24: 0 | Z24: L | AA24: L | AB24: 0 | AC24: 0 | AD24: 0 | AE24: 0 | AF24: 0 | AG24: 0 | AJ24: =SUM(E24:AI24)/AM24*50/100 -> #REF! | AM24: =AM23 -> #REF!
A25: =A24+1 -> 7 | B25: Kemampuan menangani life saving anak dan dewasa | D25: 100 | E25: 0 | F25: 0 | G25: 0 | H25: 0 | I25: 0 | J25: 0 | K25: L | L25: L | M25: 0 | N25: L | O25: 0 | P25: 0 | Q25: 0 | R25: L | S25: L | T25: 0 | U25: 0 | V25: 0 | W25: 0 | X25: 0 | Y25: 0 | Z25: L | AA25: L | AB25: 0 | AC25: 0 | AD25: 0 | AE25: 0 | AF25: 0 | AG25: 0 | AJ25: =SUM(E25:AI25)/AM25*50/100 -> #REF! | AM25: =AM24 -> #REF!
A26: 8 | B26: RESPON Time / kecepatan pelayanan di Gawat Darurat | D26: 100 | E26: 0 | F26: 0 | G26: 0 | H26: 0 | I26: 0 | J26: 0 | K26: L | L26: L | M26: 0 | N26: L | O26: 0 | P26: 0 | Q26: 0 | R26: L | S26: L | T26: 0 | U26: 0 | V26: 0 | W26: 0 | X26: 0 | Y26: 0 | Z26: L | AA26: L | AB26: 0 | AC26: 0 | AD26: 0 | AE26: 0 | AF26: 0 | AG26: 0 | AJ26: =SUM(E26:AI26)/AM26*50/100 -> #REF! | AM26: =AM25 -> #REF!
A27: JUMLAH RATA - RATA | E27: =SUM(E19:E26)/8 -> 5.25 | F27: =SUM(F19:F26)/8 -> 4.375 | G27: =SUM(G19:G26)/8 -> 2.625 | H27: =SUM(H19:H26)/8 -> 2.625 | I27: =SUM(I19:I26)/8 -> 3.5 | J27: =SUM(J19:J26)/8 -> 3.5 | K27: =SUM(K19:K26)/8 -> 0 | L27: =SUM(L19:L26)/8 -> 0 | ... AJ27: =SUM(AJ19:AJ26)/8 -> #REF! | AM27: =AM26 -> #REF!
A28: TOTAL NILAI PERILAKU + PENGEMBANGAN PROFESI + KINERJA KLINIS | AJ28: =AJ13+AJ17+AJ27 -> #REF! | AM28: =AM27 -> #REF!

Sheet JUNI
A1: PENILAIAN KINERJA PERAWAT
A2: SESUAI STANDAR AKRIDITASI RUMAH SAKIT
A4: NAMA | C4: =": "&'3'!B33 -> :
A5: PK | C5: :
A7: NO | B7: INDIKATOR YANG DINILAI | D7: TARGET (%) | E7: BULAN : JUNI | AJ7: CAPAIAN (%) | AL7: RUMUS WAJIB DIISI
E8: 1 | F8: 2 | G8: 3 | H8: 4 | I8: 5 | J8: 6 | K8: 7 | L8: 8 | M8: 9 | N8: 10 | O8: 11 | P8: 12 | Q8: 13 | R8: 14 | S8: 15 | T8: 16 | U8: 17 | V8: 18 | W8: 19 | X8: 20 | Y8: 21 | Z8: 22 | AA8: 23 | AB8: 24 | AC8: 25 | AD8: 26 | AE8: 27 | AF8: 28 | AG8: 29 | AH8: 30 | AI8: 31 | AL8: JUMLAH HARI : | AM8: 28
A9: A. PERILAKU ( 40 % ) | AM9: =AM8 -> 28
A10: 1 | B10: Melaporkan insiden keselamatan pasien | D10: 100 | E10: 0 | F10: L | G10: 0 | H10: 0 | I10: 0 | J10: 0 | K10: 0 | L10: 0 | M10: 0 | N10: L | O10: L | P10: 0 | Q10: 0 | R10: 0 | S10: 0 | T10: 0 | U10: L | V10: L | W10: 0 | X10: 0 | Y10: 0 | Z10: 0 | AA10: 0 | AB10: 0 | AC10: L | AD10: L | AE10: 0 | AF10: 0 | AG10: 0 | AJ10: =SUM(E10:AI10)/AM8*40/100 -> 0 | AM10: =AM9 -> 28
A11: 2 | B11: Tidak ada keluhan dari teman sejawat/profesi lain/pasien dan keluarga | D11: 100 | E11: 0 | F11: L | G11: 0 | H11: 0 | I11: 0 | J11: 0 | K11: 0 | L11: 0 | M11: 0 | N11: L | O11: L | P11: 0 | Q11: 0 | R11: 0 | S11: 0 | T11: 0 | U11: L | V11: L | W11: 0 | X11: 0 | Y11: 0 | Z11: 0 | AA11: 0 | AB11: 0 | AC11: L | AD11: L | AE11: 0 | AF11: 0 | AG11: 0 | AJ11: =SUM(E11:AI11)/AM9*40/100 -> 0 | AM11: =AM10 -> 28
A12: 3 | B12: Kepatuhan terhadap kode etik keperawatan | D12: 100 | E12: 3 | F12: L | G12: 3 | H12: 4 | I12: 4 | J12: 5 | K12: 6 | L12: 6 | M12: 5 | N12: L | O12: L | P12: 3 | Q12: 2 | R12: 2 | S12: 3 | T12: 3 | U12: L | V12: L | W12: 3 | X12: 4 | Y12: 5 | Z12: 6 | AA12: 5 | AB12: 5 | AC12: L | AD12: L | AE12: 6 | AF12: 4 | AG12: 5 | AJ12: =SUM(E12:AI12)/AM10*40/100 -> 1.3142857 | AM12: =AM11 -> 28
A13: JUMLAH RATA - RATA | E13: =SUM(E10:E12)/3 -> 1 | F13: =SUM(F10:F12)/3 -> 0 | G13: =SUM(G10:G12)/3 -> 1 | H13: =SUM(H10:H12)/3 -> 1.3333333 | I13: =SUM(I10:I12)/3 -> 1.3333333 | J13: =SUM(J10:J12)/3 -> 1.6666667 | K13: =SUM(K10:K12)/3 -> 2 | L13: =SUM(L10:L12)/3 -> 2 | ... R13: =SUM(R10:R12)/3 -> 0.66666667 | S13: 0 | T13: =SUM(T10:T12)/3 -> 1 | U13: =SUM(U10:U12)/3 -> 0 | V13: =SUM(V10:V12)/3 -> 0 | W13: =SUM(W10:W12)/3 -> 1 | X13: =SUM(X10:X12)/3 -> 1.3333333 | Y13: =SUM(Y10:Y12)/3 -> 1.6666667 | Z13: =SUM(Z10:Z12)/3 -> 2 | AA13: =SUM(AA10:AA12)/3 -> 1.6666667 | ... AJ13: =SUM(AJ10:AJ12)/3 -> 0.43809524 | AM13: =AM12 -> 28
A14: B. PENGEMBANGAN PROFESI (10%) | AM14: =AM13 -> 28
A15: 1 | B15: Menunjukan perilaku bertanggung gugat terhadap praktek profesional | D15: 100 | E15: 3 | F15: L | G15: 3 | H15: 4 | I15: 4 | J15: 5 | K15: 6 | L15: 6 | M15: 5 | N15: L | O15: L | P15: 3 | Q15: 2 | R15: 2 | S15: 3 | T15: 3 | U15: L | V15: L | W15: 3 | X15: 4 | Y15: 5 | Z15: 6 | AA15: 5 | AB15: 5 | AC15: L | AD15: L | AE15: 6 | AF15: 4 | AG15: 5 | AJ15: =SUM(E15:AI15)/AM15*10/100 -> 0.32857143 | AM15: =AM14 -> 28
A16: 2 | B16: Kepatuhan dalam memberikan pendidikan pasien dan keluarga | D16: 100 | E16: 3 | F16: L | G16: 3 | H16: 4 | I16: 4 | J16: 5 | K16: 6 | L16: 6 | M16: 5 | N16: L | O16: L | P16: 3 | Q16: 2 | R16: 2 | S16: 3 | T16: 3 | U16: L | V16: L | W16: 3 | X16: 4 | Y16: 5 | Z16: 6 | AA16: 5 | AB16: 5 | AC16: L | AD16: L | AE16: 6 | AF16: 4 | AG16: 5 | AJ16: =SUM(E16:AI16)/AM16*10/100 -> 0.32857143 | AM16: =AM15 -> 28
A17: JUMLAH RATA - RATA | E17: =SUM(E15:E16)/3 -> 2 | F17: =SUM(F15:F16)/3 -> 0 | G17: =SUM(G15:G16)/3 -> 2 | H17: =SUM(H15:H16)/3 -> 2.6666667 | I17: =SUM(I15:I16)/3 -> 2.6666667 | J17: =SUM(J15:J16)/3 -> 3.3333333 | K17: =SUM(K15:K16)/3 -> 4 | L17: =SUM(L15:L16)/3 -> 4 | ... AJ17: =SUM(AJ15:AJ16)/3 -> 0.21904762 | AM17: =#REF! -> #REF!
A18: C. KINERJA KLINIS (50%) | AM18: =AM17 -> #REF!
A19: 1 | B19: Kepatuhan identifikasi pasien | D19: 100 | E19: 3 | F19: L | G19: 3 | H19: 4 | I19: 4 | J19: 5 | K19: 6 | L19: 6 | M19: 5 | N19: L | O19: L | P19: 3 | Q19: 2 | R19: 2 | S19: 3 | T19: 3 | U19: L | V19: L | W19: 3 | X19: 4 | Y19: 5 | Z19: 6 | AA19: 5 | AB19: 5 | AC19: L | AD19: L | AE19: 6 | AF19: 4 | AG19: 5 | AJ19: =SUM(E19:AI19)/AM19*50/100 -> #REF! | AM19: =AM18 -> #REF!
A20: =A19+1 -> 2 | B20: Kepatuhan pemakaian APD dengan benar | D20: 100 | E20: 6 | F20: L | G20: 6 | H20: 8 | I20: 8 | J20: 10 | K20: 12 | L20: 12 | M20: 10 | N20: L | O20: L | P20: 6 | Q20: 4 | R20: 4 | S20: 6 | T20: 6 | U20: L | V20: L | W20: 6 | X20: 8 | Y20: 10 | Z20: 12 | AA20: 10 | AB20: 10 | AC20: L | AD20: L | AE20: 12 | AF20: 8 | AG20: 10 | AJ20: =SUM(E20:AI20)/AM20*50/100 -> #REF! | AM20: =AM19 -> #REF!
A21: =A20+1 -> 3 | B21: Kepatuhan kebersihan tangan | D21: 100 | E21: 6 | F21: L | G21: 6 | H21: 8 | I21: 8 | J21: 10 | K21: 12 | L21: 12 | M21: 10 | N21: L | O21: L | P21: 6 | Q21: 4 | R21: 4 | S21: 6 | T21: 6 | U21: L | V21: L | W21: 6 | X21: 8 | Y21: 10 | Z21: 12 | AA21: 10 | AB21: 10 | AC21: L | AD21: L | AE21: 12 | AF21: 8 | AG21: 10 | AJ21: =SUM(E21:AI21)/AM21*50/100 -> #REF! | AM21: =AM20 -> #REF!
A22: =A21+1 -> 4 | B22: Kepatuhan upaya pencegahan resiko pasien jatuh | D22: 100 | E22: 3 | F22: L | G22: 3 | H22: 4 | I22: 4 | J22: 5 | K22: 6 | L22: 6 | M22: 5 | N22: L | O22: L | P22: 3 | Q22: 2 | R22: 2 | S22: 3 | T22: 3 | U22: L | V22: L | W22: 3 | X22: 4 | Y22: 5 | Z22: 6 | AA22: 5 | AB22: 5 | AC22: L | AD22: L | AE22: 6 | AF22: 4 | AG22: 5 | AJ22: =SUM(E22:AI22)/AM22*50/100 -> #REF! | AM22: =AM21 -> #REF!
A23: =A22+1 -> 5 | B23: Kepatuhan melaksanakan hand over antar petugas dengan metode SBAR | D23: 100 | E23: 3 | F23: L | G23: 3 | H23: 4 | I23: 4 | J23: 5 | K23: 6 | L23: 6 | M23: 5 | N23: L | O23: L | P23: 3 | Q23: 2 | R23: 2 | S23: 3 | T23: 3 | U23: L | V23: L | W23: 3 | X23: 4 | Y23: 5 | Z23: 6 | AA23: 5 | AB23: 5 | AC23: L | AD23: L | AE23: 6 | AF23: 4 | AG23: 5 | AJ23: =SUM(E23:AI23)/AM23*50/100 -> #REF! | AM23: =AM22 -> #REF!
A24: =A23+1 -> 6 | B24: Kepatuhan melaksanakan double chek obat high allert | D24: 100 | E24: 1 | F24: L | G24: 1 | H24: 1 | I24: 1 | J24: 1 | K24: 1 | L24: 0 | M24: 1 | N24: L | O24: L | P24: 1 | Q24: 0 | R24: 0 | S24: 0 | T24: 0 | U24: L | V24: L | W24: 1 | X24: 1 | Y24: 1 | Z24: 1 | AA24: 0 | AB24: 0 | AC24: L | AD24: L | AE24: 1 | AF24: 1 | AG24: 1 | AJ24: =SUM(E24:AI24)/AM24*50/100 -> #REF! | AM24: =AM23 -> #REF!
A25: =A24+1 -> 7 | B25: Kemampuan menangani life saving anak dan dewasa | D25: 100 | E25: 0 | F25: L | G25: 0 | H25: 0 | I25: 0 | J25: 0 | K25: 0 | L25: 0 | M25: 0 | N25: L | O25: L | P25: 0 | Q25: 0 | R25: 0 | S25: 0 | T25: 0 | U25: L | V25: L | W25: 0 | X25: 0 | Y25: 0 | Z25: 0 | AA25: 0 | AB25: 0 | AC25: L | AD25: L | AE25: 0 | AF25: 0 | AG25: 0 | AJ25: =SUM(E25:AI25)/AM25*50/100 -> #REF! | AM25: =AM24 -> #REF!
A26: 8 | B26: RESPON Time / kecepatan pelayanan di Gawat Darurat | D26: 100 | E26: 0 | F26: L | G26: 0 | H26: 0 | I26: 0 | J26: 0 | K26: 0 | L26: 0 | M26: 0 | N26: L | O26: L | P26: 0 | Q26: 0 | R26: 0 | S26: 0 | T26: 0 | U26: L | V26: L | W26: 0 | X26: 0 | Y26: 0 | Z26: 0 | AA26: 0 | AB26: 0 | AC26: L | AD26: L | AE26: 0 | AF26: 0 | AG26: 0 | AJ26: =SUM(E26:AI26)/AM26*50/100 -> #REF! | AM26: =AM25 -> #REF!
A27: JUMLAH RATA - RATA | E27: =SUM(E19:E26)/8 -> 2.75 | F27: =SUM(F19:F26)/8 -> 0 | G27: =SUM(G19:G26)/8 -> 2.75 | H27: =SUM(H19:H26)/8 -> 3.625 | I27: =SUM(I19:I26)/8 -> 3.625 | J27: =SUM(J19:J26)/8 -> 4.5 | K27: =SUM(K19:K26)/8 -> 5.375 | L27: =SUM(L19:L26)/8 -> 5.25 | ... AJ27: =SUM(AJ19:AJ26)/8 -> #REF! | AM27: =AM26 -> #REF!
A28: TOTAL NILAI PERILAKU + PENGEMBANGAN PROFESI + KINERJA KLINIS | AJ28: =AJ13+AJ17+AJ27 -> #REF! | AM28: =AM27 -> #REF!

Sheet JULI 
A1: PENILAIAN KINERJA PERAWAT
A2: SESUAI STANDAR AKRIDITASI RUMAH SAKIT
A4: NAMA | C4: =": "&'3'!B33 -> :
A5: PK | C5: :
A7: NO | B7: INDIKATOR YANG DINILAI | D7: TARGET (%) | E7: BULAN : JULI | AJ7: CAPAIAN (%) | AL7: RUMUS WAJIB DIISI
E8: 1 | F8: 2 | G8: 3 | H8: 4 | I8: 5 | J8: 6 | K8: 7 | L8: 8 | M8: 9 | N8: 10 | O8: 11 | P8: 12 | Q8: 13 | R8: 14 | S8: 15 | T8: 16 | U8: 17 | V8: 18 | W8: 19 | X8: 20 | Y8: 21 | Z8: 22 | AA8: 23 | AB8: 24 | AC8: 25 | AD8: 26 | AE8: 27 | AF8: 28 | AG8: 29 | AH8: 30 | AI8: 31 | AL8: JUMLAH HARI : | AM8: 28
A9: A. PERILAKU ( 40 % ) | AM9: =AM8 -> 28
A10: 1 | B10: Melaporkan insiden keselamatan pasien | D10: 100 | E10: 0 | F10: L | G10: L | H10: 0 | I10: 0 | J10: 0 | K10: 0 | L10: 0 | M10: L | N10: 0 | O10: 0 | P10: 0 | Q10: 0 | R10: L | S10: 0 | T10: 0 | U10: 0 | V10: L | W10: L | X10: 0 | Y10: 0 | Z10: 0 | AA10: 0 | AB10: 0 | AC10: 0 | AJ10: =SUM(E10:AI10)/AM8*40/100 -> 0 | AM10: =AM9 -> 28
A11: 2 | B11: Tidak ada keluhan dari teman sejawat/profesi lain/pasien dan keluarga | D11: 100 | E11: 0 | F11: L | G11: L | H11: 0 | I11: 0 | J11: 6 | K11: 0 | L11: 0 | M11: L | N11: 0 | O11: 0 | P11: 0 | Q11: 0 | R11: L | S11: 0 | T11: 0 | U11: 0 | V11: L | W11: L | X11: 0 | Y11: 0 | Z11: 0 | AA11: 0 | AB11: 0 | AC11: 0 | AJ11: =SUM(E11:AI11)/AM9*40/100 -> 0.085714286 | AM11: =AM10 -> 28
A12: 3 | B12: Kepatuhan terhadap kode etik keperawatan | D12: 100 | E12: 5 | F12: L | G12: L | H12: 7 | I12: 6 | J12: 6 | K12: 4 | L12: 4 | M12: L | N12: 7 | O12: 5 | P12: 5 | Q12: 8 | R12: L | S12: 6 | T12: 5 | U12: 3 | V12: L | W12: L | X12: 4 | Y12: 4 | Z12: 3 | AA12: 3 | AB12: 3 | AC12: 2 | AJ12: =SUM(E12:AI12)/AM10*40/100 -> 1.2857143 | AM12: =AM11 -> 28
A13: JUMLAH RATA - RATA | E13: =SUM(E10:E12)/3 -> 1.6666667 | F13: =SUM(F10:F12)/3 -> 0 | G13: =SUM(G10:G12)/3 -> 0 | H13: =SUM(H10:H12)/3 -> 2.3333333 | I13: =SUM(I10:I12)/3 -> 2 | J13: =SUM(J10:J12)/3 -> 4 | K13: =SUM(K10:K12)/3 -> 1.3333333 | L13: =SUM(L10:L12)/3 -> 1.3333333 | ... R13: =SUM(R10:R12)/3 -> 0 | S13: 0 | T13: =SUM(T10:T12)/3 -> 1.6666667 | U13: =SUM(U10:U12)/3 -> 1 | V13: =SUM(V10:V12)/3 -> 0 | W13: =SUM(W10:W12)/3 -> 0 | X13: =SUM(X10:X12)/3 -> 1.3333333 | Y13: =SUM(Y10:Y12)/3 -> 1.3333333 | Z13: =SUM(Z10:Z12)/3 -> 1 | AA13: =SUM(AA10:AA12)/3 -> 1 | ... AJ13: =SUM(AJ10:AJ12)/3 -> 0.45714286 | AM13: =AM12 -> 28
A14: B. PENGEMBANGAN PROFESI (10%) | AM14: =AM13 -> 28
A15: 1 | B15: Menunjukan perilaku bertanggung gugat terhadap praktek profesional | D15: 100 | E15: 5 | F15: L | G15: L | H15: 7 | I15: 6 | J15: 6 | K15: 4 | L15: 4 | M15: L | N15: 7 | O15: 5 | P15: 5 | Q15: 8 | R15: L | S15: 6 | T15: 5 | U15: 3 | V15: L | W15: L | X15: 4 | Y15: 4 | Z15: 3 | AA15: 3 | AB15: 3 | AC15: 2 | AJ15: =SUM(E15:AI15)/AM15*10/100 -> 0.32142857 | AM15: =AM14 -> 28
A16: 2 | B16: Kepatuhan dalam memberikan pendidikan pasien dan keluarga | D16: 100 | E16: 5 | F16: L | G16: L | H16: 7 | I16: 6 | J16: 6 | K16: 4 | L16: 4 | M16: L | N16: 7 | O16: 5 | P16: 5 | Q16: 8 | R16: L | S16: 6 | T16: 5 | U16: 3 | V16: L | W16: L | X16: 4 | Y16: 4 | Z16: 3 | AA16: 3 | AB16: 3 | AC16: 2 | AJ16: =SUM(E16:AI16)/AM16*10/100 -> 0.32142857 | AM16: =AM15 -> 28
A17: JUMLAH RATA - RATA | E17: =SUM(E15:E16)/3 -> 3.3333333 | F17: =SUM(F15:F16)/3 -> 0 | G17: =SUM(G15:G16)/3 -> 0 | H17: =SUM(H15:H16)/3 -> 4.6666667 | I17: =SUM(I15:I16)/3 -> 4 | J17: =SUM(J15:J16)/3 -> 4 | K17: =SUM(K15:K16)/3 -> 2.6666667 | L17: =SUM(L15:L16)/3 -> 2.6666667 | ... AJ17: =SUM(AJ15:AJ16)/3 -> 0.21428571 | AM17: =#REF! -> #REF!
A18: C. KINERJA KLINIS (50%) | AM18: =AM17 -> #REF!
A19: 1 | B19: Kepatuhan identifikasi pasien | D19: 100 | E19: 5 | F19: L | G19: L | H19: 7 | I19: 6 | J19: 6 | K19: 4 | L19: 4 | M19: L | N19: 7 | O19: 5 | P19: 5 | Q19: 8 | R19: L | S19: 6 | T19: 5 | U19: 3 | V19: L | W19: L | X19: 4 | Y19: 4 | Z19: 3 | AA19: 3 | AB19: 3 | AC19: 2 | AJ19: =SUM(E19:AI19)/AM19*50/100 -> #REF! | AM19: =AM18 -> #REF!
A20: =A19+1 -> 2 | B20: Kepatuhan pemakaian APD dengan benar | D20: 100 | E20: 10 | F20: L | G20: L | H20: 14 | I20: 12 | J20: 12 | K20: 8 | L20: 8 | M20: L | N20: 14 | O20: 10 | P20: 10 | Q20: 16 | R20: L | S20: 12 | T20: 10 | U20: 6 | V20: L | W20: L | X20: 8 | Y20: 8 | Z20: 6 | AA20: 6 | AB20: 6 | AC20: 4 | AJ20: =SUM(E20:AI20)/AM20*50/100 -> #REF! | AM20: =AM19 -> #REF!
A21: =A20+1 -> 3 | B21: Kepatuhan kebersihan tangan | D21: 100 | E21: 10 | F21: L | G21: L | H21: 14 | I21: 12 | J21: 12 | K21: 8 | L21: 8 | M21: L | N21: 14 | O21: 10 | P21: 10 | Q21: 16 | R21: L | S21: 12 | T21: 10 | U21: 6 | V21: L | W21: L | X21: 8 | Y21: 8 | Z21: 6 | AA21: 3 | AB21: 6 | AC21: 4 | AJ21: =SUM(E21:AI21)/AM21*50/100 -> #REF! | AM21: =AM20 -> #REF!
A22: =A21+1 -> 4 | B22: Kepatuhan upaya pencegahan resiko pasien jatuh | D22: 100 | E22: 5 | F22: L | G22: L | H22: 7 | I22: 6 | J22: 6 | K22: 4 | L22: 4 | M22: L | N22: 7 | O22: 5 | P22: 5 | Q22: 8 | R22: L | S22: 6 | T22: 5 | U22: 3 | V22: L | W22: L | X22: 4 | Y22: 4 | Z22: 3 | AA22: 3 | AB22: 3 | AC22: 2 | AJ22: =SUM(E22:AI22)/AM22*50/100 -> #REF! | AM22: =AM21 -> #REF!
A23: =A22+1 -> 5 | B23: Kepatuhan melaksanakan hand over antar petugas dengan metode SBAR | D23: 100 | E23: 5 | F23: L | G23: L | H23: 7 | I23: 6 | J23: 6 | K23: 4 | L23: 4 | M23: L | N23: 7 | O23: 5 | P23: 5 | Q23: 8 | R23: L | S23: 6 | T23: 5 | U23: 3 | V23: L | W23: L | X23: 4 | Y23: 4 | Z23: 3 | AA23: 3 | AB23: 3 | AC23: 2 | AJ23: =SUM(E23:AI23)/AM23*50/100 -> #REF! | AM23: =AM22 -> #REF!
A24: =A23+1 -> 6 | B24: Kepatuhan melaksanakan double chek obat high allert | D24: 100 | E24: 0 | F24: L | G24: L | H24: 2 | I24: 0 | J24: 0 | K24: 0 | L24: 1 | M24: L | N24: 0 | O24: 0 | P24: 0 | Q24: 1 | R24: L | S24: 1 | T24: 2 | U24: 0 | V24: L | W24: L | X24: 0 | Y24: 0 | Z24: 0 | AA24: 1 | AB24: 1 | AC24: 1 | AJ24: =SUM(E24:AI24)/AM24*50/100 -> #REF! | AM24: =AM23 -> #REF!
A25: =A24+1 -> 7 | B25: Kemampuan menangani life saving anak dan dewasa | D25: 100 | E25: 0 | F25: L | G25: L | H25: 0 | I25: 0 | J25: 0 | K25: 0 | L25: 0 | M25: L | N25: 0 | O25: 0 | P25: 0 | Q25: 0 | R25: L | S25: 0 | T25: 0 | U25: 0 | V25: L | W25: L | X25: 0 | Y25: 0 | Z25: 0 | AA25: 0 | AB25: 0 | AC25: 0 | AJ25: =SUM(E25:AI25)/AM25*50/100 -> #REF! | AM25: =AM24 -> #REF!
A26: 8 | B26: RESPON Time / kecepatan pelayanan di Gawat Darurat | D26: 100 | E26: 0 | F26: L | G26: L | H26: 0 | I26: 0 | J26: 0 | K26: 0 | L26: 0 | M26: L | N26: 0 | O26: 0 | P26: 0 | Q26: 0 | R26: L | S26: 0 | T26: 0 | U26: 0 | V26: L | W26: L | X26: 0 | Y26: 0 | Z26: 0 | AA26: 0 | AB26: 0 | AC26: 0 | AJ26: =SUM(E26:AI26)/AM26*50/100 -> #REF! | AM26: =AM25 -> #REF!
A27: JUMLAH RATA - RATA | E27: =SUM(E19:E26)/8 -> 4.375 | F27: =SUM(F19:F26)/8 -> 0 | G27: =SUM(G19:G26)/8 -> 0 | H27: =SUM(H19:H26)/8 -> 6.375 | I27: =SUM(I19:I26)/8 -> 5.25 | J27: =SUM(J19:J26)/8 -> 5.25 | K27: =SUM(K19:K26)/8 -> 3.5 | L27: =SUM(L19:L26)/8 -> 3.625 | ... AJ27: =SUM(AJ19:AJ26)/8 -> #REF! | AM27: =AM26 -> #REF!
A28: TOTAL NILAI PERILAKU + PENGEMBANGAN PROFESI + KINERJA KLINIS | AJ28: =AJ13+AJ17+AJ27 -> #REF! | AM28: =AM27 -> #REF!

Sheet AGUST
A1: PENILAIAN KINERJA PERAWAT
A2: SESUAI STANDAR AKRIDITASI RUMAH SAKIT
A4: NAMA | C4: =": "&'3'!B33 -> :
A5: PK | C5: :
A7: NO | B7: INDIKATOR YANG DINILAI | D7: TARGET (%) | E7: BULAN : AGUSTUS | AJ7: CAPAIAN (%) | AL7: RUMUS WAJIB DIISI
E8: 1 | F8: 2 | G8: 3 | H8: 4 | I8: 5 | J8: 6 | K8: 7 | L8: 8 | M8: 9 | N8: 10 | O8: 11 | P8: 12 | Q8: 13 | R8: 14 | S8: 15 | T8: 16 | U8: 17 | V8: 18 | W8: 19 | X8: 20 | Y8: 21 | Z8: 22 | AA8: 23 | AB8: 24 | AC8: 25 | AD8: 26 | AE8: 27 | AF8: 28 | AG8: 29 | AH8: 30 | AI8: 31 | AL8: JUMLAH HARI : | AM8: 28
A9: A. PERILAKU ( 40 % ) | AM9: =AM8 -> 28
A10: 1 | B10: Melaporkan insiden keselamatan pasien | D10: 100 | AJ10: =SUM(E10:AI10)/AM8*40/100 -> 0 | AM10: =AM9 -> 28
A11: 2 | B11: Tidak ada keluhan dari teman sejawat/profesi lain/pasien dan keluarga | D11: 100 | S11: . | AJ11: =SUM(E11:AI11)/AM9*40/100 -> 0 | AM11: =AM10 -> 28
A12: 3 | B12: Kepatuhan terhadap kode etik keperawatan | D12: 100 | AJ12: =SUM(E12:AI12)/AM10*40/100 -> 0 | AM12: =AM11 -> 28
A13: JUMLAH RATA - RATA | E13: =SUM(E10:E12)/3 -> 0 | F13: =SUM(F10:F12)/3 -> 0 | G13: =SUM(G10:G12)/3 -> 0 | H13: =SUM(H10:H12)/3 -> 0 | I13: =SUM(I10:I12)/3 -> 0 | J13: =SUM(J10:J12)/3 -> 0 | K13: =SUM(K10:K12)/3 -> 0 | L13: =SUM(L10:L12)/3 -> 0 | ... R13: =SUM(R10:R12)/3 -> 0 | S13: 0 | T13: =SUM(T10:T12)/3 -> 0 | U13: =SUM(U10:U12)/3 -> 0 | V13: =SUM(V10:V12)/3 -> 0 | W13: =SUM(W10:W12)/3 -> 0 | X13: =SUM(X10:X12)/3 -> 0 | Y13: =SUM(Y10:Y12)/3 -> 0 | Z13: =SUM(Z10:Z12)/3 -> 0 | AA13: =SUM(AA10:AA12)/3 -> 0 | ... AJ13: =SUM(AJ10:AJ12)/3 -> 0 | AM13: =AM12 -> 28
A14: B. PENGEMBANGAN PROFESI (10%) | AM14: =AM13 -> 28
A15: 1 | B15: Menunjukan perilaku bertanggung gugat terhadap praktek profesional | D15: 100 | AJ15: =SUM(E15:AI15)/AM15*10/100 -> 0 | AM15: =AM14 -> 28
A16: 2 | B16: Kepatuhan dalam memberikan pendidikan pasien dan keluarga | D16: 100 | AJ16: =SUM(E16:AI16)/AM16*10/100 -> 0 | AM16: =AM15 -> 28
A17: JUMLAH RATA - RATA | E17: =SUM(E15:E16)/3 -> 0 | F17: =SUM(F15:F16)/3 -> 0 | G17: =SUM(G15:G16)/3 -> 0 | H17: =SUM(H15:H16)/3 -> 0 | I17: =SUM(I15:I16)/3 -> 0 | J17: =SUM(J15:J16)/3 -> 0 | K17: =SUM(K15:K16)/3 -> 0 | L17: =SUM(L15:L16)/3 -> 0 | ... AJ17: =SUM(AJ15:AJ16)/3 -> 0 | AM17: =#REF! -> #REF!
A18: C. KINERJA KLINIS (50%) | AM18: =AM17 -> #REF!
A19: 1 | B19: Kepatuhan identifikasi pasien | D19: 100 | AJ19: =SUM(E19:AI19)/AM19*50/100 -> #REF! | AM19: =AM18 -> #REF!
A20: =A19+1 -> 2 | B20: Kepatuhan pemakaian APD dengan benar | D20: 100 | AJ20: =SUM(E20:AI20)/AM20*50/100 -> #REF! | AM20: =AM19 -> #REF!
A21: =A20+1 -> 3 | B21: Kepatuhan kebersihan tangan | D21: 100 | AJ21: =SUM(E21:AI21)/AM21*50/100 -> #REF! | AM21: =AM20 -> #REF!
A22: =A21+1 -> 4 | B22: Kepatuhan upaya pencegahan resiko pasien jatuh | D22: 100 | AJ22: =SUM(E22:AI22)/AM22*50/100 -> #REF! | AM22: =AM21 -> #REF!
A23: =A22+1 -> 5 | B23: Kepatuhan melaksanakan hand over antar petugas dengan metode SBAR | D23: 100 | AJ23: =SUM(E23:AI23)/AM23*50/100 -> #REF! | AM23: =AM22 -> #REF!
A24: =A23+1 -> 6 | B24: Kepatuhan melaksanakan double chek obat high allert | D24: 100 | AJ24: =SUM(E24:AI24)/AM24*50/100 -> #REF! | AM24: =AM23 -> #REF!
A25: =A24+1 -> 7 | B25: Kemampuan menangani life saving anak dan dewasa | D25: 100 | AJ25: =SUM(E25:AI25)/AM25*50/100 -> #REF! | AM25: =AM24 -> #REF!
A26: 8 | B26: RESPON Time / kecepatan pelayanan di Gawat Darurat | D26: 100 | AJ26: =SUM(E26:AI26)/AM26*50/100 -> #REF! | AM26: =AM25 -> #REF!
A27: JUMLAH RATA - RATA | E27: =SUM(E19:E26)/8 -> 0 | F27: =SUM(F19:F26)/8 -> 0 | G27: =SUM(G19:G26)/8 -> 0 | H27: =SUM(H19:H26)/8 -> 0 | I27: =SUM(I19:I26)/8 -> 0 | J27: =SUM(J19:J26)/8 -> 0 | K27: =SUM(K19:K26)/8 -> 0 | L27: =SUM(L19:L26)/8 -> 0 | ... AJ27: =SUM(AJ19:AJ26)/8 -> #REF! | AM27: =AM26 -> #REF!
A28: TOTAL NILAI PERILAKU + PENGEMBANGAN PROFESI + KINERJA KLINIS | AJ28: =AJ13+AJ17+AJ27 -> #REF! | AM28: =AM27 -> #REF!

Sheet SEPT 
A1: PENILAIAN KINERJA PERAWAT
A2: SESUAI STANDAR AKRIDITASI RUMAH SAKIT
A4: NAMA | C4: =": "&'3'!B33 -> :
A5: PK | C5: :
A7: NO | B7: INDIKATOR YANG DINILAI | D7: TARGET (%) | E7: BULAN : SEPTEMBER | AJ7: CAPAIAN (%) | AL7: RUMUS WAJIB DIISI
E8: 1 | F8: 2 | G8: 3 | H8: 4 | I8: 5 | J8: 6 | K8: 7 | L8: 8 | M8: 9 | N8: 10 | O8: 11 | P8: 12 | Q8: 13 | R8: 14 | S8: 15 | T8: 16 | U8: 17 | V8: 18 | W8: 19 | X8: 20 | Y8: 21 | Z8: 22 | AA8: 23 | AB8: 24 | AC8: 25 | AD8: 26 | AE8: 27 | AF8: 28 | AG8: 29 | AH8: 30 | AI8: 31 | AL8: JUMLAH HARI : | AM8: 28
A9: A. PERILAKU ( 40 % ) | AM9: =AM8 -> 28
A10: 1 | B10: Melaporkan insiden keselamatan pasien | D10: 100 | AJ10: =SUM(E10:AI10)/AM8*40/100 -> 0 | AM10: =AM9 -> 28
A11: 2 | B11: Tidak ada keluhan dari teman sejawat/profesi lain/pasien dan keluarga | D11: 100 | S11: . | AJ11: =SUM(E11:AI11)/AM9*40/100 -> 0 | AM11: =AM10 -> 28
A12: 3 | B12: Kepatuhan terhadap kode etik keperawatan | D12: 100 | AJ12: =SUM(E12:AI12)/AM10*40/100 -> 0 | AM12: =AM11 -> 28
A13: JUMLAH RATA - RATA | E13: =SUM(E10:E12)/3 -> 0 | F13: =SUM(F10:F12)/3 -> 0 | G13: =SUM(G10:G12)/3 -> 0 | H13: =SUM(H10:H12)/3 -> 0 | I13: =SUM(I10:I12)/3 -> 0 | J13: =SUM(J10:J12)/3 -> 0 | K13: =SUM(K10:K12)/3 -> 0 | L13: =SUM(L10:L12)/3 -> 0 | ... R13: =SUM(R10:R12)/3 -> 0 | S13: 0 | T13: =SUM(T10:T12)/3 -> 0 | U13: =SUM(U10:U12)/3 -> 0 | V13: =SUM(V10:V12)/3 -> 0 | W13: =SUM(W10:W12)/3 -> 0 | X13: =SUM(X10:X12)/3 -> 0 | Y13: =SUM(Y10:Y12)/3 -> 0 | Z13: =SUM(Z10:Z12)/3 -> 0 | AA13: =SUM(AA10:AA12)/3 -> 0 | ... AJ13: =SUM(AJ10:AJ12)/3 -> 0 | AM13: =AM12 -> 28
A14: B. PENGEMBANGAN PROFESI (10%) | AM14: =AM13 -> 28
A15: 1 | B15: Menunjukan perilaku bertanggung gugat terhadap praktek profesional | D15: 100 | AJ15: =SUM(E15:AI15)/AM15*10/100 -> 0 | AM15: =AM14 -> 28
A16: 2 | B16: Kepatuhan dalam memberikan pendidikan pasien dan keluarga | D16: 100 | AJ16: =SUM(E16:AI16)/AM16*10/100 -> 0 | AM16: =AM15 -> 28
A17: JUMLAH RATA - RATA | E17: =SUM(E15:E16)/3 -> 0 | F17: =SUM(F15:F16)/3 -> 0 | G17: =SUM(G15:G16)/3 -> 0 | H17: =SUM(H15:H16)/3 -> 0 | I17: =SUM(I15:I16)/3 -> 0 | J17: =SUM(J15:J16)/3 -> 0 | K17: =SUM(K15:K16)/3 -> 0 | L17: =SUM(L15:L16)/3 -> 0 | ... AJ17: =SUM(AJ15:AJ16)/3 -> 0 | AM17: =#REF! -> #REF!
A18: C. KINERJA KLINIS (50%) | AM18: =AM17 -> #REF!
A19: 1 | B19: Kepatuhan identifikasi pasien | D19: 100 | AJ19: =SUM(E19:AI19)/AM19*50/100 -> #REF! | AM19: =AM18 -> #REF!
A20: =A19+1 -> 2 | B20: Kepatuhan pemakaian APD dengan benar | D20: 100 | AJ20: =SUM(E20:AI20)/AM20*50/100 -> #REF! | AM20: =AM19 -> #REF!
A21: =A20+1 -> 3 | B21: Kepatuhan kebersihan tangan | D21: 100 | AJ21: =SUM(E21:AI21)/AM21*50/100 -> #REF! | AM21: =AM20 -> #REF!
A22: =A21+1 -> 4 | B22: Kepatuhan upaya pencegahan resiko pasien jatuh | D22: 100 | AJ22: =SUM(E22:AI22)/AM22*50/100 -> #REF! | AM22: =AM21 -> #REF!
A23: =A22+1 -> 5 | B23: Kepatuhan melaksanakan hand over antar petugas dengan metode SBAR | D23: 100 | AJ23: =SUM(E23:AI23)/AM23*50/100 -> #REF! | AM23: =AM22 -> #REF!
A24: =A23+1 -> 6 | B24: Kepatuhan melaksanakan double chek obat high allert | D24: 100 | AJ24: =SUM(E24:AI24)/AM24*50/100 -> #REF! | AM24: =AM23 -> #REF!
A25: =A24+1 -> 7 | B25: Kemampuan menangani life saving anak dan dewasa | D25: 100 | AJ25: =SUM(E25:AI25)/AM25*50/100 -> #REF! | AM25: =AM24 -> #REF!
A26: 8 | B26: RESPON Time / kecepatan pelayanan di Gawat Darurat | D26: 100 | AJ26: =SUM(E26:AI26)/AM26*50/100 -> #REF! | AM26: =AM25 -> #REF!
A27: JUMLAH RATA - RATA | E27: =SUM(E19:E26)/8 -> 0 | F27: =SUM(F19:F26)/8 -> 0 | G27: =SUM(G19:G26)/8 -> 0 | H27: =SUM(H19:H26)/8 -> 0 | I27: =SUM(I19:I26)/8 -> 0 | J27: =SUM(J19:J26)/8 -> 0 | K27: =SUM(K19:K26)/8 -> 0 | L27: =SUM(L19:L26)/8 -> 0 | ... AJ27: =SUM(AJ19:AJ26)/8 -> #REF! | AM27: =AM26 -> #REF!
A28: TOTAL NILAI PERILAKU + PENGEMBANGAN PROFESI + KINERJA KLINIS | AJ28: =AJ13+AJ17+AJ27 -> #REF! | AM28: =AM27 -> #REF!

Sheet OKT
A1: PENILAIAN KINERJA PERAWAT
A2: SESUAI STANDAR AKRIDITASI RUMAH SAKIT
A4: NAMA | C4: =": "&'3'!B33 -> :
A5: PK | C5: :
A7: NO | B7: INDIKATOR YANG DINILAI | D7: TARGET (%) | E7: BULAN : OKTOBER | AJ7: CAPAIAN (%) | AL7: RUMUS WAJIB DIISI
E8: 1 | F8: 2 | G8: 3 | H8: 4 | I8: 5 | J8: 6 | K8: 7 | L8: 8 | M8: 9 | N8: 10 | O8: 11 | P8: 12 | Q8: 13 | R8: 14 | S8: 15 | T8: 16 | U8: 17 | V8: 18 | W8: 19 | X8: 20 | Y8: 21 | Z8: 22 | AA8: 23 | AB8: 24 | AC8: 25 | AD8: 26 | AE8: 27 | AF8: 28 | AG8: 29 | AH8: 30 | AI8: 31 | AL8: JUMLAH HARI : | AM8: 28
A9: A. PERILAKU ( 40 % ) | AM9: =AM8 -> 28
A10: 1 | B10: Melaporkan insiden keselamatan pasien | D10: 100 | AJ10: =SUM(E10:AI10)/AM10*40/100 -> 0 | AM10: =AM9 -> 28
A11: 2 | B11: Tidak ada keluhan dari teman sejawat/profesi lain/pasien dan keluarga | D11: 100 | AJ11: =SUM(E11:AI11)/AM11*40/100 -> 0 | AM11: =AM10 -> 28
A12: 3 | B12: Kepatuhan terhadap kode etik keperawatan | D12: 100 | AJ12: =SUM(E12:AI12)/AM12*40/100 -> 0 | AM12: =AM11 -> 28
A13: JUMLAH RATA - RATA | E13: =SUM(E10:E12)/3 -> 0 | F13: =SUM(F10:F12)/3 -> 0 | G13: =SUM(G10:G12)/3 -> 0 | H13: =SUM(H10:H12)/3 -> 0 | I13: =SUM(I10:I12)/3 -> 0 | J13: =SUM(J10:J12)/3 -> 0 | K13: =SUM(K10:K12)/3 -> 0 | L13: =SUM(L10:L12)/3 -> 0 | ... AJ13: =SUM(AJ10:AJ12)/3 -> 0 | AM13: =AM12 -> 28
A14: B. PENGEMBANGAN PROFESI (10%) | AM14: =AM13 -> 28
A15: 1 | B15: Menunjukan perilaku bertanggung gugat terhadap praktek profesional | D15: 100 | AJ15: =SUM(E15:AI15)/AM15*10/100 -> 0 | AM15: =AM14 -> 28
A16: 2 | B16: Kepatuhan dalam memberikan pendidikan pasien dan keluarga | D16: 100 | AJ16: =SUM(E16:AI16)/AM16*10/100 -> 0 | AM16: =AM15 -> 28
A17: JUMLAH RATA - RATA | E17: =SUM(E15:E16)/3 -> 0 | F17: =SUM(F15:F16)/3 -> 0 | G17: =SUM(G15:G16)/3 -> 0 | H17: =SUM(H15:H16)/3 -> 0 | I17: =SUM(I15:I16)/3 -> 0 | J17: =SUM(J15:J16)/3 -> 0 | K17: =SUM(K15:K16)/3 -> 0 | L17: =SUM(L15:L16)/3 -> 0 | ... AJ17: =SUM(AJ15:AJ16)/3 -> 0 | AM17: =#REF! -> #REF!
A18: C. KINERJA KLINIS (50%) | AM18: =AM17 -> #REF!
A19: 1 | B19: Kepatuhan identifikasi pasien | D19: 100 | AJ19: =SUM(E19:AI19)/AM19*50/100 -> #REF! | AM19: =AM18 -> #REF!
A20: =A19+1 -> 2 | B20: Kepatuhan pemakaian APD dengan benar | D20: 100 | AJ20: =SUM(E20:AI20)/AM20*50/100 -> #REF! | AM20: =AM19 -> #REF!
A21: =A20+1 -> 3 | B21: Kepatuhan kebersihan tangan | D21: 100 | AJ21: =SUM(E21:AI21)/AM21*50/100 -> #REF! | AM21: =AM20 -> #REF!
A22: =A21+1 -> 4 | B22: Kepatuhan upaya pencegahan resiko pasien jatuh | D22: 100 | AJ22: =SUM(E22:AI22)/AM22*50/100 -> #REF! | AM22: =AM21 -> #REF!
A23: =A22+1 -> 5 | B23: Kepatuhan melaksanakan hand over antar petugas dengan metode SBAR | D23: 100 | AJ23: =SUM(E23:AI23)/AM23*50/100 -> #REF! | AM23: =AM22 -> #REF!
A24: =A23+1 -> 6 | B24: Kepatuhan melaksanakan double chek obat high allert | D24: 100 | AJ24: =SUM(E24:AI24)/AM24*50/100 -> #REF! | AM24: =AM23 -> #REF!
